Workbook

Sheet TOTAL NASABAH BARU
A1: PT PIPOSMART DIGITAL INDONESIA
A2: Laporan Nasabah Baru
A3: Tahun 2026
I4: 2021 | U4: 2022 | AG4: 2023 | AS4: 2024 | BE4: 2025 | BQ4: 2026
A5: No | B5: Provinsi | C5: Total 2021 | D5: Total 2022 | E5: Total 2023 | F5: Total 2024 | G5: Total 2025 | H5: Total User 2021-2025 | I5: Januari | J5: Februari | K5: Maret | L5: April | M5: Mei | N5: Juni | O5: Juli | P5: Agustus | Q5: September | R5: Oktober | S5: November | T5: Desember | U5: Januari | V5: Februari | W5: Maret | X5: April | Y5: Mei | Z5: Juni | AA5: Juli | AB5: Agustus | AC5: September | AD5: Oktober | AE5: November | AF5: Desember | AG5: Januari | AH5: Februari | AI5: Maret | AJ5: April | AK5: Mei | AL5: Juni | AM5: Juli | AN5: Agustus | AO5: September | AP5: Oktober | AQ5: November | AR5: Desember | AS5: Januari | AT5: Februari | AU5: Maret | AV5: April | AW5: Mei | AX5: Juni | AY5: Juli | AZ5: Agustus | BA5: September | BB5: Oktober | BC5: November | BD5: Desember | BE5: Januari | BF5: Februari | BG5: Maret | BH5: April | BI5: Mei | BJ5: Juni | BK5: Juli | BL5: Agustus | BM5: September | BN5: Oktober | BO5: November | BP5: Desember | BQ5: Januari | BR5: Februari | BS5: Maret | BT5: April | BU5: Mei | BV5: Juni | BW5: Juli | BX5: Agustus | BY5: September
A6: 1 | B6: Nanggroe Aceh Darussalam | C6: =sum(I6:T6) -> 4 | D6: =sum(U6:AF6) -> 8 | E6: =sum(AG6:AR6) -> 7 | F6: =SUM(AS6:BD6) -> 8 | G6: =sum(BE6:BP6) -> 0 | H6: =Aceh!$H$33 -> 27 | I6: 0 | J6: 0 | K6: 0 | L6: 0 | M6: 0 | N6: 0 | O6: 1 | P6: 1 | Q6: 0 | R6: 1 | S6: 0 | T6: 1 | U6: 1 | V6: 1 | W6: 0 | X6: 0 | Y6: 0 | Z6: 2 | AA6: 0 | AB6: 1 | AC6: 1 | AD6: 0 | AE6: 2 | AF6: 0 | AG6: 0 | AH6: 0 | AI6: 0 | AJ6: 1 | AK6: 1 | AL6: 1 | AM6: 0 | AN6: 0 | AO6: 0 | AP6: 0 | AQ6: 1 | AR6: 3 | AS6: 2 | AT6: 0 | AU6: 2 | AV6: 0 | AW6: 1 | AX6: 0 | AY6: =COUNTA(#REF!) -> 1 | AZ6: =COUNTA(#REF!) -> 1 | BA6: 1 | BB6: 0 | BC6: 0 | BD6: 0 | BE6: 0 | BF6: 0 | BG6: 0 | BH6: 0 | BI6: 0 | BJ6: 0 | BK6: 0 | BL6: 0 | BM6: 0 | BN6: 0 | BO6: 0 | BP6: 0 | BQ6: 0 | BR6: 0 | BS6: 0 | BT6: 0 | BU6: 0 | BV6: 0
A7: =A6+1 -> 2 | B7: Sumatera Utara | C7: =sum(I7:T7) -> 12 | D7: =sum(U7:AF7) -> 23 | E7: =sum(AG7:AR7) -> 53 | F7: =SUM(AS7:BD7) -> 52 | G7: =sum(BE7:BP7) -> 51 | H7: ='Sumatera Utara'!$H$210 -> 200 | I7: 0 | J7: 0 | K7: 0 | L7: 0 | M7: 0 | N7: 1 | O7: 0 | P7: 0 | Q7: 4 | R7: 2 | S7: 1 | T7: 4 | U7: 1 | V7: 2 | W7: 0 | X7: 1 | Y7: 3 | Z7: 1 | AA7: 3 | AB7: 3 | AC7: 0 | AD7: 2 | AE7: 3 | AF7: 4 | AG7: 2 | AH7: 4 | AI7: 3 | AJ7: 1 | AK7: 7 | AL7: 7 | AM7: 5 | AN7: 5 | AO7: 5 | AP7: 5 | AQ7: 4 | AR7: 5 | AS7: 6 | AT7: 6 | AU7: 7 | AV7: 4 | AW7: 5 | AX7: 5 | AY7: =COUNTA('Sumatera Utara'!C126:C128) -> 3 | AZ7: 2 | BA7: 2 | BB7: 1 | BC7: 4 | BD7: 7 | BE7: 6 | BF7: 5 | BG7: 6 | BH7: 1 | BI7: 6 | BJ7: 4 | BK7: 4 | BL7: 5 | BM7: 4 | BN7: 7 | BO7: 2 | BP7: 1 | BQ7: 4 | BR7: 0 | BS7: 2 | BT7: 4 | BU7: 0 | BV7: 3
A8: =A7+1 -> 3 | B8: Sumatera Selatan | C8: =sum(I8:T8) -> 5 | D8: =sum(U8:AF8) -> 11 | E8: =sum(AG8:AR8) -> 2 | F8: =SUM(AS8:BD8) -> 5 | G8: =sum(BE8:BP8) -> 5 | H8: ='Sumatera Selatan'!$H$36 -> 30 | I8: 0 | J8: 0 | K8: 0 | L8: 0 | M8: 0 | N8: 2 | O8: 0 | P8: 0 | Q8: 1 | R8: 1 | S8: 0 | T8: 1 | U8: 2 | V8: 1 | W8: 1 | X8: 3 | Y8: 0 | Z8: 0 | AA8: 1 | AB8: 0 | AC8: 2 | AD8: 0 | AE8: 0 | AF8: 1 | AG8: 0 | AH8: 2 | AI8: 0 | AJ8: 0 | AK8: 0 | AL8: 0 | AM8: 0 | AN8: 0 | AO8: 0 | AP8: 0 | AQ8: 0 | AR8: 0 | AS8: 0 | AT8: 2 | AU8: 0 | AV8: 0 | AW8: 0 | AX8: 1 | AY8: 0 | AZ8: =COUNTA(Aceh!D33) -> 0 | BA8: 1 | BB8: 0 | BC8: 0 | BD8: 1 | BE8: 1 | BF8: 1 | BG8: 0 | BH8: 1 | BI8: 0 | BJ8: 0 | BK8: 1 | BL8: 0 | BM8: 1 | BN8: 0 | BO8: 0 | BP8: 0 | BQ8: 0 | BR8: 0 | BS8: 0 | BT8: 0 | BU8: 0 | BV8: 0
A9: =A8+1 -> 4 | B9: Sumatera Barat | C9: =sum(I9:T9) -> 6 | D9: =sum(U9:AF9) -> 9 | E9: =sum(AG9:AR9) -> 7 | F9: =SUM(AS9:BD9) -> 6 | G9: =sum(BE9:BP9) -> 2 | H9: ='Sumatera Barat'!$H$40 -> 35 | I9: 0 | J9: 0 | K9: 0 | L9: 0 | M9: 1 | N9: 0 | O9: 1 | P9: 2 | Q9: 0 | R9: 0 | S9: 0 | T9: 2 | U9: 2 | V9: 0 | W9: 0 | X9: 1 | Y9: 1 | Z9: 2 | AA9: 0 | AB9: 0 | AC9: 0 | AD9: 0 | AE9: 1 | AF9: 2 | AG9: 1 | AH9: 0 | AI9: 0 | AJ9: 0 | AK9: 2 | AL9: 1 | AM9: 0 | AN9: 0 | AO9: 0 | AP9: 2 | AQ9: 1 | AR9: 0 | AS9: 1 | AT9: 0 | AU9: 1 | AV9: 0 | AW9: 0 | AX9: 0 | AY9: 1 | AZ9: 2 | BA9: 1 | BB9: 0 | BC9: 0 | BD9: 0 | BE9: 0 | BF9: 0 | BG9: 0 | BH9: 0 | BI9: 0 | BJ9: 0 | BK9: 1 | BL9: 0 | BM9: 0 | BN9: 1 | BO9: 0 | BP9: 0 | BQ9: 0 | BR9: 2 | BS9: 0 | BT9: 0 | BU9: 0 | BV9: 2
A10: =A9+1 -> 5 | B10: Bengkulu | C10: =sum(I10:T10) -> 1 | D10: =sum(U10:AF10) -> 0 | E10: =sum(AG10:AR10) -> 1 | F10: =SUM(AS10:BD10) -> 0 | G10: =sum(BE10:BP10) -> 0 | H10: =Bengkulu!$H$8 -> 2 | I10: 0 | J10: 0 | K10: 0 | L10: 0 | M10: 0 | N10: 0 | O10: 0 | P10: 0 | Q10: 1 | R10: 0 | S10: 0 | T10: 0 | U10: 0 | V10: 0 | W10: 0 | X10: 0 | Y10: 0 | Z10: 0 | AA10: 0 | AB10: 0 | AC10: 0 | AD10: 0 | AE10: 0 | AF10: 0 | AG10: 0 | AH10: 0 | AI10: 0 | AJ10: 0 | AK10: 0 | AL10: 0 | AM10: 0 | AN10: 0 | AO10: 0 | AP10: 0 | AQ10: 1 | AR10: 0 | AS10: 0 | AT10: 0 | AU10: 0 | AV10: 0 | AW10: 0 | AX10: 0 | AY10: 0 | AZ10: =COUNTA(Aceh!D35) -> 0 | BA10: 0 | BB10: 0 | BC10: 0 | BD10: 0 | BE10: 0 | BF10: 0 | BG10: 0 | BH10: 0 | BI10: 0 | BJ10: 0 | BK10: 0 | BL10: 0 | BN10: 0 | BO10: 0 | BP10: 0 | BQ10: 0 | BR10: 0 | BS10: 0 | BT10: 0 | BU10: 0 | BV10: 0
A11: =A10+1 -> 6 | B11: Riau | C11: =sum(I11:T11) -> 0 | D11: =sum(U11:AF11) -> 7 | E11: =sum(AG11:AR11) -> 4 | F11: =SUM(AS11:BD11) -> 1 | G11: =sum(BE11:BP11) -> 5 | H11: =Riau!$H$25 -> 20 | I11: 0 | J11: 0 | K11: 0 | L11: 0 | M11: 0 | N11: 0 | O11: 0 | P11: 0 | Q11: 0 | R11: 0 | S11: 0 | T11: 0 | U11: 2 | V11: 1 | W11: 1 | X11: 2 | Y11: 0 | Z11: 1 | AA11: 0 | AB11: 0 | AC11: 0 | AD11: 0 | AE11: 0 | AF11: 0 | AG11: 0 | AH11: 1 | AI11: 0 | AJ11: 0 | AK11: 1 | AL11: 0 | AM11: 0 | AN11: 0 | AO11: 1 | AP11: 0 | AQ11: 0 | AR11: 1 | AS11: 0 | AT11: 0 | AU11: 0 | AV11: 0 | AW11: 0 | AX11: 0 | AY11: 0 | AZ11: =COUNTA(Aceh!D36) -> 0 | BA11: 0 | BB11: 0 | BC11: 1 | BD11: 0 | BE11: 1 | BF11: 1 | BG11: 0 | BH11: 0 | BI11: 1 | BJ11: 0 | BK11: 1 | BL11: 1 | BM11: 0 | BN11: 0 | BO11: 0 | BP11: 0 | BQ11: 1 | BR11: 0 | BS11: 0 | BT11: 1 | BU11: 0 | BV11: 0
A12: =A11+1 -> 7 | B12: Kepulauan Riau | C12: =sum(I12:T12) -> 16 | D12: =sum(U12:AF12) -> 5 | E12: =sum(AG12:AR12) -> 3 | F12: =SUM(AS12:BD12) -> 11 | G12: =sum(BE12:BP12) -> 9 | H12: ='Kepulauan Riau '!$H$61 -> 51 | I12: 0 | J12: 0 | K12: 0 | L12: 0 | M12: 2 | N12: 3 | O12: 2 | P12: 2 | Q12: 3 | R12: 1 | S12: 0 | T12: 3 | U12: 0 | V12: 0 | W12: 0 | X12: 0 | Y12: 1 | Z12: 1 | AA12: 1 | AB12: 0 | AC12: 0 | AD12: 0 | AE12: 1 | AF12: 1 | AG12: 1 | AH12: 0 | AI12: 0 | AJ12: 1 | AK12: 0 | AL12: 0 | AM12: 0 | AN12: 0 | AO12: 0 | AP12: 0 | AQ12: 1 | AR12: 0 | AS12: 2 | AT12: 1 | AU12: 1 | AV12: 0 | AW12: 1 | AX12: 1 | AY12: 3 | AZ12: =COUNTA(Aceh!D37) -> 0 | BA12: 1 | BB12: 1 | BC12: 0 | BD12: 0 | BE12: 1 | BF12: 1 | BG12: 1 | BH12: 1 | BI12: 1 | BJ12: 1 | BK12: 1 | BL12: 0 | BM12: 0 | BN12: 1 | BO12: 0 | BP12: 1 | BQ12: 3 | BR12: 4 | BS12: 2 | BT12: 0 | BU12: 1 | BV12: 0
A13: =A12+1 -> 8 | B13: Jambi | C13: =sum(I13:T13) -> 1 | D13: =sum(U13:AF13) -> 1 | E13: =sum(AG13:AR13) -> 2 | F13: =SUM(AS13:BD13) -> 2 | G13: =sum(BE13:BP13) -> 13 | H13: =Jambi!$H$28 -> 22 | I13: 0 | J13: 0 | K13: 0 | L13: 0 | M13: 0 | N13: 0 | O13: 0 | P13: 0 | Q13: 0 | R13: 0 | S13: 0 | T13: 1 | U13: 0 | V13: 0 | W13: 0 | X13: 1 | Y13: 0 | Z13: 0 | AA13: 0 | AB13: 0 | AC13: 0 | AD13: 0 | AE13: 0 | AF13: 0 | AG13: 0 | AH13: 0 | AI13: 0 | AJ13: 0 | AK13: 0 | AL13: 0 | AM13: 1 | AN13: 0 | AO13: 0 | AP13: 0 | AQ13: 0 | AR13: 1 | AS13: 0 | AT13: 0 | AU13: 0 | AV13: 0 | AW13: 0 | AX13: 0 | AY13: 0 | AZ13: =COUNTA(Aceh!D38) -> 0 | BA13: 0 | BB13: 2 | BC13: 0 | BD13: 0 | BE13: 2 | BF13: 1 | BG13: 0 | BH13: 1 | BI13: 1 | BJ13: 0 | BK13: 1 | BL13: 5 | BM13: 1 | BN13: 1 | BO13: 0 | BP13: 0 | BQ13: 0 | BR13: 0 | BS13: 0 | BT13: 0 | BU13: 2 | BV13: 1
A14: =A13+1 -> 9 | B14: Lampung | C14: =sum(I14:T14) -> 4 | D14: =sum(U14:AF14) -> 3 | E14: =sum(AG14:AR14) -> 6 | F14: =SUM(AS14:BD14) -> 5 | G14: =sum(BE14:BP14) -> 4 | H14: =Lampung!$H$30 -> 22 | I14: 0 | J14: 0 | K14: 0 | L14: 0 | M14: 0 | N14: 1 | O14: 0 | P14: 1 | Q14: 1 | R14: 1 | S14: 0 | T14: 0 | U14: 1 | V14: 0 | W14: 0 | X14: 0 | Y14: 1 | Z14: 0 | AA14: 0 | AB14: 0 | AC14: 0 | AD14: 1 | AE14: 0 | AF14: 0 | AG14: 0 | AH14: 0 | AI14: 0 | AJ14: 0 | AK14: 1 | AL14: 1 | AM14: 1 | AN14: 1 | AO14: 0 | AP14: 0 | AQ14: 0 | AR14: 2 | AS14: 2 | AT14: 0 | AU14: 0 | AV14: 1 | AW14: 1 | AX14: 0 | AY14: 1 | AZ14: =COUNTA(Aceh!D39) -> 0 | BA14: 0 | BB14: 0 | BC14: 0 | BD14: 0 | BE14: 0 | BF14: 1 | BG14: 1 | BH14: 0 | BI14: 1 | BJ14: 0 | BK14: 1 | BL14: 0 | BM14: 0 | BN14: 0 | BO14: 0 | BP14: 0 | BQ14: 1 | BR14: 0 | BS14: 0 | BT14: 0 | BU14: 1 | BV14: 0
A15: =A14+1 -> 10 | B15: Bangka Belitung | C15: =sum(I15:T15) -> 2 | D15: =sum(U15:AF15) -> 0 | E15: =sum(AG15:AR15) -> 0 | F15: =SUM(AS15:BD15) -> 2 | G15: =sum(BE15:BP15) -> 0 | H15: ='Bangka Belitung'!$H$10 -> 4 | I15: 0 | J15: 0 | K15: 0 | L15: 0 | M15: 0 | N15: 0 | O15: 1 | P15: 1 | Q15: 0 | R15: 0 | S15: 0 | T15: 0 | U15: 0 | V15: 0 | W15: 0 | X15: 0 | Y15: 0 | Z15: 0 | AA15: 0 | AB15: 0 | AC15: 0 | AD15: 0 | AE15: 0 | AF15: 0 | AG15: 0 | AH15: 0 | AI15: 0 | AJ15: 0 | AK15: 0 | AL15: 0 | AM15: 0 | AN15: 0 | AO15: 0 | AP15: 0 | AQ15: 0 | AR15: 0 | AS15: 0 | AT15: 0 | AU15: 1 | AV15: 0 | AW15: 1 | AX15: 0 | AY15: 0 | AZ15: =COUNTA(Aceh!D40) -> 0 | BA15: 0 | BB15: 0 | BC15: 0 | BD15: 0 | BE15: 0 | BF15: 0 | BG15: 0 | BH15: 0 | BI15: 0 | BJ15: 0 | BK15: 0 | BL15: 0 | BM15: 0 | BN15: 0 | BO15: 0 | BP15: 0 | BQ15: 0 | BR15: 0 | BS15: 0 | BT15: 0 | BU15: 0 | BV15: 0
A16: =A15+1 -> 11 | B16: Kalimantan Barat | C16: =sum(I16:T16) -> 7 | D16: =sum(U16:AF16) -> 19 | E16: =sum(AG16:AR16) -> 25 | F16: =SUM(AS16:BD16) -> 23 | G16: =sum(BE16:BP16) -> 15 | H16: ='Kalimantan Barat '!$H$98 -> 91 | I16: 0 | J16: 0 | K16: 0 | L16: 0 | M16: 1 | N16: 2 | O16: 0 | P16: 2 | Q16: 0 | R16: 0 | S16: 1 | T16: 1 | U16: 4 | V16: 3 | W16: 0 | X16: 1 | Y16: 4 | Z16: 1 | AA16: 4 | AB16: 1 | AC16: 0 | AD16: 0 | AE16: 0 | AF16: 1 | AG16: 1 | AH16: 2 | AI16: 0 | AJ16: 1 | AK16: 1 | AL16: 5 | AM16: 1 | AN16: 2 | AO16: 3 | AP16: 2 | AQ16: 4 | AR16: 3 | AS16: 4 | AT16: 2 | AU16: 2 | AV16: 0 | AW16: 3 | AX16: 3 | AY16: 3 | AZ16: =COUNTA(Aceh!D41) -> 0 | BA16: 1 | BB16: 1 | BC16: 2 | BD16: 2 | BE16: 0 | BF16: 6 | BG16: 1 | BH16: 1 | BI16: 1 | BJ16: 1 | BK16: 0 | BL16: 1 | BM16: 2 | BN16: 1 | BO16: 0 | BP16: 1 | BQ16: 1 | BR16: 0 | BS16: 1 | BT16: 0 | BU16: 1 | BV16: 0
A17: =A16+1 -> 12 | B17: Kalimantan Timur | C17: =sum(I17:T17) -> 17 | D17: =sum(U17:AF17) -> 14 | E17: =sum(AG17:AR17) -> 11 | F17: =SUM(AS17:BD17) -> 3 | G17: =sum(BE17:BP17) -> 4 | H17: ='Kalimantan Timur'!$H$56 -> 51 | I17: 0 | J17: 0 | K17: 0 | L17: 0 | M17: 1 | N17: 1 | O17: 0 | P17: 2 | Q17: 0 | R17: 1 | S17: 2 | T17: 10 | U17: 0 | V17: 2 | W17: 2 | X17: 3 | Y17: 1 | Z17: 4 | AA17: 0 | AB17: 1 | AC17: 0 | AD17: 0 | AE17: 1 | AF17: 0 | AG17: 0 | AH17: 0 | AI17: 2 | AJ17: 1 | AK17: 1 | AL17: 1 | AM17: 1 | AN17: 1 | AO17: 2 | AP17: 2 | AQ17: 0 | AR17: 0 | AS17: 0 | AT17: 1 | AU17: 0 | AV17: 0 | AW17: 0 | AX17: 2 | AY17: 0 | AZ17: =COUNTA(Aceh!D42) -> 0 | BA17: 0 | BB17: 0 | BC17: 0 | BD17: 0 | BE17: 0 | BF17: 1 | BG17: 0 | BH17: 0 | BI17: 1 | BJ17: 1 | BK17: 1 | BL17: 0 | BM17: 0 | BN17: 0 | BO17: 0 | BP17: 0 | BQ17: 0 | BR17: 0 | BS17: 0 | BT17: 0 | BU17: 0 | BV17: 1
A18: =A17+1 -> 13 | B18: Kalimantan Selatan | C18: =sum(I18:T18) -> 5 | D18: =sum(U18:AF18) -> 1 | E18: =sum(AG18:AR18) -> 3 | F18: =SUM(AS18:BD18) -> 5 | G18: =sum(BE18:BP18) -> 6 | H18: ='Kalimantan Selatan'!$H$31 -> 25 | I18: 0 | J18: 0 | K18: 0 | L18: 0 | M18: 0 | N18: 0 | O18: 0 | P18: 1 | Q18: 2 | R18: 0 | S18: 0 | T18: 2 | U18: 0 | V18: 0 | W18: 0 | X18: 0 | Y18: 0 | Z18: 0 | AA18: 0 | AB18: 1 | AC18: 0 | AD18: 0 | AE18: 0 | AF18: 0 | AG18: 1 | AH18: 0 | AI18: 0 | AJ18: 1 | AK18: 0 | AL18: 0 | AM18: 0 | AN18: 0 | AO18: 1 | AP18: 0 | AQ18: 0 | AR18: 0 | AS18: 0 | AT18: 0 | AU18: 1 | AV18: 0 | AW18: 1 | AX18: 0 | AY18: 1 | AZ18: =COUNTA(Aceh!D43) -> 0 | BA18: 1 | BB18: 0 | BC18: 0 | BD18: 1 | BE18: 0 | BF18: 1 | BG18: 2 | BH18: 1 | BI18: 0 | BJ18: 0 | BK18: 0 | BL18: 0 | BM18: 1 | BN18: 0 | BO18: 1 | BP18: 0 | BQ18: 0 | BR18: 3 | BS18: 0 | BT18: 0 | BU18: 1 | BV18: 1
A19: =A18+1 -> 14 | B19: Kalimantan Tengah | C19: =sum(I19:T19) -> 5 | D19: =sum(U19:AF19) -> 1 | E19: =sum(AG19:AR19) -> 1 | F19: =SUM(AS19:BD19) -> 2 | G19: =sum(BE19:BP19) -> 3 | H19: ='Kalimantan Tengah '!$H$20 -> 14 | I19: 0 | J19: 0 | K19: 0 | L19: 0 | M19: 1 | N19: 1 | O19: 2 | P19: 0 | Q19: 0 | R19: 1 | S19: 0 | T19: 0 | U19: 0 | V19: 1 | W19: 0 | X19: 0 | Y19: 0 | Z19: 0 | AA19: 0 | AB19: 0 | AC19: 0 | AD19: 0 | AE19: 0 | AF19: 0 | AG19: 0 | AH19: 0 | AI19: 0 | AJ19: 0 | AK19: 0 | AL19: 0 | AM19: 0 | AN19: 0 | AO19: 0 | AP19: 0 | AQ19: 0 | AR19: 1 | AS19: 0 | AT19: 0 | AU19: 0 | AV19: 0 | AW19: 0 | AX19: 0 | AY19: 1 | AZ19: =COUNTA(Aceh!D44) -> 0 | BA19: 1 | BB19: 0 | BC19: 0 | BD19: 0 | BE19: 0 | BF19: 0 | BG19: 1 | BH19: 1 | BI19: 0 | BJ19: 0 | BK19: 0 | BL19: 0 | BM19: 0 | BN19: 0 | BO19: 0 | BP19: 1 | BQ19: 1 | BR19: 0 | BS19: 0 | BT19: 0 | BU19: 0 | BV19: 1
A20: =A19+1 -> 15 | B20: Kalimantan Utara | C20: =sum(I20:T20) -> 1 | D20: =sum(U20:AF20) -> 1 | E20: =sum(AG20:AR20) -> 0 | F20: =SUM(AS20:BD20) -> 1 | G20: =sum(BE20:BP20) -> 0 | H20: ='Kalimantan Utara'!$H$9 -> 4 | I20: 0 | J20: 0 | K20: 0 | L20: 0 | M20: 0 | N20: 0 | O20: 0 | P20: 0 | Q20: 0 | R20: 0 | S20: 1 | T20: 0 | U20: 0 | V20: 0 | W20: 1 | X20: 0 | Y20: 0 | Z20: 0 | AA20: 0 | AB20: 0 | AC20: 0 | AD20: 0 | AE20: 0 | AF20: 0 | AG20: 0 | AH20: 0 | AI20: 0 | AJ20: 0 | AK20: 0 | AL20: 0 | AM20: 0 | AN20: 0 | AO20: 0 | AP20: 0 | AQ20: 0 | AR20: 0 | AS20: 0 | AT20: 0 | AU20: 0 | AV20: 0 | AW20: 0 | AX20: 0 | AY20: 0 | AZ20: =COUNTA(Aceh!D45) -> 0 | BA20: 1 | BB20: 0 | BC20: 0 | BD20: 0 | BE20: 0 | BF20: 0 | BG20: 0 | BH20: 0 | BI20: 0 | BJ20: 0 | BK20: 0 | BL20: 0 | BM20: 0 | BN20: 0 | BO20: 0 | BP20: 0 | BQ20: 0 | BR20: 0 | BS20: 0 | BT20: 0 | BU20: 0 | BV20: 0
A21: =A20+1 -> 16 | B21: Banten | C21: =sum(I21:T21) -> 28 | D21: =sum(U21:AF21) -> 40 | E21: =sum(AG21:AR21) -> 32 | F21: =SUM(AS21:BD21) -> 25 | G21: =sum(BE21:BP21) -> 15 | H21: =Banten!$H$152 -> 141 | I21: 0 | J21: 0 | K21: 0 | L21: 0 | M21: 3 | N21: 4 | O21: 3 | P21: 3 | Q21: 3 | R21: 4 | S21: 5 | T21: 3 | U21: 2 | V21: 6 | W21: 6 | X21: 3 | Y21: 3 | Z21: 2 | AA21: 4 | AB21: 1 | AC21: 4 | AD21: 6 | AE21: 0 | AF21: 3 | AG21: 2 | AH21: 3 | AI21: 1 | AJ21: 2 | AK21: 2 | AL21: 2 | AM21: 4 | AN21: 1 | AO21: 6 | AP21: 3 | AQ21: 1 | AR21: 5 | AS21: 5 | AT21: 4 | AU21: 0 | AV21: 2 | AW21: 5 | AX21: 1 | AY21: 1 | AZ21: =COUNTA(Aceh!D46) -> 0 | BA21: 4 | BB21: 1 | BC21: 0 | BD21: 2 | BE21: 2 | BF21: 0 | BG21: 0 | BH21: 1 | BI21: 1 | BJ21: 3 | BK21: 0 | BL21: 3 | BM21: 0 | BN21: 2 | BO21: 1 | BP21: 2 | BQ21: 2 | BR21: 0 | BS21: 2 | BT21: 0 | BU21: 0 | BV21: 1
A22: =A21+1 -> 17 | B22: DKI Jakarta | C22: =sum(I22:T22) -> 55 | D22: =sum(U22:AF22) -> 47 | E22: =sum(AG22:AR22) -> 69 | F22: =SUM(AS22:BD22) -> 62 | G22: =sum(BE22:BP22) -> 41 | H22: ='DKI Jakarta'!$H$302 -> 294 | I22: 0 | J22: 0 | K22: 0 | L22: 0 | M22: 4 | N22: 10 | O22: 5 | P22: 8 | Q22: 8 | R22: 3 | S22: 11 | T22: 6 | U22: 3 | V22: 5 | W22: 6 | X22: 7 | Y22: 4 | Z22: 4 | AA22: 1 | AB22: 4 | AC22: 7 | AD22: 4 | AE22: 1 | AF22: 1 | AG22: 8 | AH22: 4 | AI22: 5 | AJ22: 6 | AK22: 9 | AL22: 7 | AM22: 7 | AN22: 4 | AO22: 10 | AP22: 3 | AQ22: 2 | AR22: 4 | AS22: 7 | AT22: 5 | AU22: 6 | AV22: 2 | AW22: 14 | AX22: 7 | AY22: 5 | AZ22: 4 | BA22: 4 | BB22: 3 | BC22: 1 | BD22: 4 | BE22: 1 | BF22: 8 | BG22: 1 | BH22: 1 | BI22: 9 | BJ22: 5 | BK22: 2 | BL22: 2 | BM22: 6 | BN22: 2 | BO22: 3 | BP22: 1 | BQ22: 1 | BR22: 4 | BS22: 5 | BT22: 2 | BU22: 5 | BV22: 4
A23: =A22+1 -> 18 | B23: Jawa Barat | C23: =sum(I23:T23) -> 76 | D23: =sum(U23:AF23) -> 91 | E23: =sum(AG23:AR23) -> 79 | F23: =SUM(AS23:BD23) -> 97 | G23: =sum(BE23:BP23) -> 53 | H23: ='Jawa Barat'!$H$433 -> 409 | I23: 0 | J23: 0 | K23: 0 | L23: 0 | M23: 8 | N23: 9 | O23: 5 | P23: 6 | Q23: 10 | R23: 18 | S23: 10 | T23: 10 | U23: 11 | V23: 13 | W23: 8 | X23: 7 | Y23: 11 | Z23: 9 | AA23: 5 | AB23: 5 | AC23: 3 | AD23: 8 | AE23: 7 | AF23: 4 | AG23: 6 | AH23: 6 | AI23: 9 | AJ23: 5 | AK23: 7 | AL23: 6 | AM23: 7 | AN23: 11 | AO23: 8 | AP23: 6 | AQ23: 4 | AR23: 4 | AS23: 12 | AT23: 11 | AU23: 7 | AV23: 4 | AW23: 6 | AX23: 13 | AY23: 9 | AZ23: 6 | BA23: 6 | BB23: 7 | BC23: 7 | BD23: 9 | BE23: 4 | BF23: 6 | BG23: 4 | BH23: 5 | BI23: 10 | BJ23: 3 | BK23: 6 | BL23: 3 | BM23: 5 | BN23: 3 | BO23: 4 | BP23: 0 | BQ23: 3 | BR23: 2 | BS23: 3 | BT23: 3 | BU23: 9 | BV23: 9
A24: =A23+1 -> 19 | B24: Jawa Tengah | C24: =sum(I24:T24) -> 22 | D24: =sum(U24:AF24) -> 32 | E24: =sum(AG24:AR24) -> 41 | F24: =SUM(AS24:BD24) -> 34 | G24: =sum(BE24:BP24) -> 13 | H24: ='Jawa Tengah'!$H$161 -> 152 | I24: 0 | J24: 0 | K24: 0 | L24: 0 | M24: 0 | N24: 4 | O24: 3 | P24: 5 | Q24: 1 | R24: 2 | S24: 1 | T24: 6 | U24: 6 | V24: 0 | W24: 6 | X24: 4 | Y24: 2 | Z24: 3 | AA24: 3 | AB24: 2 | AC24: 1 | AD24: 2 | AE24: 3 | AF24: 0 | AG24: 2 | AH24: 1 | AI24: 4 | AJ24: 5 | AK24: 5 | AL24: 4 | AM24: 4 | AN24: 3 | AO24: 5 | AP24: 5 | AQ24: 0 | AR24: 3 | AS24: 1 | AT24: 5 | AU24: 2 | AV24: 3 | AW24: 4 | AX24: 3 | AY24: 3 | AZ24: 4 | BA24: 1 | BB24: 5 | BC24: 0 | BD24: 3 | BE24: 2 | BF24: 1 | BG24: 0 | BH24: 2 | BI24: 2 | BJ24: 1 | BK24: 0 | BL24: 3 | BM24: 0 | BN24: 0 | BO24: 1 | BP24: 1 | BQ24: 3 | BR24: 1 | BS24: 1 | BT24: 0 | BU24: 4 | BV24: 3
A25: =A24+1 -> 20 | B25: DI Yogyakarta | C25: =sum(I25:T25) -> 6 | D25: =sum(U25:AF25) -> 8 | E25: =sum(AG25:AR25) -> 6 | F25: =SUM(AS25:BD25) -> 3 | G25: =sum(BE25:BP25) -> 6 | H25: ='DI Yogyakarta'!$H$36 -> 30 | I25: 0 | J25: 0 | K25: 0 | L25: 1 | M25: 2 | N25: 0 | O25: 0 | P25: 1 | Q25: 0 | R25: 1 | S25: 1 | T25: 0 | U25: 2 | V25: 0 | W25: 3 | X25: 0 | Y25: 1 | Z25: 0 | AA25: 0 | AB25: 2 | AC25: 0 | AD25: 0 | AE25: 0 | AF25: 0 | AG25: 0 | AH25: 0 | AI25: 1 | AJ25: 0 | AK25: 0 | AL25: 0 | AM25: 1 | AN25: 2 | AO25: 2 | AP25: 0 | AQ25: 0 | AR25: 0 | AS25: 1 | AT25: 0 | AU25: 0 | AV25: 0 | AW25: 0 | AX25: 0 | AY25: 1 | AZ25: 0 | BA25: 0 | BB25: 1 | BC25: 0 | BD25: 0 | BE25: 0 | BF25: 3 | BG25: 0 | BH25: 0 | BI25: 1 | BJ25: 0 | BK25: 0 | BL25: 1 | BM25: 0 | BN25: 0 | BO25: 1 | BP25: 0 | BQ25: 0 | BR25: 0 | BS25: 0 | BT25: 0 | BU25: 0 | BV25: 1
A26: =A25+1 -> 21 | B26: Jawa Timur | C26: =sum(I26:T26) -> 30 | D26: =sum(U26:AF26) -> 52 | E26: =sum(AG26:AR26) -> 20 | F26: =SUM(AS26:BD26) -> 27 | G26: =sum(BE26:BP26) -> 15 | H26: ='Jawa Timur'!$H$158 -> 151 | I26: 0 | J26: 0 | K26: 0 | L26: 0 | M26: 4 | N26: 2 | O26: 2 | P26: 1 | Q26: 6 | R26: 7 | S26: 1 | T26: 7 | U26: 6 | V26: 17 | W26: 4 | X26: 3 | Y26: 4 | Z26: 5 | AA26: 1 | AB26: 3 | AC26: 3 | AD26: 2 | AE26: 0 | AF26: 4 | AG26: 3 | AH26: 4 | AI26: 0 | AJ26: 0 | AK26: 1 | AL26: 3 | AM26: 1 | AN26: 3 | AO26: 3 | AP26: 0 | AQ26: 2 | AR26: 0 | AS26: 4 | AT26: 1 | AU26: 3 | AV26: 1 | AW26: 2 | AX26: 2 | AY26: 2 | AZ26: 2 | BA26: 3 | BB26: 4 | BC26: 2 | BD26: 1 | BE26: 5 | BF26: 0 | BG26: 0 | BH26: 1 | BI26: 1 | BJ26: 0 | BK26: 3 | BL26: 2 | BM26: 0 | BN26: 1 | BO26: 1 | BP26: 1 | BQ26: 2 | BR26: 0 | BS26: 1 | BT26: 1 | BU26: 3 | BV26: 1
A27: =A26+1 -> 22 | B27: Bali | C27: =sum(I27:T27) -> 10 | D27: =sum(U27:AF27) -> 18 | E27: =sum(AG27:AR27) -> 11 | F27: =SUM(AS27:BD27) -> 7 | G27: =sum(BE27:BP27) -> 6 | H27: =Bali!$H$63 -> 57 | I27: 0 | J27: 0 | K27: 0 | L27: 0 | M27: 2 | N27: 0 | O27: 1 | P27: 0 | Q27: 1 | R27: 2 | S27: 1 | T27: 3 | U27: 1 | V27: 2 | W27: 3 | X27: 0 | Y27: 1 | Z27: 0 | AA27: 2 | AB27: 3 | AC27: 0 | AD27: 4 | AE27: 1 | AF27: 1 | AG27: 2 | AH27: 0 | AI27: 1 | AJ27: 0 | AK27: 1 | AL27: 0 | AM27: 0 | AN27: 1 | AO27: 2 | AP27: 1 | AQ27: 1 | AR27: 2 | AS27: 1 | AT27: 0 | AU27: 1 | AV27: 1 | AW27: 0 | AX27: 2 | AY27: 0 | AZ27: =COUNTA(Aceh!D52) -> 0 | BA27: 1 | BB27: 0 | BC27: 0 | BD27: 1 | BE27: 1 | BF27: 1 | BG27: 1 | BH27: 0 | BI27: 1 | BJ27: 1 | BK27: 0 | BL27: 0 | BM27: 1 | BN27: 0 | BO27: 0 | BP27: 0 | BQ27: 0 | BR27: 1 | BS27: 0 | BT27: 1 | BU27: 2 | BV27: 1
A28: =A27+1 -> 23 | B28: Nusa Tenggara Timur | C28: =sum(I28:T28) -> 1 | D28: =sum(U28:AF28) -> 2 | E28: =sum(AG28:AR28) -> 0 | F28: =SUM(AS28:BD28) -> 0 | G28: =sum(BE28:BP28) -> 13 | H28: ='Nusa Tenggara Timur'!$H$25 -> 20 | I28: 0 | J28: 0 | K28: 0 | L28: 0 | M28: 0 | N28: 0 | O28: 0 | P28: 0 | Q28: 1 | R28: 0 | S28: 0 | T28: 0 | U28: 0 | V28: 0 | W28: 1 | X28: 0 | Y28: 0 | Z28: 0 | AA28: 0 | AB28: 0 | AC28: 1 | AD28: 0 | AE28: 0 | AF28: 0 | AG28: 0 | AH28: 0 | AI28: 0 | AJ28: 0 | AK28: 0 | AL28: 0 | AM28: 0 | AN28: 0 | AO28: 0 | AP28: 0 | AQ28: 0 | AR28: 0 | AS28: 0 | AT28: 0 | AU28: 0 | AV28: 0 | AW28: 0 | AX28: 0 | AY28: 0 | AZ28: =COUNTA(Aceh!D53) -> 0 | BA28: 0 | BB28: 0 | BC28: 0 | BD28: 0 | BE28: 0 | BF28: 0 | BG28: 3 | BH28: 1 | BI28: 0 | BJ28: 0 | BK28: 0 | BL28: 1 | BM28: 0 | BN28: 1 | BO28: 1 | BP28: 6 | BQ28: 0 | BR28: 1 | BS28: 0 | BT28: 0 | BU28: 2 | BV28: 0
A29: =A28+1 -> 24 | B29: Nusa Tenggara Barat | C29: =sum(I29:T29) -> 2 | D29: =sum(U29:AF29) -> 3 | E29: =sum(AG29:AR29) -> 0 | F29: =SUM(AS29:BD29) -> 1 | G29: =sum(BE29:BP29) -> 1 | H29: ='Nusa Tenggara Barat'!$H$13 -> 8 | I29: 0 | J29: 0 | K29: 0 | L29: 0 | M29: 0 | N29: 1 | O29: 1 | P29: 0 | Q29: 0 | R29: 0 | S29: 0 | T29: 0 | U29: 0 | V29: 1 | W29: 0 | X29: 0 | Y29: 1 | Z29: 0 | AA29: 0 | AB29: 0 | AC29: 0 | AD29: 0 | AE29: 1 | AF29: 0 | AG29: 0 | AH29: 0 | AI29: 0 | AJ29: 0 | AK29: 0 | AL29: 0 | AM29: 0 | AN29: 0 | AO29: 0 | AP29: 0 | AQ29: 0 | AR29: 0 | AS29: 0 | AT29: 0 | AU29: 0 | AV29: 0 | AW29: 0 | AX29: 1 | AY29: 0 | AZ29: =COUNTA(Aceh!D54) -> 0 | BA29: 0 | BB29: 0 | BC29: 0 | BD29: 0 | BE29: 0 | BF29: 0 | BG29: 0 | BH29: 0 | BI29: 0 | BJ29: 0 | BK29: 0 | BL29: 0 | BM29: 0 | BN29: 1 | BO29: 0 | BP29: 0 | BQ29: 0 | BR29: 0 | BS29: 0 | BT29: 0 | BU29: 0 | BV29: 0
A30: =A29+1 -> 25 | B30: Gorontalo | C30: =sum(I30:T30) -> 2 | D30: =sum(U30:AF30) -> 1 | E30: =sum(AG30:AR30) -> 0 | F30: =SUM(AS30:BD30) -> 0 | G30: =sum(BE30:BP30) -> 1 | H30: ='Gorontalo '!$H$10 -> 4 | I30: 0 | J30: 0 | K30: 0 | L30: 0 | M30: 0 | N30: 0 | O30: 0 | P30: 2 | Q30: 0 | R30: 0 | S30: 0 | T30: 0 | U30: 0 | V30: 0 | W30: 0 | X30: 0 | Y30: 1 | Z30: 0 | AA30: 0 | AB30: 0 | AC30: 0 | AD30: 0 | AE30: 0 | AF30: 0 | AG30: 0 | AH30: 0 | AI30: 0 | AJ30: 0 | AK30: 0 | AL30: 0 | AM30: 0 | AN30: 0 | AO30: 0 | AP30: 0 | AQ30: 0 | AR30: 0 | AS30: 0 | AT30: 0 | AU30: 0 | AV30: 0 | AW30: 0 | AX30: 0 | AY30: 0 | AZ30: =COUNTA(Aceh!D55) -> 0 | BA30: 0 | BB30: 0 | BC30: 0 | BD30: 0 | BE30: 0 | BF30: 0 | BG30: 0 | BH30: 0 | BI30: 0 | BJ30: 0 | BK30: 1 | BL30: 0 | BM30: 0 | BN30: 0 | BO30: 0 | BP30: 0 | BQ30: 0 | BR30: 0 | BS30: 0 | BT30: 0 | BU30: 0 | BV30: 0
A31: =A30+1 -> 26 | B31: Sulawesi Barat | C31: =sum(I31:T31) -> 1 | D31: =sum(U31:AF31) -> 1 | E31: =sum(AG31:AR31) -> 1 | F31: =SUM(AS31:BD31) -> 7 | G31: =sum(BE31:BP31) -> 0 | H31: ='Sulawesi Barat'!$H$16 -> 9 | I31: 0 | J31: 0 | K31: 0 | L31: 0 | M31: 0 | N31: 0 | O31: 0 | P31: 0 | Q31: 0 | R31: 0 | S31: 1 | T31: 0 | U31: 1 | V31: 0 | W31: 0 | X31: 0 | Y31: 0 | Z31: 0 | AA31: 0 | AB31: 0 | AC31: 0 | AD31: 0 | AE31: 0 | AF31: 0 | AG31: 0 | AH31: 0 | AI31: 0 | AJ31: 0 | AK31: 0 | AL31: 0 | AM31: 0 | AN31: 0 | AO31: 0 | AP31: 1 | AQ31: 0 | AR31: 0 | AS31: 0 | AT31: 2 | AU31: 0 | AV31: 0 | AW31: 1 | AX31: 1 | AY31: 0 | AZ31: 1 | BA31: 0 | BB31: 1 | BC31: 1 | BD31: 0 | BE31: 0 | BF31: 0 | BG31: 0 | BH31: 0 | BI31: 0 | BJ31: 0 | BK31: 0 | BL31: 0 | BM31: 0 | BN31: 0 | BO31: 0 | BP31: 0 | BQ31: 0 | BR31: 0 | BS31: 0 | BT31: 0 | BU31: 0 | BV31: 0
A32: =A31+1 -> 27 | B32: Sulawesi Tengah | C32: =sum(I32:T32) -> 3 | D32: =sum(U32:AF32) -> 3 | E32: =sum(AG32:AR32) -> 7 | F32: =SUM(AS32:BD32) -> 8 | G32: =sum(BE32:BP32) -> 0 | H32: ='Sulawesi Tengah '!$H$27 -> 22 | I32: 0 | J32: 0 | K32: 0 | L32: 0 | M32: 1 | N32: 0 | O32: 1 | P32: 1 | Q32: 0 | R32: 0 | S32: 0 | T32: 0 | U32: 0 | V32: 0 | W32: 1 | X32: 1 | Y32: 0 | Z32: 0 | AA32: 0 | AB32: 1 | AC32: 0 | AD32: 0 | AE32: 0 | AF32: 0 | AG32: 0 | AH32: 2 | AI32: 1 | AJ32: 0 | AK32: 0 | AL32: 0 | AM32: 0 | AN32: 0 | AO32: 0 | AP32: 2 | AQ32: 2 | AR32: 0 | AS32: 1 | AT32: 1 | AU32: 0 | AV32: 1 | AW32: 2 | AX32: 0 | AY32: 0 | AZ32: 1 | BA32: 0 | BB32: 1 | BC32: 1 | BD32: 0 | BE32: 0 | BF32: 0 | BG32: 0 | BH32: 0 | BI32: 0 | BJ32: 0 | BK32: 0 | BL32: 0 | BM32: 0 | BN32: 0 | BO32: 0 | BP32: 0 | BQ32: 0 | BR32: 0 | BS32: 0 | BT32: 0 | BU32: 0 | BV32: 0
A33: =A32+1 -> 28 | B33: Sulawesi Utara | C33: =sum(I33:T33) -> 5 | D33: =sum(U33:AF33) -> 9 | E33: =sum(AG33:AR33) -> 7 | F33: =SUM(AS33:BD33) -> 2 | G33: =sum(BE33:BP33) -> 1 | H33: ='Sulawesi Utara'!$H$31 -> 26 | I33: 0 | J33: 0 | K33: 0 | L33: 0 | M33: 0 | N33: 3 | O33: 2 | P33: 0 | Q33: 0 | R33: 0 | S33: 0 | T33: 0 | U33: 1 | V33: 0 | W33: 0 | X33: 1 | Y33: 3 | Z33: 2 | AA33: 2 | AB33: 0 | AC33: 0 | AD33: 0 | AE33: 0 | AF33: 0 | AG33: 1 | AH33: 2 | AI33: 0 | AJ33: 0 | AK33: 0 | AL33: 0 | AM33: 0 | AN33: 0 | AO33: 1 | AP33: 3 | AQ33: 0 | AR33: 0 | AS33: 0 | AT33: 0 | AU33: 0 | AV33: 0 | AW33: 0 | AX33: 0 | AY33: 1 | AZ33: =COUNTA(Aceh!D58) -> 0 | BA33: 0 | BB33: 0 | BC33: 1 | BD33: 0 | BE33: 0 | BF33: 1 | BG33: 0 | BH33: 0 | BI33: 0 | BJ33: 0 | BK33: 0 | BL33: 0 | BM33: 0 | BN33: 0 | BO33: 0 | BP33: 0 | BQ33: 0 | BR33: 0 | BS33: 0 | BT33: 0 | BU33: 2 | BV33: 0
A34: =A33+1 -> 29 | B34: Sulawesi Tenggara | C34: =sum(I34:T34) -> 4 | D34: =sum(U34:AF34) -> 4 | E34: =sum(AG34:AR34) -> 0 | F34: =SUM(AS34:BD34) -> 1 | G34: =sum(BE34:BP34) -> 1 | H34: ='Sulawesi Tenggara'!$H$19 -> 14 | I34: 0 | J34: 0 | K34: 0 | L34: 0 | M34: 0 | N34: 2 | O34: 0 | P34: 0 | Q34: 2 | R34: 0 | S34: 0 | T34: 0 | U34: 1 | V34: 0 | W34: 0 | X34: 0 | Y34: 0 | Z34: 1 | AA34: 0 | AB34: 0 | AC34: 0 | AD34: 0 | AE34: 0 | AF34: 2 | AG34: 0 | AH34: 0 | AI34: 0 | AJ34: 0 | AK34: 0 | AL34: 0 | AM34: 0 | AN34: 0 | AO34: 0 | AP34: 0 | AQ34: 0 | AR34: 0 | AS34: 0 | AT34: 0 | AU34: 0 | AV34: 0 | AW34: 0 | AX34: 0 | AY34: 0 | AZ34: 1 | BA34: 0 | BB34: 0 | BC34: 0 | BD34: 0 | BE34: 0 | BF34: 1 | BG34: 0 | BH34: 0 | BI34: 0 | BJ34: 0 | BK34: 0 | BL34: 0 | BM34: 0 | BN34: 0 | BO34: 0 | BP34: 0 | BQ34: 1 | BR34: 0 | BS34: 0 | BT34: 0 | BU34: 1 | BV34: 1
A35: =A34+1 -> 30 | B35: Sulawesi Selatan | C35: =sum(I35:T35) -> 14 | D35: =sum(U35:AF35) -> 19 | E35: =sum(AG35:AR35) -> 9 | F35: =SUM(AS35:BD35) -> 7 | G35: =sum(BE35:BP35) -> 4 | H35: ='Sulawesi Selatan'!$H$60 -> 55 | I35: 0 | J35: 0 | K35: 0 | L35: 0 | M35: 2 | N35: 1 | O35: 1 | P35: 1 | Q35: 0 | R35: 1 | S35: 3 | T35: 5 | U35: 5 | V35: 6 | W35: 3 | X35: 2 | Y35: 1 | Z35: 0 | AA35: 0 | AB35: 2 | AC35: 0 | AD35: 0 | AE35: 0 | AF35: 0 | AG35: 1 | AH35: 0 | AI35: 0 | AJ35: 0 | AK35: 1 | AL35: 1 | AM35: 0 | AN35: 2 | AO35: 0 | AP35: 1 | AQ35: 3 | AR35: 0 | AS35: 2 | AT35: 0 | AU35: 1 | AV35: 0 | AW35: 0 | AX35: 0 | AY35: 0 | AZ35: 2 | BA35: 0 | BB35: 1 | BC35: 0 | BD35: 1 | BE35: 0 | BF35: 1 | BG35: 0 | BH35: 1 | BI35: 0 | BJ35: 1 | BK35: 0 | BL35: 0 | BM35: 1 | BN35: 0 | BO35: 0 | BP35: 0 | BQ35: 0 | BR35: 0 | BS35: 0 | BT35: 0 | BU35: 0 | BV35: 1
A36: =A35+1 -> 31 | B36: Maluku Utara | C36: =sum(I36:T36) -> 0 | D36: =sum(U36:AF36) -> 0 | E36: =sum(AG36:AR36) -> 0 | F36: =SUM(AS36:BD36) -> 0 | G36: =sum(BE36:BP36) -> 0 | H36: 0 | I36: 0 | J36: 0 | K36: 0 | L36: 0 | M36: 0 | N36: 0 | O36: 0 | P36: 0 | Q36: 0 | R36: 0 | S36: 0 | T36: 0 | U36: 0 | V36: 0 | W36: 0 | X36: 0 | Y36: 0 | Z36: 0 | AA36: 0 | AB36: 0 | AC36: 0 | AD36: 0 | AE36: 0 | AF36: 0 | AG36: 0 | AH36: 0 | AI36: 0 | AJ36: 0 | AK36: 0 | AL36: 0 | AM36: 0 | AN36: 0 | AO36: 0 | AP36: 0 | AQ36: 0 | AR36: 0 | AS36: 0 | AT36: 0 | AU36: 0 | AV36: 0 | AW36: 0 | AX36: 0 | AY36: 0 | AZ36: 0 | BA36: 0 | BB36: 0 | BC36: 0 | BD36: 0 | BE36: 0 | BF36: 0 | BG36: 0 | BH36: 0 | BI36: 0 | BJ36: 0 | BK36: 0 | BL36: 0 | BM36: 0 | BN36: 0 | BO36: 0 | BP36: 0 | BQ36: 0 | BR36: 0 | BS36: 0 | BT36: 0 | BU36: 0 | BV36: 0
A37: =A36+1 -> 32 | B37: Maluku | C37: =sum(I37:T37) -> 1 | D37: =sum(U37:AF37) -> 0 | E37: =sum(AG37:AR37) -> 0 | F37: =SUM(AS37:BD37) -> 1 | G37: =sum(BE37:BP37) -> 0 | H37: ='Maluku '!$H$8 -> 3 | I37: 0 | J37: 0 | K37: 0 | L37: 1 | M37: 0 | N37: 0 | O37: 0 | P37: 0 | Q37: 0 | R37: 0 | S37: 0 | T37: 0 | U37: 0 | V37: 0 | W37: 0 | X37: 0 | Y37: 0 | Z37: 0 | AA37: 0 | AB37: 0 | AC37: 0 | AD37: 0 | AE37: 0 | AF37: 0 | AG37: 0 | AH37: 0 | AI37: 0 | AJ37: 0 | AK37: 0 | AL37: 0 | AM37: 0 | AN37: 0 | AO37: 0 | AP37: 0 | AQ37: 0 | AR37: 0 | AS37: 0 | AT37: 0 | AU37: 0 | AV37: 0 | AW37: 0 | AX37: 0 | AY37: 0 | AZ37: =COUNTA(Aceh!D62) -> 0 | BA37: 0 | BB37: 0 | BC37: 0 | BD37: 1 | BE37: 0 | BF37: 0 | BG37: 0 | BH37: 0 | BI37: 0 | BJ37: 0 | BK37: 0 | BL37: 0 | BM37: 0 | BN37: 0 | BO37: 0 | BP37: 0 | BQ37: 0 | BR37: 0 | BS37: 0 | BT37: 0 | BU37: 0 | BV37: 0
A38: =A37+1 -> 33 | B38: Papua Barat | C38: =sum(I38:T38) -> 0 | D38: =sum(U38:AF38) -> 0 | E38: =sum(AG38:AR38) -> 0 | F38: =SUM(AS38:BD38) -> 1 | G38: =sum(BE38:BP38) -> 1 | H38: ='Papua Barat'!$E$8 -> 2 | I38: 0 | J38: 0 | K38: 0 | L38: 0 | M38: 0 | N38: 0 | O38: 0 | P38: 0 | Q38: 0 | R38: 0 | S38: 0 | T38: 0 | U38: 0 | V38: 0 | W38: 0 | X38: 0 | Y38: 0 | Z38: 0 | AA38: 0 | AB38: 0 | AC38: 0 | AD38: 0 | AE38: 0 | AF38: 0 | AG38: 0 | AH38: 0 | AI38: 0 | AJ38: 0 | AK38: 0 | AL38: 0 | AM38: 0 | AN38: 0 | AO38: 0 | AP38: 0 | AQ38: 0 | AR38: 0 | AS38: 0 | AT38: 0 | AU38: 0 | AV38: 0 | AW38: 1 | AX38: 0 | AY38: 0 | AZ38: =COUNTA(Aceh!D63) -> 0 | BA38: 0 | BB38: 0 | BC38: 0 | BD38: 0 | BE38: 0 | BF38: 0 | BG38: 0 | BH38: 0 | BI38: 0 | BJ38: 0 | BK38: 0 | BL38: 0 | BM38: 1 | BN38: 0 | BO38: 0 | BP38: 0 | BQ38: 0 | BR38: 0 | BS38: 0 | BT38: 0 | BU38: 0 | BV38: 0
A39: =A38+1 -> 34 | B39: Papua | C39: =sum(I39:T39) -> 4 | D39: =sum(U39:AF39) -> 2 | E39: =sum(AG39:AR39) -> 4 | F39: =SUM(AS39:BD39) -> 1 | G39: =sum(BE39:BP39) -> 2 | H39: ='Papua '!$H$20 -> 14 | I39: 0 | J39: 0 | K39: 0 | L39: 0 | M39: 0 | N39: 0 | O39: 1 | P39: 0 | Q39: 1 | R39: 1 | S39: 1 | T39: 0 | U39: 0 | V39: 1 | W39: 1 | X39: 0 | Y39: 0 | Z39: 0 | AA39: 0 | AB39: 0 | AC39: 0 | AD39: 0 | AE39: 0 | AF39: 0 | AG39: 0 | AH39: 0 | AI39: 0 | AJ39: 1 | AK39: 0 | AL39: 2 | AM39: 1 | AN39: 0 | AO39: 0 | AP39: 0 | AQ39: 0 | AR39: 0 | AS39: 0 | AT39: 0 | AU39: 0 | AV39: 0 | AW39: 0 | AX39: 0 | AY39: 0 | AZ39: =COUNTA(Aceh!D64) -> 0 | BA39: 0 | BB39: 1 | BC39: 0 | BD39: 0 | BE39: 0 | BF39: 0 | BG39: 1 | BH39: 0 | BI39: 0 | BJ39: 0 | BK39: 0 | BL39: 0 | BM39: 0 | BN39: 0 | BO39: 1 | BP39: 0 | BQ39: 0 | BR39: 1 | BS39: 0 | BT39: 0 | BU39: 0 | BV39: 0
A40: =A39+1 -> 35 | B40: Papua Tengah | C40: =sum(I40:T40) -> 0 | D40: =sum(U40:AF40) -> 0 | E40: =sum(AG40:AR40) -> 0 | F40: =SUM(AS40:BD40) -> 0 | G40: =sum(BE40:BP40) -> 0 | H40: 0 | I40: 0 | J40: 0 | K40: 0 | L40: 0 | M40: 0 | N40: 0 | O40: 0 | P40: 0 | Q40: 0 | R40: 0 | S40: 0 | T40: 0 | U40: 0 | V40: 0 | W40: 0 | X40: 0 | Y40: 0 | Z40: 0 | AA40: 0 | AB40: 0 | AC40: 0 | AD40: 0 | AE40: 0 | AF40: 0 | AG40: 0 | AH40: 0 | AI40: 0 | AJ40: 0 | AK40: 0 | AL40: 0 | AM40: 0 | AN40: 0 | AO40: 0 | AP40: 0 | AQ40: 0 | AR40: 0 | AS40: 0 | AT40: 0 | AU40: 0 | AV40: 0 | AW40: 0 | AX40: 0 | AY40: 0 | AZ40: 0 | BA40: 0 | BB40: 0 | BC40: 0 | BD40: 0 | BE40: 0 | BF40: 0 | BG40: 0 | BH40: 0 | BI40: 0 | BJ40: 0 | BK40: 0 | BL40: 0 | BM40: 0 | BN40: 0 | BO40: 0 | BP40: 0 | BQ40: 0 | BR40: 0 | BS40: 0 | BT40: 0 | BU40: 0 | BV40: 0
...

Sheet Aceh
A1: PT PIPOSMART DIGITAL INDONESIA
A2: Laporan Nasabah Baru
A3: Tahun 2026
A4: Nomor | B4: Tahun Member | C4: Bulan | D4: Kode Owner | E4: Nama Owner | F4: No. Hp Owner | G4: Email | H4: Project/Outlet | I4: Kota | J4: Alamat
A5: 1 | B5: 2021 | C5: Juli | D5: 1609 | E5: Nur Anita dewi | F5: 0822 7718 8487 | G5: nuranita642@gmail.com | H5: sahabat laundry/SAHABAT LAUNDRY KILOAN GRATIS ANTAR JEMPUT.praktis-mudah-aman-bersih dan suci. | I5: Kab. Aceh Tamiang | J5: dusun bahagia perumahan mutiara residen 2 blok k nmr 9 tanah terban
A6: 2 | B6: 2021 | C6: Agustus | D6: 307 | E6: SURIATI | F6: 0813 60608515 | G6: isur.bna@gmail.com | H6: A&Z LAUNDRY/AZ LAUNDRY | I6: Kab. Aceh Besar | J6: jln. limpo Desa Meunasah papeun
A7: 3 | B7: 2021 | C7: Oktober | D7: 2838 | E7: rafka | F7: 0813 60283975 | G7: 46laundryexpress@gmail.com | H7: 46laundry express | I7: Kota Banda Aceh | J7: jln. Taman siswa no 27 samping Adi kupi
A8: 4 | B8: 2021 | C8: Desember | D8: 3609 | E8: Nayla | F8: 0813 60455014 | G8: Cutmini1988@gmail.com | H8: mini laundry/Mini Laundry Syariah | I8: Kab. Aceh Barat Daya | J8: komplek terminal blangpidie aceh barat daya
A9: 5 | B9: 2022 | C9: Januari | D9: 4325 | E9: muhammad Riza | F9: 0813 17879281 | G9: mina_Laundry@gmail.com | H9: MINA LAUNDRY | I9: Kab. Pidie | J9: jalan Medan-Banda aceh KM 125samping Polsek Mutiara Timur. Beureunuen. Kab Pidie
A10: 6 | B10: 2022 | C10: Februari | D10: 4353 | E10: Laundry Kiloan Lueng Bata | F10: 0812 75988253 | G10: luengbatalaundrykiloan@gmail.com | H10: Laundry Kiloan Lueng Bata | I10: Kota Banda Aceh | J10: Jln. Tgk. Imuem Lueng Bata no. 25Samping Bank BSIBanda Aceh
A11: 7 | B11: 2022 | C11: Juni | D11: 6023 | E11: Annisa loundry | F11: 0823 6386 4228 | G11: syibral28@gmail.com | H11: annisa | I11: Kota Lhokseumawe | J11: jln.medan Banda Aceh depan kampus IAIN samping cultur coffee
A12: 8 | B12: 2022 | C12: Juni | D12: 6331 | E12: Admin | F12: 08116812501 | G12: laundryjamboo@gmail.com | H12: Jamboo Laundry | I12: Kota Banda Aceh | J12: Jalan Chik Dipineung Raya
A13: 9 | B13: 2022 | C13: Agustus | D13: 6411 | E13: Agustianto Rusdi | F13: 0811 688 0989 | G13: agustiantorusdi26@gmail.com | H13: ym laundry | I13: Kota Banda Aceh | J13: Teuku umar no 253
A14: 10 | B14: 2022 | C14: September | D14: 6928 | E14: Rais Fahrizal | F14: 082360612025 | G14: laundrycoin124@gmail.com | H14: 124 Laundry | I14: Kab. Aceh Besar | J14: jln.laksamana Malahayati Gampong ba'et kecamatan Baitussalam Aceh besar
A15: 11 | B15: 2022 | C15: November | D15: 7436 | E15: Agustian Saputra | F15: 0853 7989 4486 | G15: rafkacoinlaundry@gmail.com | H15: rafkacoinlaundry/rafkacoinlaundry | I15: Kota Banda Aceh | J15: jln. t nyak arief
A16: 12 | B16: 2022 | C16: November | D16: 7436 | E16: Agustian Saputra | F16: 0853 7989 4486 | G16: rafkacoinlaundry@gmail.com | H16: rafkacoinlaundry/46 laundry express | I16: Kota Banda Aceh | J16: jln. t nyak arief
A17: 13 | B17: 2023 | C17: April | D17: 8480 | E17: Syakila | F17: 081269777817 | H17: Syakila Laundry Expres | I17: Kota Banda Aceh | J17: Jl Kebun Raja Desa Ie Masen Kec. Ule Kareng
A18: 14 | B18: 2023 | C18: Mei | D18: 7436 | E18: Agustian Saputra | F18: 0853 7989 4486 | G18: rafkacoinlaundry@gmail.com | H18: rafkacoinlaundry/delapan Laundry express | I18: Kota Banda Aceh | J18: jln. t nyak arief
A19: 15 | B19: 2023 | C19: Juni | D19: 8714 | E19: er laundry | F19: 0812 6204 3766 | G19: er.laundry2023@gmail.com | H19: er Laundry | I19: Kota Banda Aceh | J19: Jl. Seokarno Hatta, Lam Ara, Banda Raya
A20: 16 | B20: 2023 | C20: November | D20: 10201 | E20: Fakhrul Razi | F20: 085260008048 | G20: bangbungie@gmail.com | H20: Mami Laundry | I20: Kota Banda Aceh | J20: Jl. Taman Siswa Merduati Banda Aceh
A21: 17 | B21: 2023 | C21: Desember | D21: 10755 | E21: ultra Clean londry | F21: 085277488773 | G21: amanahacehdarussalam@gmail.com | H21: Ultra Clean Londry | I21: Kota Banda Aceh | J21: Jalan AMD manunggal cot mesjid
A22: 18 | B22: 2023 | C22: Desember | D22: 7436 | E22: Agustian Saputra | F22: 0853 7989 4486 | G22: rafkacoinlaundry@gmail.com | H22: rafkacoinlaundry/HATEMA LAUNDRY EXPRESS | I22: Kota Banda Aceh | J22: jln. t nyak arief
A23: 19 | B23: 2023 | C23: Desember | D23: 10779 | E23: Farid | F23: 081269779203 | H23: ellaundry/joeragan Laundry | I23: Kota Banda Aceh | J23: panterik
A24: 20 | B24: 2024 | C24: Januari | D24: 10906 | E24: Fadli | F24: 085213596433 | G24: zulfadliyacob2486@gmail.com | H24: papa laundry/Papa Laundry | I24: Kota Lhokseumawe | J24: jln kenari no 3
A25: 21 | B25: 2024 | C25: Januari | D25: 11091 | E25: Halimah | F25: 08116703276 | G25: tqn2024@gmail.com | H25: TQN laundry | I25: Kota Lhokseumawe | J25: jalan mardeka timur
A26: 22 | B26: 2024 | C26: Maret | D26: 10124 | E26: laundry Karpet bireuen | F26: 085380273221 | G26: juangkarpet@gmail.com | H26: laundry Karpet bireuen | I26: Kab. Bireuen | J26: jalan rel kereta api, gelanggang Teungoh, kota juang, bireuen
A27: 23 | B27: 2024 | C27: Maret | D27: 11301 | E27: rumoh cooperation | F27: 082245989203 | H27: Zahra Laundry Express | I27: Kota Sabang | J27: Pertokoan Pujasera No 27, Jl Cut Nyak Dien
A28: 24 | B28: 2024 | C28: Mei | D28: 6085 | E28: Hidayat Muchsin | F28: 082282551800 | G28: laundrymutia230808@gmail.com | H28: Laundry Mutia | I28: Kab. Pidie | J28: Jalan Baru No 6
A29: 25 | B29: 2024 | C29: Juli | D29: 12728 | E29: DINA | F29: 089518928591 | H29: DINA LAUNDRY | I29: Kab. Aceh Tamiang | J29: karang baru .aceh tamiang
A30: 26 | B30: 2024 | C30: Agustus | D30: 6928 | E30: Rais Fahrizal | F30: 082360612025 | G30: laundrycoin124@gmail.com | H30: 124 Laundry/124 laundry new | I30: Kab. Aceh Besar
A31: 27 | B31: 2024 | C31: September | D31: 12793 | E31: aly sazam | F31: 085831739251 | G31: alisazam1998ali@gmail.com | H31: Ilyas Laundry | I31: Kota Subulussalam | J31: jln Teuku Umar kita Subulussalam dpn Polsek Simpang kiri
A32: TOTAL 2026 | E32: {=sum(1/countif(E32,E32))} -> #REF! | H32: {=sum(1/countif(H32,H32))} -> #REF!
A33: TOTAL 2021-2026 | E33: {=sum(1/countif(E5:E31,E5:E31))} -> 23 | H33: {=sum(1/countif(H5:H31,H5:H31))} -> 27 | I33: {=sum(1/countif(I5:I31,I5:I31))} -> 9

Sheet Bali
A1: PT PIPOSMART DIGITAL INDONESIA
A2: Laporan Nasabah Baru
A3: Tahun 2026
A4: Nomor | B4: Tahun Member | C4: Bulan | D4: Kode Owner | E4: Nama Owner | F4: No. Hp Owner | G4: Email | H4: Project/Outlet | I4: Kota | J4: Alamat
A5: 1 | B5: 2021 | C5: Mei | D5: 887 | E5: Gede Bali Laundry | F5: 0878 1114 1000 | G5: laundrygedebali@gmail.com | H5: Gede Bali Laundry | I5: Kab. Gianyar | J5: JL Baka, No 25 Batubulan Gianyar
A6: 2 | B6: 2021 | C6: Mei | D6: 439 | E6: RED Express Laundry | F6: 0818 232 777 | G6: red.xpress3@gmail.com | H6: RED EXPRESS Laundry | I6: Kab. Badung | J6: Jl Poh Gading III no 1
A7: 3 | B7: 2021 | C7: Juli | D7: 1522 | E7: sugiana indah lestari | F7: 0812 3918 8191 | G7: ndahtari7@gmail.com | H7: Indah express laundry | I7: Kota Denpasar | J7: Danau tempe no.35 sanur kecamatan Denpasar Selatan
A8: 4 | B8: 2021 | C8: September | D8: 1454 | E8: Tri | F8: 0813 38035425 | G8: trimandala01@gmail.com | H8: Agung Laundry/Agung Laundry Singaraja | I8: Kab. Buleleng | J8: Jln. Srikandi depan SMAN 2 Sambangan Singaraja - Bali 81119
A9: 5 | B9: 2021 | C9: Oktober | D9: 1541 | E9: Sisilia Agustina | F9: 081353777676 | G9: berkahlaundrydps@gmail.com | H9: Berkah Laundry | I9: Kota Denpasar | J9: Jl. Pulau Moyo no.7b, sesetan, denpasar selatan
A10: 6 | B10: 2021 | C10: Oktober | D10: 2284 | E10: S&C Laundry | F10: 0812 37987097 | G10: laundrysc09@gmail.com | H10: S&C Laundry | I10: Kab. Tabanan | J10: Jalan Gunung Agung 69.II, Pasekan Baleran, Tabanan.
A11: 7 | B11: 2021 | C11: November | D11: 2955 | E11: Dwi | F11: 0878 03152309 | G11: laundrycorner21@gmail.com | H11: 8 Nindy Laundry/Nindy Laundry | I11: Kota Denpasar | J11: Jl. Dukuh Sari
A12: 8 | B12: 2021 | C12: Desember | D12: 3281 | E12: ari wulandari | F12: 0819 852805 | G12: ulandx@yahoo.com | H12: Laundry Tiang | I12: Kota Denpasar | J12: Jalan Kebo Iwa Utara No. 87, Padang Sambian Kaja - Denpasar Barat
A13: 9 | B13: 2021 | C13: Desember | D13: 3401 | E13: barry yudho briantoro | F13: 0813 37379737 | G13: kopisamakami@gmail.com | H13: SAMAKAMI | I13: Kota Denpasar | J13: Jl. Palapa No.88A
A14: 10 | B14: 2021 | C14: Desember | D14: 3687 | E14: DESI | F14: 0819 4412 8567 | G14: desiarya2015@gmail.com | H14: Top Laundry | I14: Kab. Badung | J14: Banjar Denkayu Baleran
A15: 11 | B15: 2022 | C15: Januari | D15: 3813 | E15: M. Fatih Zakiyyurrahman | F15: 822 44000148 | G15: fatihzaky1234@gmail.com | H15: Zaky Laundry/Mama Laundry | I15: Kota Denpasar | J15: jl. sedap malam gg. seruni IVA
A16: 12 | B16: 2022 | C16: Februari | D16: 3813 | E16: M. Fatih Zakiyyurrahman | F16: 0821 44000148 | G16: fatihzaky1234@gmail.com | H16: Zaky Laundry/Zaky Laundry | I16: Kota Denpasar | J16: Jl. Anyelir gg. Rama no. 23
... A40: 36 | B40: 2023 | C40: Oktober | D40: 10487 | E40: Ananda Nugraha | F40: 081957491192 | G40: anandanugraha53@gmail.com | H40: Detergen Laundry | I40: Kab. Badung | J40: Jl. I Gusti Ngurah Rai, Mengwi, Kec Mengwi, Kabupaten Badung, Bali
A41: 37 | B41: 2023 | C41: November | D41: 10692 | E41: RUMAHA LAUNDRY JIMBARAN | F41: 081547167390 | H41: RUMAHA LAUNDRY EXPRESS | I41: Kab. Badung | J41: jln puri gading gg saribu (tepat di depan toko saribu)
A42: 38 | B42: 2023 | C42: Desember | D42: 10569 | E42: Josepha | F42: 082138444374 | H42: Wash Pro 2123 | I42: Kab. Tabanan | J42: Jln. Yeh Gangga 1, Gubug, Tabanan
A43: 39 | B43: 2023 | C43: Desember | D43: 10801 | E43: ida ayu krisna dewi putra | F43: 081237887616 | G43: krisnadewiputra@gmail.com | H43: Beta clean laundry | I43: Kota Denpasar | J43: jln.gn lumut no 46
A44: 40 | B44: 2024 | C44: Januari | D44: 11141 | E44: Nurul Adjam | F44: 085958950007 | G44: nuruladjam6@gmail.com | H44: PICKERING LAUNDRY | I44: Kota Denpasar | J44: jl griya anyar no.92 gg cendrawasih pemogan - Denpasar Selatan
A45: 41 | B45: 2024 | C45: Maret | D45: 11622 | E45: Arya Laundry | F45: 081937290846 | G45: aryalaundry10@gmail.com | H45: Arya Laundry | I45: Kota Denpasar | J45: Jalan Tegal Wangi No 22 sesetan
A46: 42 | B46: 2024 | C46: April | D46: 11696 | E46: glenda | F46: 087865195929 | G46: bubbleslaundry24@gmail.com | H46: Bubble's Laundry | I46: Kab. Badung | J46: Jl. Raya Uluwatu, Pecatu
A47: 43 | B47: 2024 | C47: Juni | D47: 12224 | E47: RUMAHA LAUNDRY PURIGADING | F47: 081547167390 | G47: rumahalaundry21@gmail.com | H47: Laundry | I47: Kab. Badung | J47: Jln puri gading gg saribu (tepat di depan toko saribu)
A48: 44 | B48: 2024 | C48: Juni | D48: 6468 | E48: Kilo Laundry | F48: 081238161111 | G48: kilolaundry23@gmail.com | H48: kilo laundry/Kilo Laundry 2 | I48: Kota Denpasar | J48: Panjer
A49: 45 | B49: 2024 | C49: September | D49: 5138 | E49: Anisa | F49: 081237935953 | G49: anisaputriani.cablek@gmail.com | H49: Sasha Laundry/SASHA LAUNDRY | I49: Kab. Badung | J49: Jln. Darmawangsa, Kampial
A50: 46 | B50: 2024 | C50: Desember | D50: 13791 | E50: glenda | F50: 085945951576 | G50: bobasolaundry02@gmail.com | H50: Bobaso Laundry | I50: Kab. Badung | J50: Teras Hijau Residen blok.3 no.33
A51: 47 | B51: 2025 | C51: Januari | D51: 14431 | E51: Bali Tes | F51: 082340134262 | G51: tesbali869@gmail.com | H51: Check in laundry/Check in laundry | I51: Kab. Gianyar | J51: Jln Batu Intan Utama No 16 Batubulan, Gianyar, Bali
A52: 48 | B52: 2025 | C52: Februari | D52: 14630 | E52: One Love Laundry | F52: 082241305157 | G52: onelovelaundry192@gmail.com | H52: one love laundry/one love laundry | I52: Kota Denpasar | J52: jl. sidakarya no 192
A53: 49 | B53: 2025 | C53: Maret | D53: 14842 | E53: NI PUTU PINGKA PRATIWI | F53: 081916292293 | H53: GINZZ LAUNDROMAT/GINZZ LAUNDROMAT | I53: Kota Denpasar | J53: Jalan. Gunung Karang III 4A 1
A54: 50 | B54: 2025 | C54: Mei | D54: 15398 | E54: owner | F54: 085337764792 | H54: laundryuk/LaundrYuk | I54: Kota Denpasar | J54: Jl Sakura IV Denpasar
A55: 51 | B55: 2025 | C55: Juni | D55: 15593 | E55: Freshclean laundry | F55: 085935363911 | G55: freshcleanlaundry1999@gmail.com | H55: Freshclean/FRESHCLEAN BALI | I55: Kab. Badung | J55: BALI
A56: 52 | B56: 2025 | C56: September | D56: 16269 | E56: Puri Laundry Akasia | F56: 082144461557 | G56: purilaundryakasia@gmail.com | H56: Puri Laundry/Puri Laundry | I56: Kota Denpasar | J56: Jalan Akasia XV no.7
A57: 53 | B57: 2026 | C57: Februari | D57: 10801 | E57: ida ayu krisna dewi putra | F57: 081237887616 | G57: krisnadewiputra@gmail.com | H57: Beta clean laundry/MIRACLE LAUNDRY 2 | I57: Kota Denpasar | J57: jln.gn lumut no 46
A58: 54 | B58: 2026 | C58: April | D58: 17997 | E58: Komang Diatmika | F58: 081937092216 | G58: diatmikakomang690@gmail.com | H58: kedas Laundry/kedas Laundry | I58: Kab. Buleleng | J58: desa Pemaron dusun dauh Margi
A59: 55 | B59: 2026 | C59: Mei | D59: 18591 | E59: VIRLY | F59: 0881037755144 | H59: D.V LAUNDRY/D.V LAUNDRY | I59: Kota Denpasar | J59: JL SEDAP MALAM NO 110 A. DENPASAR TIMUR
A60: 56 | B60: 2026 | C60: Mei | D60: 18742 | E60: Nana Kasterin | F60: 0818356761 | G60: mail.laundrykubali@gmail.com | H60: Laundryku Bali/Laundryku Bali | I60: Kota Denpasar | J60: Jl Mertasari No. 109, Sidakarya - Denpasar
A61: 57 | B61: 2026 | C61: Juni | D61: 18907 | E61: Bubble's 2 | F61: 62881012801023 | H61: Bubble 2/BUBBLE'S LAUNDRY 2 | I61: Kab. Badung | J61: Jalan Raya Uluwatu no 99x
A62: TOTAL 2026 | E62: {=sum(1/countif(E61,E61))} -> 1 | H62: {=sum(1/countif(H61,H61))} -> 1 | I62: {=sum(1/countif(I51:I56,I51:I56))} -> 3
A63: TOTAL 2021-2026 | E63: {=sum(1/countif(E5:E61,E5:E61))} -> 48 | H63: {=sum(1/countif(H5:H61,H5:H61))} -> 57 | I63: {=sum(1/countif(I5:I56,I5:I56))} -> 6

Sheet Bangka Belitung
A1: PT PIPOSMART DIGITAL INDONESIA
A2: Laporan Nasabah Baru
A3: Tahun 2026
A4: Nomor | B4: Tahun Member | C4: Bulan | D4: Kode Owner | E4: Nama Owner | F4: No. Hp Owner | G4: Email | H4: Project/Outlet | I4: Kota | J4: Alamat
A5: 1 | B5: 2021 | C5: Juli | D5: 1342 | E5: Nurdin Araniri | F5: 0818120024 | G5: madanilaundrysyari@gmail.com | H5: Madani laundry/Madani laundry | I5: Kota Pangkal Pinang | J5: Jl. Salak II Keramat Kec Rangkui Pangkalpinang
A6: 2 | B6: 2021 | C6: Agustus | D6: 1342 | E6: Nurdin Araniri | F6: 0818120024 | G6: madanilaundrysyari@gmail.com | H6: Madani laundry/Mitra Madani Laundry Syar'i Gun | I6: Kota Pangkal Pinang | J6: Jln Gandaria 1 RT 07 RW 03 Gerunggang
A7: 3 | B7: 2024 | C7: Maret | D7: 11381 | E7: Widya Novita | F7: 082292404142 | G7: babelcleaning1@gmail.com | H7: Babel Cleaning | I7: Kota Pangkal Pinang | J7: Pangkalpinang
A8: 4 | B8: 2024 | C8: Mei | D8: 12092 | E8: Hasan Sobri | F8: 08127856520 | G8: sobribadarawi.78@gmail.com | H8: Berkah Laundry | I8: Kota Pangkal Pinang | J8: Jl. Bukit Manggis Gg. Berkah
A9: TOTAL 2026 | E9: {=sum(1/countif(E9,E9))} -> #REF! | H9: {=sum(1/countif(H9,H9))} -> #REF! | I9: 0
A10: TOTAL 2021-2026 | E10: {=sum(1/countif(E5:E8,E5:E8))} -> 3 | H10: {=sum(1/countif(H5:H8,H5:H8))} -> 4 | I10: {=sum(1/countif(I5:I8,I5:I8))} -> 1

Sheet Banten
A1: PT PIPOSMART DIGITAL INDONESIA
A2: Laporan Nasabah Baru
A3: Tahun 2026
A4: Nomor | B4: Tahun Member | C4: Bulan | D4: Kode Owner | E4: Nama Owner | F4: No. Hp Owner | G4: Email | H4: Project/Outlet | I4: Kota | J4: Alamat
A5: 1 | B5: 2021 | C5: Mei | D5: 562 | E5: Mimin Sustini | F5: 0818 0608 4931 | G5: miminsustini6@gmail.com | H5: MS Laundry | I5: Kota Tangerang Selatan | J5: Jalan Kenari No 1 Serua Pamulang
A6: 2 | B6: 2021 | C6: Mei | D6: 1027 | E6: Setiyo budhi | F6: 0812 5303 2998 | G6: setiyobudhi@gmail.com | H6: intessar laundry | I6: Kota Tangerang Selatan | J6: jl.mesran Raya M16/B6komplek Pertamina pondok Ranji Ciputat Tangerang Selatan
A7: 3 | B7: 2021 | C7: Mei | D7: 536 | E7: Admin Alea Laundry | F7: 0821 1453 1064 | G7: doelrich001@gmail.com | H7: Alea Laundry | I7: Kota Tangerang | J7: Jl. kihajar Dewantoro RT 03 RW 02 Gondrong Cipondoh Tangerang
A8: 4 | B8: 2021 | C8: Juni | D8: 891 | E8: Nina Marlena | F8: 0811 9413 111 | G8: netto.roseville@gmail.com | H8: Netto Laundromat Roseville | I8: Kota Tangerang Selatan | J8: Ruko SOHO Roseville
A9: 5 | B9: 2021 | C9: Juni | D9: 927 | E9: Nur | F9: 0813 1133 3788 | G9: meughah@yahoo.com | H9: Vertical Laundry | I9: Kota Tangerang Selatan | J9: golden park
A10: 6 | B10: 2021 | C10: Juni | D10: 436 | E10: admin | F10: 0877 8866 1138 | G10: baybaylaundry@gmail.com | H10: baybay laundry/§ BAYBAY LAUNDRY § | I10: Kab. Tangerang | J10: Jl. Raya serang km 13.8 cikupa, kaws. Industri tunas bitung
A11: 7 | B11: 2021 | C11: Juni | D11: 1039 | E11: Ali Usman | F11: 0899 9623 189 | G11: farzanaarsyla02@gmail.com | H11: ISTANA LAUNDRY EXPRESS | I11: Kota Cilegon | J11: link. periuk desa Sukmajaya kecamatan jombang kota cilegon kawasan CCM
A12: 8 | B12: 2021 | C12: Juli | D12: 1647 | E12: BUDI SURIAWAN | F12: 0812 7743 6909 | G12: busurtop1@gmail.com | H12: CUCI MAX Laundry Profesional | I12: Kota Tangerang | J12: Villa Japos Ciledug Tangerang
A13: 9 | B13: 2021 | C13: Juli | D13: 473 | E13: My Laundry | F13: 0857 7607 2793 | G13: maidy.herdian@gmail.com | H13: My Laundry | I13: Kota Tangerang | J13: Cimone jaya Karawaci Tangerang
A14: 10 | B14: 2021 | C14: Juli | D14: 865 | E14: OWNER Laundry MO88 | F14: 0813 8318 8688 | G14: wellson.octo@gmail.com | H14: Laundry MO88 | I14: Kab. Tangerang | J14: Kompleks Villa Taman Bandarablok B1 no 30(Seberang dr. Sulaiman)
A15: 11 | B15: 2021 | C15: Agustus | D15: 1925 | E15: putri ika septyani | F15: 0813 14202094 | G15: zalaundry@gmail.com | H15: za laundry/za laundry | I15: Kota Tangerang | J15: jalan masjid xii batas paninggilan utara ciledug tangerang
A16: 12 | B16: 2021 | C16: Agustus | D16: 1851 | E16: anggi | F16: 0889 73995043 | G16: ariemasykur.amb@gmail.com | H16: Tabina Laundry | I16: Kota Cilegon | J16: Jl.kalitimbang jerang (depan SMP BCK/SMA BCA) Cibeber Cilegon
... A45: 41 | B45: 2022 | C45: Maret | D45: 4805 | E45: Londeri Beringin Raya | F45: 0856 93400073 | G45: londeri.001@gmail.com | H45: londeri | I45: Kota Tangerang | J45: jl beringin Raya no 163
A46: 42 | B46: 2022 | C46: Maret | D46: 4892 | E46: Sri Maryati | F46: 085217473192 | H46: SR laundry | I46: Kota Tangerang | J46: jl. prof Hamka blok F5 no.1, bulak wareng, Kel. larangan selatan
A47: 43 | B47: 2022 | C47: April | D47: 4081 | E47: Tati Sumirah | F47: 0896 36150518 | G47: tatisumirah02@gmail.com | H47: Zahra Laundry/Exferia Laundry Expres | I47: Kota Tangerang | J47: Ketapang Cipondoh Tangerang
A48: 44 | B48: 2022 | C48: April | D48: 3824 | E48: putri ika septyani | F48: 0813 14202094 | G48: zalaundry@gmail.com | H48: za laundry/za laundry 3 | I48: Kota Tangerang | J48: jalan masjid xii batas paninggilan utara ciledug tangerang
A49: 45 | B49: 2022 | C49: April | D49: 5187 | E49: Nita | F49: 0813 11052489 | G49: prionos58@gmail.com | H49: SMESTA Laundry | I49: Kota Tangerang | J49: Griya Kencana 2 Blok i No.2 Sudimara Barat, Ciledug Tangerang
A50: 46 | B50: 2022 | C50: Mei | D50: 5550 | E50: Moni Laundry | F50: 0812 8339 1166 | G50: evonnyjohanes21@gmail.com | H50: MONI LAUNDRY | I50: Kab. Tangerang | J50: Jalan raya cisauk lapan
A51: 47 | B51: 2022 | C51: Mei | D51: 5581 | E51: Laundry Lab | F51: 0819 488 8311 | G51: laundrylabidgs@gmail.com | H51: Laundry Lab | I51: Kab. Tangerang | J51: Ruko Arcadia Grande blok A-31
A52: 48 | B52: 2022 | C52: Mei | D52: 2079 | E52: deni supriatna | F52: 0895 61653 8839 | G52: ds9330861@gmail.com | H52: silver star laundry | I52: Kota Tangerang Selatan | J52: jl bangau rt 05/2 kp sawah poncol (depan sekolah sdi assalam
A53: 49 | B53: 2022 | C53: Juni | D53: 5657 | E53: Adro Servis Indonesia | F53: 0877 5520 2050 | G53: bibicucilaundry.bcl@gmail.com | H53: Bibi Cuci Laundry | I53: Kab. Tangerang | J53: Ruko No.1 Salakanagara
A54: 50 | B54: 2022 | C54: Juni | D54: 6001 | E54: Azkayra Shezan | F54: 0815 1446 2416 | G54: azkayrashezan12@gmail.com | H54: Kayra Laundry | I54: Kota Tangerang | J54: Jl. Rajawali 14, RT.002 RW.004
A55: 51 | B55: 2022 | C55: Juli | D55: 6291 | E55: Satya laundry | F55: 0831 7045 0183 | G55: satyalaundrypci@gmail.com | H55: Satya Laundry/Satya Laundry PCI | I55: Kota Cilegon | J55: Pondok Cilegon Indah blok C60 no.26
A56: 52 | B56: 2022 | C56: Juli | D56: 6226 | E56: Adinda Aulia Puteri | F56: 085809092343 | H56: Dryklin Laundry | I56: Kota Tangerang Selatan | J56: Jalan raya pajajaran no.18, Tangerang Selatan
A57: 53 | B57: 2022 | C57: Juli | D57: 2665 | E57: Dayu | F57: 08111558993 | G57: dr.laundry9335@gmail.com | H57: DR.Laundry/DR.Laundry Cab. Binong Permai | I57: Kab. Tangerang | J57: Perumahan Binong Permai Blok H3 no 001 kel. Binong Kec. Curug Tangerang
A58: 54 | B58: 2022 | C58: Juli | D58: 4524 | E58: Owner Bibi Cuci Laundry | F58: 082111311444 | G58: rm.adieb@gmail.com | H58: Bibi Laundry/Bibi Cuci Laundry - Balaraja | I58: Kab. Tangerang | J58: Balaraja Tangerang
A59: 55 | B59: 2022 | C59: Agustus | D59: 6683 | E59: Her lina | F59: 0813 8344 4223 | G59: linaher764@gmail.com | H59: Lina laundry | I59: Kab. Tangerang | J59: kp.tigarasa/kaduagung
A60: 56 | B60: 2022 | C60: September | D60: 6874 | E60: Gusti Putu Panji Surya | F60: 0813 6863 9194 | G60: panjisurya.26.ps@gmail.com | H60: Tavisya Laundry/TAVISHA LAUNDRY | I60: Kab. Tangerang | J60: jl. Desa Bojong no. 62, Bojong, Kec. Cikupa, Tangerang, Banten 15710
A61: 57 | B61: 2022 | C61: September | D61: 6926 | E61: leny | F61: 0877 7713 9459 | G61: GetlaundryRMJ@gmail.com | H61: Get Laundry RMJ/Get Laundry RMJ | I61: Kota Tangerang Selatan | J61: Jl. Ciater Rt 004 / Rw 022 Kel. Rawabuntu Kec. Serpong
A62: 58 | B62: 2022 | C62: September | D62: 6863 | E62: warino cerano | F62: 081410202984 | G62: bjsslaundry@gmail.com | H62: bjsslaundry/1.Teh Manis Solo.Tmn Ceger | I62: Kota Tangerang Selatan | J62: jl.mushola .no.103 rt.03/rw.04 pondok kacang timur Pondok Aren Tangsel Banten
A63: 59 | B63: 2022 | C63: September | D63: 6926 | E63: Leny | F63: 087777139459 | G63: GetlaundryRMJ@gmail.com | H63: Get Laundry RMJ / Get Laundry Serpong Ekpress | I63: Kota Tangerang Selatan | J63: Jl. Ciater Rt 004 / Rw 022 Kel. Rawabuntu Kec. Serpong
A64: 60 | B64: 2022 | C64: Oktober | D64: 6926 | E64: Leny | F64: 0877 77139459 | G64: GetlaundryRMJ@gmail.com | H64: Get Laundry RMJ/Get Laundry Ciater | I64: Kota Tangerang Selatan | J64: Jl. Ciater Rt 004 / Rw 022 Kel. Rawabuntu Kec. Serpong
A65: 61 | B65: 2022 | C65: Oktober | D65: 7082 | E65: Sumiyati Kusumo | F65: 087808510613 | G65: kusumosumiyati@gmail.com | H65: berkah laundry | I65: Kab. Tangerang | J65: jalan raya serang km 18.5
A66: 62 | B66: 2022 | C66: Oktober | D66: 7160 | E66: Amanahclean Laundry | F66: 085772531302 | G66: laundryamanahclean@gmail.com | H66: Amanah Clean Laundry | I66: Kota Tangerang Selatan | J66: Pasar Segar Graha Raya Blok KA 2 No 10
A67: 63 | B67: 2022 | C67: Oktober | D67: 7321 | E67: Defri Mardona | F67: 081287784546 | G67: defrimardona92@gmail.com | H67: Delta Laundry | I67: Kota Tangerang Selatan | J67: Loftvilles City
A68: 64 | B68: 2022 | C68: Oktober | D68: 4524 | E68: Owner Bibi Cuci Laundry | F68: 082111311444 | G68: rm.adieb@gmail.com | H68: Bibi Laundry/Bibi Cuci Laundry - Tigaraksa | I68: Kab. Tangerang | J68: Balaraja Tangerang
...

Sheet Bengkulu
A1: PT PIPOSMART DIGITAL INDONESIA
A2: Laporan Nasabah Baru
A3: Tahun 2026
A4: Nomor | B4: Tahun Member | C4: Bulan | D4: Kode Owner | E4: Nama Owner | F4: No. Hp Owner | G4: Email | H4: Project/Outlet | I4: Kota | J4: Alamat
A5: 1 | B5: 2021 | C5: September | D5: 2188 | E5: lora seftiantara | F5: 0821 77694046 | G5: evakolambia@gmail.com | H5: Eva Kolambia Laundry | I5: Kab. Rejang Lebong | J5: jalan m.h thamrin
A6: 2 | B6: 2023 | C6: November | D6: 10649 | E6: EDWIN PARULIAN PANGGARBESI | F6: 081936217822 | G6: edwin.parulian@gmail.com | H6: STIM STUM/STIM STUM MANGGA | I6: Kota Bengkulu | J6: stim stum
A7: TOTAL 2026 | E7: {=sum(1/countif(E7,E7))} -> #REF! | H7: {=sum(1/countif(H7,H7))} -> #REF! | I7: 0
A8: TOTAL 2021-2026 | E8: {=sum(1/countif(E5:E6,E5:E6))} -> 2 | H8: {=sum(1/countif(H5:H6,H5:H6))} -> 2 | I8: {=sum(1/countif(I5:I6,I5:I6))} -> 2

Sheet DI Yogyakarta
A1: PT PIPOSMART DIGITAL INDONESIA
A2: Laporan Nasabah Baru
A3: Tahun 2026
A4: Nomor | B4: Tahun Member | C4: Bulan | D4: Kode Owner | E4: Nama Owner | F4: No. Hp Owner | G4: Email | H4: Project/Outlet | I4: Kota | J4: Alamat
A5: 1 | B5: 2021 | C5: April | D5: 287 | E5: Bilqis | F5: 0813 2572 0522 | G5: icislaundry@gmail.com | H5: icis laundry | I5: Kab. Bantul | J5: bekelan no. 12, tirtonirmolo
A6: 2 | B6: 2021 | C6: Mei | D6: 376 | E6: Arya | F6: 0812 7438 7653 | G6: laundrytechno@gmail.com | H6: Techno Laundry/Techno Laundry New Generation | I6: Kab. Sleman | J6: jalan Wulung no 8a Papringan
A7: 3 | B7: 2021 | C7: Mei | D7: 518 | E7: Duga griamugung | F7: 0896 6171 3766 | G7: griaduga@gmail.com | H7: Griya Laundry | I7: Kab. Sleman | J7: Kwarasan no.102 RT 5 RW 5
A8: 4 | B8: 2021 | C8: Agustus | D8: 1780 | E8: icha | F8: 0878 43143035 | G8: ichasholichah03@gmail.com | H8: icha donat | I8: Kab. Sleman | J8: jln kebon agung getas tlogoadi mlati sleman
A9: 5 | B9: 2021 | C9: Oktober | D9: 2825 | E9: yona clean | F9: 0882 007116956 | G9: yonaclean@gmail.com | H9: YONACLEAN | I9: Kab. Bantul | J9: Jati Wonokromo Pleret Bantul
A10: 6 | B10: 2021 | C10: November | D10: 3404 | E10: Yulianingrum | F10: 0857 59167300 | G10: wuri.asian@gmail.com | H10: HIDDENIA | I10: Kab. Bantul | J10: Jeblog Rt2
A11: 7 | B11: 2022 | C11: Januari | D11: 3851 | E11: Ratna | F11: 0811 2630082 | G11: mrcleanjogja@gmail.com | H11: MrCleanLaundry | I11: Kab. Sleman | J11: Jl. Klithikan Kranggan (Selatan Toko Emas Semar Jawa)
A12: 8 | B12: 2022 | C12: Januari | D12: 1485 | E12: Ahmad | F12: 0878 39878808 | G12: magic.laundry.17@gmail.com | H12: Magic Laundry Express/MagicLaundryExpress.com | I12: Kab. Bantul | J12: Jl Imogiri Barat km 5.5 Ngoto
A13: 9 | B13: 2022 | C13: Maret | D13: 3411 | E13: Bayu Kurniawan | F13: 0852 16458603 | G13: anakkoslaundry@gmail.com | H13: Anakkos Laundry | I13: Kota Yogyakarta | J13: Jalan Bimasakti, No.55, Demangan, Gondokusuman, Yogyakarta
A14: 10 | B14: 2022 | C14: Maret | D14: 4979 | E14: sarona gaharu | F14: 0821 17723500 | G14: andreas.abednego@gmail.com | H14: Laundry Ayem Tentrem | I14: Kab. Sleman | J14: Ringinsari RT 01 RW 01
A15: 11 | B15: 2022 | C15: Maret | D15: 4865 | E15: andina | F15: 0821 33346637 | G15: temanlaundryjogja@gmail.com | H15: Teman Laundry & Dry Clean | I15: Kab. Sleman | J15: Jl kaliurang km 14 no 11c
A16: 12 | B16: 2022 | C16: Mei | D16: 5536 | E16: Aji Darma | F16: 085876549841 | G16: laundrybinatuconcat@gmail.com | H16: Laundry Binatu Concat | I16: Kab. Sleman | J16: Jl.Sukun No.98A, Mancasan Lor
... A29: 25 | B29: 2025 | C29: Februari | D29: 6508 | E29: Owner Soekaer | F29: 0895333353583 | G29: soekaer.indonesia@gmail.com | H29: Soekaer/Soekaer Paris | I29: Kota Yogyakarta | J29: Jl. Parangtritis No 163
A30: 26 | B30: 2025 | C30: Februari | D30: 14698 | E30: Soekaer UGM | F30: 089678167250 | H30: Soekaer UGM/Soekaer UGM | I30: Kab. Sleman | J30: Jl Kaliurang Km 5, Karangwuni, Catur Tunggal, Depok, Sleman, Yogyakarta
A31: 27 | B31: 2025 | C31: Mei | D31: 15308 | E31: Najmuddin | F31: 089522333945 | G31: osispendidikanalma@gmail.com | H31: JUNAS UTAMA LAUNDRY EXPRESS UMY/JUNAS UTAMA LAUNDRY EXPRESS UMY | I31: Kab. Bantul | J31: JL SUNAN KUDUS NO 29 GATAK TAMANTIRTO KASIHAN BANTUL
A32: 28 | B32: 2025 | C32: Agustus | D32: 16049 | E32: Maria Vanya | F32: 082391375426 | H32: Techno Laundry/Techno Laundry | I32: Kab. Sleman | J32: Gang Mawar no 8-10, Santren, Caturtunggal
A33: 29 | B33: 2025 | C33: November | D33: 9598 | E33: ethara | F33: 085601172035 | G33: tara3mm@gmail.com | H33: ethara laundry/Amanah Baru Laundry | I33: Kab. Sleman | J33: jln pandega Martha 2
A34: 30 | B34: 2026 | C34: Juni | D34: 18986 | E34: galang daiva | F34: 082136507733 | G34: galangdaivayudhokrisno@gmail.com | H34: techno laundry gg mawar/techno laundry gg mawar | I34: Kab. Sleman | J34: gang mawar no.8-10, santren, caturtunggal
A35: TOTAL 2026 | E35: {=sum(1/countif(E35,E35))} -> #REF! | H35: {=sum(1/countif(H35,H35))} -> #REF! | I35: {=sum(1/countif(I28:I32,I28:I32))} -> 3
A36: TOTAL 2021-2026 | E36: {=sum(1/countif(E5:E34,E5:E34))} -> 24 | H36: {=sum(1/countif(H5:H34,H5:H34))} -> 30 | I36: {=sum(1/countif(I5:I32,I5:I32))} -> 3

Sheet DKI Jakarta
A1: PT PIPOSMART DIGITAL INDONESIA
A2: Laporan Nasabah Baru
A3: Tahun 2026
A4: Nomor | B4: Tahun Member | C4: Bulan | D4: Kode Owner | E4: Nama Owner | F4: No. Hp Owner | G4: Email | H4: Project/Outlet | I4: Kota | J4: Alamat
A5: 1 | B5: 2021 | C5: Mei | D5: 326 | E5: 289 Laundry | F5: 08777770289 | G5: 289laundry@gmail.com | H5: 289laundry/289 DM | I5: Kota Jakarta Barat | J5: Taman dutamas C1A/6
