Workbook

Sheet Daftar Mitra
A1: a
A2: No | B2: CMO | C2: MITRA | D2: Kategori Mitra | E2: Tanggal Kerjasama | F2: Kode Owner | G2: Nama | H2: Nama Brand / Outlet | I2: No Hp | J2: Email | K2: Kecamatan | L2: Kabupaten/Kota | M2: Provinsi | N2: Alamat | O2: Atas Nama | P2: No Rekening | Q2: Nama Bank | R2: Jumlah Referral | S2: PIC | T2: PIC 2
A3: 1 | B3: SHARE CMO | C3: FRANCHISE (Jual Brand Usaha) | D3: FRENCHISE | F3: 6926 | G3: leny | H3: Get Laundry RMJ | I3: 087777139459 | J3: lenidwiyarti321@gmail.com | K3: Kec. Serpong | L3: Kota Tangerang Selatan | M3: Banten | N3: ln. Ciater Rt 004/Rw 022, Kel. Rawa Buntu Kec. Serpong, Kota Tangerang Selatan, Banten | P3: Top Up Saldo | R3: 2 | S3: Lidya | T3: Intan
A4: =A3+1 -> 2 | B4: SHARE CMO | C4: FRANCHISE (Jual Brand Usaha) | D4: FRENCHISE | F4: 11165 | G4: Ayu Widyasari primanda | H4: HAWP LAUNDRY | I4: 082197946038 | J4: ayuwidyasariprimanda000@gmail.com | K4: Kec. Sukmajaya | L4: Kota Depok | M4: Jawa Barat | N4: jln kemang swatama, gg H Tarin no 28, Kel/Kec Sukmajaya Depok | R4: 1 | S4: Lidya | T4: Intan
A5: =A4+1 -> 3 | B5: SHARE CMO | C5: REFERAL (Berlangganan) | D5: REFERRAL | F5: 1522 | G5: Sugiana | H5: Indah Express Laundry | I5: 082147446756 | J5: ndahtari7@gmail.com | K5: Denpasar Selatan | L5: Kota Denpasar | M5: Bali | N5: Danau tempe no.35 sanur kecamatan Denpasar Selatan | R5: 1 | S5: Lidya | T5: Intan
A6: =A5+1 -> 4 | B6: SHARE CMO | C6: REFERAL (Berlangganan) | D6: REFERRAL | F6: 6058 | G6: Citra Halim | H6: Citra Laundry | I6: 08174885266 | J6: citra.halim1@gmail.com | K6: Tanjung Duren Selatan | L6: Kota Jakarta Barat | M6: Dki Jakarta | N6: Jl. Tanjung Duren Timur Raya Gang Mandalika, Kota Jakarta Barat, Dki Jakarta | R6: 2 | S6: Lidya | T6: Intan
A7: =A6+1 -> 5 | B7: SHARE CMO | C7: REFERAL (Berlangganan) | D7: REFERRAL | F7: 7479 | G7: farhan alfatan | H7: Citra Laundry | I7: 082125008245 | J7: rabbittank02@gmail.com | K7: Kec. Banyusari | L7: Kab. Karawang | M7: Jawa Barat | N7: kp.krajan1 ds.jayamukti kec.banyusari kab.karawang | R7: 1 | S7: Lidya | T7: Intan
A8: =A7+1 -> 6 | B8: SHARE CMO | C8: REFERAL (Berlangganan) | D8: REFERRAL | F8: 4723 | G8: Budi Santo | H8: sahabat laundry | I8: 082174637062 | J8: sahabatlaundrybaru@gmail.com | K8: Cikampek | L8: Kab. Karawang | M8: Jawa Barat | N8: jln pertokoan stasiun cikampek nmr 2, Kab. Karawang, Jawa Barat | R8: 6 | S8: Lidya | T8: Intan
A9: =A8+1 -> 7 | B9: SHARE CMO | C9: REFERAL (Berlangganan) | D9: REFERRAL | F9: 4181 | G9: DIGNITY SINAGA | H9: DIGNITY LAUNDRY | I9: 0811620080 | J9: sachio3008@gmail.com | K9: Tangerang | L9: Kota Tangerang | M9: Banten | N9: Tanggerang, Cikokol, Tangerang, Banten | R9: 6 | S9: Lidya | T9: Intan
A10: =A9+1 -> 8 | B10: SHARE CMO | C10: REFERAL (Berlangganan) | D10: REFERRAL | F10: 7801 | G10: Rahmawaty Madjid | H10: Aroma Palopo / NETTO LAUNDRY | I10: 08114220487 | J10: aromapaloponmie@gmail.com | K10: Kadia | L10: Kota Kendari | M10: Sulawesi Tenggara | N10: Food Court The Park,Kadia,Kota Kendari,Sulawesi Tenggara | R10: 2 | S10: Lidya | T10: Intan
A11: =A10+1 -> 9 | B11: SHARE CMO | C11: REFERAL (Berlangganan) | D11: REFERRAL | F11: 11515 | G11: APRILIA | H11: SHARENA LAUNDRY | I11: 085210108123 | J11: apinkcalen@gmail.com | K11: Kec. Cakung | L11: Kota Jakarta Timur | M11: Dki Jakarta | N11: JL H.R ISMAIL RT 08 RW 03 JATINEGARA CAKUNG JAKARTA TIMUR | P11: 0940964237 | Q11: BCA | R11: 1 | S11: Lidya | T11: Intan
A12: =A11+1 -> 10 | B12: SHARE CMO | C12: REFERAL (Berlangganan) | D12: REFERRAL | F12: 9441 | G12: Kasih Laundry Siantar | H12: Kasih Laundry | I12: 0859106762310 | J12: kasihlaundrysiantar@gmail.com | K12: Bukit Shofa | L12: Kota Pematang Siantar | M12: Sumatera Utara | N12: Jl.Sisingamangaraja, No.15, Bukit Sofa, Siantar Sitalasari, Pematang Siantar | R12: 1 | S12: Lidya | T12: Intan
A13: =A12+1 -> 11 | B13: SHARE CMO | C13: REFERAL (Berlangganan) | D13: REFERRAL | F13: 14464 | G13: Kilo Laundry | H13: Kilo Laundry Singosari | I13: 087866932707 | J13: deanathaniaardita96@gmail.com | K13: Kec. Singosari | L13: Kab. Malang | M13: Jawa Timur | N13: Jl raya mondoroko, Mondoroko, Singosari, Kec. Singosari, Kabupaten Malang, Jawa Timur | P13: 0881632747 | Q13: BCA | R13: 1 | S13: Lidya | T13: Intan
A14: =A13+1 -> 12 | B14: SHARE CMO | C14: REFERAL (Berlangganan) | D14: REFERRAL | F14: 13944 | G14: Orlando Manalu | H14: LAUNDRY KITA | I14: 085163695628 | J14: orlandomanalu0@gmail.com | K14: Kec. Siantar | L14: Kab. Simalungun | M14: Sumatera Utara | N14: Jl. Asahan,KM 3,5. Pematang Simalungun, Kec. Siantar, Kabupaten Simalungun, Sumatera Utara 21151(Komplek Graha Asahan Gold) | R14: 1 | S14: Lidya | T14: Intan
A15: =A14+1 -> 13 | B15: SHARE CMO | C15: REFERAL (Berlangganan) | D15: REFERRAL | F15: 10563 | G15: Abi Hafidz | H15: AZZAHRO LAUNDRY ٣٨ CIKANDE | I15: 085217955565 | J15: noer.underbon9048@gmail.com | K15: Kec. Cikande | L15: Kab. Serang | M15: Banten | N15: kp.Gegong burung Rt 02/02 Desa situterate Kec. Cikande Kabupaten SERANG BANTEN kode pos 42186 | R15: 1 | S15: Lidya | T15: Intan
A16: =A15+1 -> 14 | B16: SHARE CMO | C16: REFERAL (Berlangganan) | D16: REFERRAL | F16: - | G16: Selly Andini | H16: Sultan Laundry. co | I16: 082297051345 | J16: Sellyandini15@yahoo.com | L16: Tanggerang | M16: Dki Jakarta | N16: Jln. Duta Raya, Perumahan Taman Cibodas, Blok H1 No.2, Tanggerang | P16: 6250379160 | Q16: BCA | R16: 1 | S16: Lidya | T16: Intan
A17: =A16+1 -> 15 | B17: SHARE CMO | C17: REFERAL (Berlangganan) | D17: REFERRAL | E17: Mei | F17: 10409 | G17: Ahmad Kamal Dahlan | H17: Zona Laundry Mamuju | I17: 085213159125 | J17: kamaldoremi@gmail.com | K17: Kec. Simboro | L17: Kab. Mamuju | M17: Sulawesi Barat | N17: Jl. Martadinata Mamuju, Kab. Mamuju | P17: 305401020779530 | Q17: BRI | R17: 1 | S17: Lidya | T17: Intan
A18: =A17+1 -> 16 | B18: SHARE CMO | C18: REFERAL (Berlangganan) | D18: REFERRAL | E18: Mei | F18: 4323 | G18: Atik Nurbayati | H18: Delisha Laundry | I18: 081259819220 | J18: atiknurbayati@gmail.com | K18: Kec.Sedati Gede | L18: Kab. Sidoarjo | M18: Jawa Timur | N18: Jl.By Pass Bandara Juanda 35 Sedati Sidoarjo | P18: 6670332641 | Q18: BCA | R18: 3 | S18: Lidya | T18: Intan
A19: =A18+1 -> 17 | B19: SHARE CMO | C19: REFERAL (Berlangganan) | D19: REFERRAL | E19: September | F19: 8177 | G19: Tengku ariani | H19: Mame Laundry | I19: 081275566111 | J19: tengkuariani20@gmail.com | K19: tengkuariani20@gmail.com | L19: Kab. Deli Serdang | M19: Sumatera Utara | N19: jalan tani asli gang Samin sebelah kolam renang Wira kel.purwodadi kec.sunggal kab.deli Serdang Sumatera Utara | P19: Top up Saldo Aplikasi | R19: 1 | S19: Lidya | T19: Intan
A20: =A19+1 -> 18 | B20: SHARE CMO | C20: AFILIASI (Perlengkapan Ex. Mesin | D20: PERLENGKAPAN | F20: 6125 | G20: Harapan | H20: Expert laundry (Raja Setrika) | I20: 081264984318 | J20: daarun18@gmail.com | K20: Medan Kota | L20: Kota Medan | M20: Sumatera Utara | N20: Jl Pelajar Timur No.157B, kel.Teladan Timur, Kec.Medan kota, kota Medan, Sumatera Utara | P20: Top up Saldo Aplikasi | R20: 9 | S20: Lidya | T20: Intan
A21: =A20+1 -> 19 | B21: SHARE CMO | C21: AFILIASI (Perlengkapan Ex. Mesin | D21: PERLENGKAPAN | F21: - | G21: Nurul | H21: PT. Alfatih Tech Utama | I21: 089662321780 | K21: Jagakarsa | L21: Jakarta Selatan | M21: Dki Jakarta | N21: Jl. Komp. Desa Putera No.1, RT.7/RW.5, Srengseng Sawah, Kec. Jagakarsa, Kota Jakarta Selatan, DKI Jakarta | P21: 4212659928 | Q21: BCA | R21: 3 | S21: Lidya | T21: Intan
A22: =A21+1 -> 20 | B22: SHARE CMO | C22: AFILIASI (Perlengkapan Ex. Mesin | D22: PERLENGKAPAN | F22: - | G22: Nurul | H22: MIKAIL ELECTRONIK | I22: 081211542249 | K22: Grogol Selatan | L22: Jakarta Selatan | M22: Dki Jakarta | N22: Jl. Persatuan Amal Mulia No. 25b, RT.5/RW.13, Grogol Sel., Jakarta, Kota Jakarta Selatan | P22: 708501008072539 | Q22: BRI | R22: 6 | S22: Lidya | T22: Intan
A23: =A22+1 -> 21 | B23: SHARE CMO | C23: AFILIASI (Perlengkapan Ex. Mesin | D23: PERLENGKAPAN | F23: - | G23: KG TEKNIK BATAM | H23: KG TEKNIK BATAM | I23: 081364050429 | J23: amiraizati01@gmail.com | K23: Batam Kota | L23: Kota Batam | M23: Kepulauan Riau | N23: Ruko Puri Legenda Blok C2 No 02-03 Batam Centre | P23: 1090019010180 | Q23: MANDIRI | R23: 3 | S23: Lidya | T23: Intan
A24: =A23+1 -> 22 | B24: SHARE CMO | C24: AFILIASI (Perlengkapan Ex. Mesin | D24: PERLENGKAPAN | F24: - | G24: Taufik | H24: CV Kinsa Niaga Sukses | I24: 081213970585 | J24: chisa.qb@gmail.com | K24: Kec. Cibarusah | L24: Kab. Bekasi | M24: Jawa Barat | N24: Perumahan Cibarusah Indah Blok e23 No.4 Cibarusah Kota Kab. Bekasi Patokan sebelum masuk perumahan ada gapura dekat dengan mesjid perahu, Kec. Cibarusah, Jawa Barat 17340 | O24: CV KINSA NIAGA SUKSES | P24: 6880445471/6881294653 | Q24: BCA | R24: 80 | S24: Lidya | T24: Intan
G25: =COUNTA(G3:G24) -> 22 | R25: =SUM(R3:R24) -> 133 | S25: =COUNTA(S3:S24) -> 22
A26: =A24+1 -> 23 | B26: SHARE CMO | C26: AFILIASI (Perlengkapan Ex. Mesin | D26: PERLENGKAPAN | F26: 1782 | G26: Ismail Akbar | H26: Akbar Laundry | I26: 085251394079 | J26: ismail2015648@gmail.com | K26: Sungai Bangkong | L26: Kota Pontianak | M26: Kalimantan Barat | N26: jln dr Sutomo GG karya 1 no 78 Akbar Laundry dan Service Pontianak Kalimantan barat Jl. Dr. Sutomo, Gg. Karya 1 No. 78Kota Pontianak, Kalimantan Barat | P26: 304701028491533 | Q26: BRI | R26: 8 | S26: Heriwati, Givoni | T26: Givoni
A27: =A26+1 -> 24 | B27: SHARE CMO | C27: AFILIASI (Perlengkapan Ex. Mesin | D27: PERLENGKAPAN | E27: 44927 | F27: 6343 | G27: Ade Syahputra | H27: Key Loundry/AAdelia store | I27: 085270356833 | J27: papakey1708@gmail.com | K27: Sei Semayang | L27: Kab. Deli Serdang | M27: Sumatera Utara | N27: jln mesjid dusun 1 aman damai,Sei Semayang,Kab. Deli Serdang,Sumatera Utara | R27: 12 | S27: Heriwati, Givoni | T27: Givoni
A28: =A27+1 -> 25 | B28: SHARE CMO | C28: AFILIASI (Perlengkapan Ex. Mesin | D28: PERLENGKAPAN | F28: 989 | G28: Pak NANANG | H28: Junior Laundry | I28: 087786116755 | J28: nanangjunior232@gmail.com | K28: Grogol | L28: Kab. Sukoharjo | M28: Jawa Tengah | N28: Jl. Parangkesit, RT 02 / RW 17, Ngruki, Cemani, Grogol, Sukoharjo, Jawa Tengah | R28: 6 | S28: Heriwati, Givoni | T28: Givoni
A29: =A28+1 -> 26 | B29: SHARE CMO | C29: AFILIASI (Perlengkapan Ex. Mesin | D29: PERLENGKAPAN | F29: - | G29: Pak Medi | H29: BMG Laundry | R29: 2 | S29: Heriwati, Givoni | T29: Givoni
A30: =A29+1 -> 27 | B30: SHARE CMO | C30: AFILIASI (Perlengkapan Ex. Mesin | D30: PERLENGKAPAN | F30: 6509 | G30: Mulya Sari | H30: mulya jaya abadi | I30: 0813833788860 | J30: mulyasari992@gmail.com | K30: Cempaka Putih | L30: Kota Jakarta Pusat | M30: Dki Jakarta | N30: jl.cempaka putih tengah 1 no 10 a | R30: 6 | S30: Heriwati, Givoni | T30: Givoni
A31: =A30+1 -> 28 | B31: SHARE CMO | C31: AFILIASI (Perlengkapan Ex. Mesin | D31: PERLENGKAPAN | F31: 8645 | G31: Yendri Yusman | H31: Dhiva Laundry | I31: 081238802987 | J31: makmur0902@gmail.com | K31: Medan Maimun | L31: Kota Medan | M31: Sumatera Utara | N31: Jl. Brigjen katamso, Kel.Kampung Baru, Kec.Medan Maimun, Kota Medan, Sumatera Utara | P31: 8430520009 | Q31: BCA | R31: 4 | S31: Heriwati, Givoni | T31: Givoni
A32: =A31+1 -> 29 | B32: SHARE CMO | C32: AFILIASI (Perlengkapan Ex. Mesin | D32: PERLENGKAPAN | F32: 14152 | G32: Mohacmad Hadi | H32: PUTRA TEKNIK SEMARANG | I32: 087718146514 | J32: alifjunior210@gmail.com | L32: Semarang | M32: Jawa Tengah | N32: jl. Bukit Palem Kipas Blok 7, Semarang, Jawa Tengah | P32: 303701020614532 | Q32: BRI | R32: 2 | S32: Heriwati, Givoni | T32: Givoni
A33: =A32+1 -> 30 | B33: SHARE CMO | C33: AFILIASI (Perlengkapan Ex. Mesin | D33: PERLENGKAPAN | F33: - | G33: Adip | H33: ADIP LAUNDRY SEMARANG | I33: 081575502277 | R33: 1 | S33: Heriwati, Givoni | T33: Givoni
A34: =A33+1 -> 31 | B34: SHARE CMO | C34: FRANCHISE (Jual Brand Usaha) | D34: FRENCHISE | E34: 45047 | F34: - | G34: Beta Nurry Damayanti | H34: Deter_gent Laundry | I34: 081252347769 | J34: @detergentlaundry_official | K34: Lowokwaru | L34: Kota Malang | M34: Jawa Timur | N34: Jln Simp.Pandan Arum No 2 RT 01 RW 02, Desa/Kel. Jatimulyo, | P34: 223701000459309 | Q34: BRI | R34: 6 | S34: Heriwati, Givoni | T34: Givoni
A35: =A34+1 -> 32 | B35: SHARE CMO | C35: FRANCHISE (Jual Brand Usaha) | D35: FRENCHISE | F35: 10717 | G35: joko Widodo daulay | H35: Adira laundry expres | I35: 082181303164 | J35: askaraputradaulay@gmail.com | K35: Kisaran Timur | L35: Kab. Asahan | M35: Sumatera Utara | N35: Jalan kakak Tua, kisaran. Kab. Asahan,Sumatera Utara | P35: 269276177 | Q35: BNI | R35: 2 | S35: Heriwati, Givoni | T35: Givoni
A36: =A35+1 -> 33 | B36: SHARE CMO | C36: REFERAL (Berlangganan) | D36: REFERRAL | F36: 5836 | G36: Adi Prayitno | H36: Inches Laundry Express | I36: 082110007816 | J36: adiprayitno754@gmail.com | K36: Sungai Jawi | L36: Kota Pontianak | M36: Kalimantan Barat | N36: Jl. Tabrani Ahmad, Pontianak, kalimantan Barat | R36: 1 | S36: Heriwati, Givoni | T36: Givoni
A37: =A36+1 -> 34 | B37: SHARE CMO | C37: REFERAL (Berlangganan) | D37: REFERRAL | F37: 4896 | G37: Elisabeth | H37: Baladewa Laundry | I37: 089639843456 | J37: dhinidhini893@gmail.com | K37: Puseurjaya | L37: Kab. Karawang | M37: Jawa Barat | N37: Jl. Menati 1 No.27 Puserjaya Kec. Telukjambe Timur Kab. Karawang | R37: 1 | S37: Heriwati, Givoni | T37: Givoni
A38: =A37+1 -> 35 | B38: SHARE CMO | C38: REFERAL (Berlangganan) | D38: REFERRAL | F38: 7233 | G38: Riendi Pratama | H38: Adrienu laundry | I38: 081295989384 | J38: riendi.pratama@gmail.com | K38: Padangsambian Klod | L38: Kota Denpasar | M38: Bali | N38: Padangsambian,Kota Denpasar Kota Bali, Bali | R38: 1 | S38: Heriwati, Givoni | T38: Givoni
A39: =A38+1 -> 36 | B39: SHARE CMO | C39: REFERAL (Berlangganan) | D39: REFERRAL | F39: 2700 | G39: My Laundry | H39: Rezky Perdana | I39: 08116360330 | J39: superlte4g@gmail.com | K39: Tanjung Gusta | L39: Kab. Deli Serdang | M39: Sumatera Utara | N39: JL LEMBAGA PEMASYARAKATAN NO 225 | R39: 4 | S39: Heriwati, Givoni | T39: Givoni
A40: =A39+1 -> 37 | B40: SHARE CMO | C40: REFERAL (Berlangganan) | D40: REFERRAL | G40: Rico Yuli Prasetyo | H40: Raja Laundry | I40: O89501299837 | J40: rico.pras09785@gmail.com | L40: Surabaya | M40: Jawa Timur | N40: Bendul merisi GG 1 selatan no.59 surabaya | P40: 4290938843 | Q40: BCA | R40: 3 | S40: Heriwati, Givoni | T40: Givoni
...

Sheet Mitra - Referral
B1: List Mitra | F1: Nasabah Yang Di Referralkan | U1: Berlangganan 2022 | AA1: Bonus Berlangganan 2023 | AI1: Bonus Berlangganan 2024 | AU1: 2025 | BG1: 2026 | BN1: Akumulasi
A2: No | B2: MITRA | C2: Kode Owner | D2: Nama | E2: Nama Brand / Outlet | F2: Kode Owner | G2: Nama Owner | H2: Nama Brand /Outlet | I2: Bukti Fu | J2: Kategory Mitra | K2: Paket Langganan | L2: PIC | M2: Link Bukti Follow Up | N2: Date Top Up | O2: Date of Renewal | P2: Status | Q2: Tanggal Pencairan 1 | R2: Tanggal Pencairan 2 | S2: Status Pencairan Komisi Mitra | T2: CMO | U2: 11 | V2: 12 | W2: 1 | X2: 2 | Y2: 3 | Z2: 4 | AA2: 5 | AB2: 6 | AC2: 7 | AD2: 8 | AE2: 9 | AF2: 10 | AG2: 11 | AH2: 12 | AI2: 1 | AJ2: 2 | AK2: 3 | AL2: 4 | AM2: 5 | AN2: 6 | AO2: 7 | AP2: 8 | AQ2: 9 | AR2: 10 | AS2: 11 | AT2: 12 | AU2: 1 | AV2: 2 | AW2: 3 | AX2: 4 | AY2: 5 | AZ2: 6 | BA2: 7 | BB2: 8 | BC2: 9 | BD2: 10 | BE2: 11 | BF2: 12 | BG2: 1 | BH2: 2 | BI2: 3 | BJ2: 4 | BK2: 5 | BL2: 6 | BM2: 7 | BN2: UNPAY | BO2: Tahap 1 | BP2: Tahap 2 | BQ2: PAY | BR2: TOTAL
A3: 1 | B3: FRANCHISE (Jual Brand Usaha) | C3: 6926 | D3: leny | E3: Get Laundry RMJ | F3: 8068 | G3: Get Laundry Villa Pamulang | H3: Get Laundry | J3: Referral | K3: Bisnis 12 Bulan | L3: Lidya | N3: 44956 | O3: 44956 | P3: Sudah 1 Tahun | S3: Selesai Dicairkan | W3: 150000 | X3: FINISH | BN3: =BR3-BQ3 -> 0 | BO3: 150000 | BP3: 0 | BQ3: =sum(U3:BH3) -> 150000 | BR3: =SUM(U3:BJ3) -> 150000
A4: =A3+1 -> 2 | B4: FRANCHISE (Jual Brand Usaha) | C4: 6926 | D4: leny | E4: Get Laundry RMJ | F4: 15516 | G4: obby/ mama laundry | H4: laundry/mama laundry | J4: Referral | K4: Bisnis 12 Bulan | L4: Lidya | M4: https://drive.google.com/file/d/1Vb5EJJZ2sZI5jQHpWT0um2fSt4v_4OSt/view?usp=sharing | N4: 45809 | O4: 45812 | P4: Sudah 1 Tahun | Q4: 45852 | S4: Selesai Dicairkan | BA4: 150000 | BB4: FINISH | BN4: =BR4-BQ4 -> 0 | BO4: 150000 | BP4: 0 | BQ4: =sum(U4:BH4) -> 150000 | BR4: =SUM(U4:BJ4) -> 150000
A5: =A4+1 -> 3 | B5: FRANCHISE (Jual Brand Usaha) | C5: 11165 | D5: Ayu Widyasari primanda | E5: HAWP LAUNDRY | F5: 13966 | G5: Laundryin Sini | H5: Laundry In Sini | J5: Corporate Paket Bisnis | K5: Bisnis 12 Bulan | L5: Lidya | N5: 45625 | O5: 45639 | P5: Sudah 1 Tahun | S5: Belum Dicairkan | T5: Share CMO | AS5: 181720 | AT5: FINISH | BN5: =BR5-BQ5 -> 181720 | BO5: 0 | BP5: 0 | BQ5: 0 | BR5: =SUM(U5:BJ5) -> 181720
A6: =A5+1 -> 4 | B6: REFERAL (Berlangganan) | C6: 1522 | D6: Sugiana | E6: Indah Express Laundry | F6: 8162 | G6: Viva Yuniarti | H6: Dilvio Laundry | J6: Referral | K6: Bisnis 12 Bulan | L6: Lidya | N6: 44953 | O6: 44953 | P6: Sudah 1 Tahun | S6: Selesai Dicairkan | W6: 150000 | X6: FINISH | BN6: =BR6-BQ6 -> 0 | BO6: 0 | BP6: 0 | BQ6: =sum(U6:BH6) -> 150000 | BR6: =SUM(U6:BJ6) -> 150000
A7: =A6+1 -> 5 | B7: REFERAL (Berlangganan) | C7: 6058 | D7: Citra Halim | E7: Citra Laundry | F7: 7885 | G7: Frenki Hardjono | H7: rejeki laundry | J7: Referral | K7: Bisnis 6 Bulan | L7: Lidya | N7: 44931 | O7: 44931 | P7: Sudah 1 Tahun | S7: Selesai Dicairkan | W7: 75000 | X7: - | Y7: - | Z7: - | AA7: - | AB7: - | AC7: US | AD7: US | AE7: US | AF7: US | AG7: US | AH7: US | AI7: FINISH | BN7: =BR7-BQ7 -> 0 | BO7: 0 | BP7: 0 | BQ7: =sum(U7:BH7) -> 75000 | BR7: =SUM(U7:BJ7) -> 75000
A8: =A7+1 -> 6 | B8: REFERAL (Berlangganan) | C8: 7479 | D8: farhan alfatan | E8: Citra Laundry | F8: 8761 | G8: Windi | H8: altha laundry | J8: Referral | K8: Basic 1 Bulan | L8: Lidya | N8: 45040 | O8: 45040 | P8: Sudah 1 Tahun | S8: Belum Dicairkan | T8: Share CMO | Z8: 8333 | AA8: 8333 | AB8: 8333 | AC8: 8333 | AD8: 8333 | AE8: 8333 | AF8: 8333 | AG8: 8333 | AH8: 8333 | AI8: 8333 | AJ8: 8333 | AK8: 8333 | AL8: FINISH | BN8: =BR8-BQ8 -> 99996 | BO8: 0 | BP8: 0 | BQ8: 0 | BR8: =SUM(U8:BJ8) -> 99996
A9: =A8+1 -> 7 | B9: REFERAL (Berlangganan) | C9: 4723 | D9: Budi Santo | E9: sahabat laundry | F9: 9322 | G9: Laundry Geulis | H9: geulis laundry | J9: Referral | K9: Basic 12 Bulan | L9: Lidya | N9: 45090 | O9: 45090 | P9: Sudah 1 Tahun | S9: Selesai Dicairkan | AB9: 100000 | AC9: FINISH | BN9: =BR9-BQ9 -> 0 | BO9: 0 | BP9: 0 | BQ9: =sum(U9:BH9) -> 100000 | BR9: =SUM(U9:BJ9) -> 100000
A10: =A9+1 -> 8 | B10: REFERAL (Berlangganan) | C10: 4723 | D10: Budi Santo | E10: sahabat laundry | F10: 7479 | G10: farhan alfatan | H10: juragan laundry | J10: Referral | K10: Bisnis 1 Bulan | L10: Lidya | N10: 44885 | O10: 44885 | P10: Sudah 1 Tahun | S10: Dicairkan Sebagian | T10: Share CMO | U10: 12500 | V10: 12500 | W10: 12500 | X10: 12500 | Y10: 12500 | Z10: 12500 | AA10: 12500 | AB10: 12500 | AC10: 12500 | AD10: 12500 | AE10: 12500 | AF10: 12500 | AG10: FINISH | BN10: =BR10-BQ10 -> 62500 | BO10: 87500 | BP10: 0 | BQ10: =sum(U10:AA10) -> 87500 | BR10: =SUM(U10:BJ10) -> 150000
A11: =A10+1 -> 9 | B11: REFERAL (Berlangganan) | C11: 4723 | D11: Budi Santo | E11: sahabat laundry | F11: 8763 | G11: Yadi Mulyawarman | H11: Ceuk Mamah/Ceuk Mamah Doel | J11: Referral | K11: Basic 1 Bulan | L11: Lidya | N11: 45041 | O11: 45041 | P11: Sudah 1 Tahun | S11: Dicairkan Sebagian | T11: Share CMO | Z11: 8333 | AA11: 8333 | AB11: 8333 | AC11: 8333 | AD11: 8333 | AE11: 8333 | AF11: 8333 | AG11: 8333 | AH11: 8333 | AI11: 8333 | AJ11: 8333 | AK11: 8333 | AL11: FINISH | BN11: =BR11-BQ11 -> 83330 | BO11: 16666 | BP11: 0 | BQ11: =sum(Z11:AA11) -> 16666 | BR11: =SUM(U11:BJ11) -> 99996
A12: =A11+1 -> 10 | B12: REFERAL (Berlangganan) | C12: 4723 | D12: Budi Santo | E12: sahabat laundry | F12: 9805 | G12: Asep Sugianto | H12: Akang Laundry | J12: Referral | K12: Basic 1 Bulan | L12: Lidya | N12: 45154 | O12: 45154 | P12: Sudah 1 Tahun | Q12: 45477 | S12: Dicairkan Sebagian | T12: Share CMO | AD12: 8333 | AE12: 8333 | AF12: 8333 | AG12: 8333 | AH12: 8333 | AI12: 8333 | AJ12: 8333 | AK12: 8333 | AL12: 8333 | AM12: 8333 | AN12: 8333 | AO12: 8333 | AP12: FINISH | BN12: =BR12-BQ12 -> 8333 | BO12: =SUM(AD12:AN12) -> 91663 | BP12: 0 | BQ12: =sum(AD12:AN12) -> 91663 | BR12: =SUM(U12:BJ12) -> 99996
A13: =A12+1 -> 11 | B13: REFERAL (Berlangganan) | C13: 4723 | D13: Budi Santo | E13: sahabat laundry | F13: 10049 | G13: Tini Hendriyani | H13: juragan laundry pabuaran | J13: Referral | K13: Basic 12 Bulan | L13: Lidya | N13: 45211 | O13: 45212 | P13: Sudah 1 Tahun | S13: Belum Dicairkan | T13: Share CMO | AF13: 8333 | AG13: 8333 | AH13: 8333 | AI13: 8333 | AJ13: =100000-AF13-AG13-AH13-AI13 -> 66668 | AK13: FINISH | BN13: =BR13-BQ13 -> 100000 | BO13: 0 | BP13: 0 | BQ13: 0 | BR13: =SUM(U13:BJ13) -> 100000
A14: =A13+1 -> 12 | B14: REFERAL (Berlangganan) | C14: 4723 | D14: Budi Santo | E14: sahabat laundry | F14: 12245 | G14: Neng gemoy | H14: Eneng gemoy | J14: Referral | K14: Basic 1 Bulan | L14: Lidya | N14: 45449 | O14: 45451 | P14: Sudah 1 Tahun | Q14: 45477 | S14: Dicairkan Sebagian | T14: Share CMO | AN14: 8333 | AO14: 8333 | AP14: 8333 | AQ14: 8333 | AR14: 8333 | AS14: 8333 | AT14: 8333 | AU14: 8333 | AV14: 8333 | AW14: 8333 | AX14: 8333 | AY14: 8333 | AZ14: FINISH | BN14: =BR14-BQ14 -> 91663 | BO14: =SUM(AN14) -> 8333 | BP14: 0 | BQ14: =AN14 -> 8333 | BR14: =SUM(U14:BJ14) -> 99996
A15: =A14+1 -> 13 | B15: REFERAL (Berlangganan) | C15: 7251 | D15: Yogi Lumban Tobing | E15: BAR LAUNDRY | F15: 9441 | G15: Kasih Laundry Siantar | H15: Kasih Laundry | J15: Referral | K15: Basic 12 Bulan | L15: Lidya | N15: 45106 | O15: 45106 | P15: Sudah 1 Tahun | S15: Selesai Dicairkan | AB15: 100000 | AC15: FINISH | BN15: =BR15-BQ15 -> 0 | BO15: 0 | BP15: 0 | BQ15: =sum(U15:BH15) -> 100000 | BR15: =SUM(U15:BJ15) -> 100000
A16: =A15+1 -> 14 | B16: REFERAL (Berlangganan) | C16: 4181 | D16: DIGNITY SINAGA | E16: DIGNITY LAUNDRY | F16: 9665 | G16: Rama Purba | H16: RAMA LAUNDRY | J16: Referral | K16: Basic 12 Bulan | L16: Lidya | N16: 45131 | O16: 45146 | P16: Sudah 1 Tahun | S16: Selesai Dicairkan | AC16: 100000 | AD16: FINISH | BN16: =BR16-BQ16 -> 0 | BO16: 0 | BP16: 0 | BQ16: =sum(U16:BH16) -> 100000 | BR16: =SUM(U16:BJ16) -> 100000
A17: =A16+1 -> 15 | B17: REFERAL (Berlangganan) | C17: 4181 | D17: DIGNITY SINAGA | E17: DIGNITY LAUNDRY | F17: 10250 | G17: Mieke Simamora | H17: Gwen Laundry | J17: Referral | K17: Basic 12 Bulan | L17: Lidya | N17: 45212 | O17: 45212 | P17: Sudah 1 Tahun | S17: Selesai Dicairkan | AF17: 100000 | AG17: FINISH | BN17: =BR17-BQ17 -> 0 | BO17: 0 | BP17: 0 | BQ17: =sum(U17:BH17) -> 100000 | BR17: =SUM(U17:BJ17) -> 100000
A18: =A17+1 -> 16 | B18: REFERAL (Berlangganan) | C18: 4181 | D18: DIGNITY SINAGA | E18: DIGNITY LAUNDRY | F18: 10237 | G18: Dolok Manullang | H18: Dr Laundry | J18: Referral | K18: Basic 12 Bulan | L18: Lidya | N18: 45212 | O18: 45212 | P18: Sudah 1 Tahun | S18: Selesai Dicairkan | AF18: 100000 | AG18: FINISH | BN18: =BR18-BQ18 -> 0 | BO18: 0 | BP18: 0 | BQ18: =sum(U18:BH18) -> 100000 | BR18: =SUM(U18:BJ18) -> 100000
A19: =A18+1 -> 17 | B19: REFERAL (Berlangganan) | C19: 4181 | D19: DIGNITY SINAGA | E19: DIGNITY LAUNDRY | F19: 11384 | G19: irwan derano parulian sinaga | H19: monang londry | J19: Referral | K19: Bisnis 1 Bulan | L19: Lidya | N19: 45341 | O19: 45341 | P19: Belum 1 Tahun | S19: Dicairkan Sebagian | T19: Share CMO | AJ19: 12500 | AK19: - | AL19: 12500 | AM19: 12500 | AN19: 12500 | AO19: 12500 | AP19: US | AQ19: US | AR19: US | AS19: US | AT19: US | AU19: US | AV19: FINISH | BN19: =BR19-BQ19 -> 50000 | BO19: 0 | BP19: 0 | BQ19: =sum(AJ19) -> 12500 | BR19: =SUM(U19:BJ19) -> 62500
A20: =A19+1 -> 18 | B20: REFERAL (Berlangganan) | C20: 4181 | D20: DIGNITY SINAGA | E20: DIGNITY LAUNDRY | F20: 11517 | G20: Nanci Siregar | H20: MALONA LAUNDRY | J20: Referral | K20: Basic 12 Bulan | L20: Lidya | N20: 45360 | O20: 45369 | P20: Sudah 1 Tahun | S20: Selesai Dicairkan | AK20: 100000 | AL20: FINISH | BN20: =BR20-BQ20 -> 0 | BO20: 0 | BP20: 0 | BQ20: =sum(U20:BH20) -> 100000 | BR20: =SUM(U20:BJ20) -> 100000
A21: =A20+1 -> 19 | B21: REFERAL (Berlangganan) | C21: 4181 | D21: DIGNITY SINAGA | E21: DIGNITY LAUNDRY | F21: 11741 | G21: Pya Laundry | H21: PYA LAUNDRY | J21: Referral | K21: Basic 12 Bulan | L21: Lidya | N21: 45381 | O21: 30/03/02 | P21: Sudah 1 Tahun | S21: Selesai Dicairkan | AK21: 100000 | AL21: FINISH | BN21: =BR21-BQ21 -> 0 | BO21: 0 | BP21: 0 | BQ21: =sum(U21:BH21) -> 100000 | BR21: =SUM(U21:BJ21) -> 100000
A22: =A21+1 -> 20 | B22: REFERAL (Berlangganan) | C22: 7801 | D22: Rahmawaty Madjid | E22: Aroma Palopo / NETTO LAUNDRY | F22: 10406 | G22: Sania kartika | H22: Fast Laundry | J22: Referral | K22: Bisnis 12 Bulan | L22: Lidya | N22: 45225 | O22: 45225 | P22: Sudah 1 Tahun | S22: Dicairkan Sebagian | T22: Share CMO | AF22: 12500 | AG22: 12500 | AH22: 12500 | AI22: 112500 | AJ22: FINISH | BN22: =BR22-BQ22 -> 137500 | BO22: 0 | BP22: 0 | BQ22: =sum(AF22) -> 12500 | BR22: =SUM(U22:BJ22) -> 150000
A23: =A22+1 -> 21 | B23: REFERAL (Berlangganan) | C23: 7801 | D23: Rahmawaty Madjid | E23: Aroma Palopo / NETTO LAUNDRY | F23: 10463 | G23: Riska | H23: Fast Laundry (Riska) | J23: Referral | K23: Bisnis 12 Bulan | L23: Lidya | N23: 45234 | O23: 45234 | P23: Sudah 1 Tahun | S23: Selesai Dicairkan | AG23: 150000 | AH23: FINISH | BN23: =BR23-BQ23 -> 0 | BO23: 0 | BP23: 0 | BQ23: =sum(U23:BH23) -> 150000 | BR23: =SUM(U23:BJ23) -> 150000
A24: =A23+1 -> 22 | B24: REFERAL (Berlangganan) | C24: 11515 | D24: APRILIA | E24: SHARENA LAUNDRY | F24: 12577 | G24: Lanri | H24: CUGOZKLIN | J24: Referral | K24: Bisnis 12 Bulan | L24: Lidya | N24: 45474 | O24: 45476 | P24: Sudah 1 Tahun | Q24: 45478 | S24: Selesai Dicairkan | AO24: 150000 | AP24: FINISH | BN24: =BR24-BQ24 -> 0 | BO24: =SUM(AO24) -> 150000 | BP24: 0 | BQ24: =sum(U24:BH24) -> 150000 | BR24: =SUM(U24:BJ24) -> 150000
A25: =A24+1 -> 23 | B25: REFERAL (Berlangganan) | C25: 9441 | D25: Kasih Laundry Siantar | E25: Kasih Laundry | F25: 13944 | G25: Orlando Manalu | H25: LAUNDRY KITA | J25: Referral | K25: Bisnis 12 Bulan | L25: Lidya | N25: 45624 | O25: 45634 | P25: Sudah 1 Tahun | Q25: 45643 | S25: Selesai Dicairkan | AT25: 150000 | AU25: FINISH | BN25: =BR25-BQ25 -> 0 | BO25: =SUM(AT25) -> 150000 | BP25: 0 | BQ25: =sum(U25:BH25) -> 150000 | BR25: =SUM(U25:BJ25) -> 150000
A26: =A25+1 -> 24 | B26: REFERAL (Berlangganan) | C26: 14464 | D26: Kilo Laundry | E26: Kilo Laundry Singosari | F26: 14837 | G26: Alban Vincent Wikardo | H26: Cucci Laundry Malang | J26: Referral | K26: Bisnis 12 Bulan | L26: Lidya | N26: 45744 | O26: 45750 | P26: Sudah 1 Tahun | Q26: 45756 | S26: Selesai Dicairkan | AW26: 150000 | AX26: FINISH | BN26: =BR26-BQ26 -> 0 | BO26: 150000 | BP26: 0 | BQ26: =sum(U26:BH26) -> 150000 | BR26: =SUM(U26:BJ26) -> 150000
A27: =A26+1 -> 25 | B27: REFERAL (Berlangganan) | C27: 13944 | D27: Orlando Manalu | E27: LAUNDRY KITA | F27: 14299 | G27: samuel saimima | H27: Wezz Laundry | J27: Referral | K27: Bisnis 6 Bulan | L27: Lidya | N27: 45936 | O27: 46326 | P27: Sudah 1 Tahun | S27: Belum Dicairkan | T27: Share CMO | AU27: =12500*6 -> 75000 | AV27: - | AW27: - | AX27: - | AY27: - | AZ27: - | BA27: - | BB27: - | BC27: - | BD27: =12500*6 -> 75000 | BE27: FINISH | BN27: =BR27-BQ27 -> 150000 | BO27: 0 | BP27: 0 | BQ27: 0 | BR27: =SUM(U27:BJ27) -> 150000
A28: =A27+1 -> 26 | B28: REFERAL (Berlangganan) | C28: 10563 | D28: Abi Hafidz | E28: AZZAHRO LAUNDRY ٣٨ CIKANDE | F28: 14529 | G28: ulfa | H28: bintang laundry | J28: Referral | K28: Bisnis 6 Bulan | L28: Lidya | N28: 46053 | O28: 46239 | P28: Sudah 1 Tahun | S28: Belum Dicairkan | T28: Share CMO | AU28: =12500*6 -> 75000 | AV28: - | AW28: - | AX28: - | AY28: - | AZ28: - | BA28: - | BB28: =12500*6 -> 75000 | BC28: FINISH | BN28: =BR28-BQ28 -> 150000 | BO28: 0 | BP28: 0 | BQ28: 0 | BR28: =SUM(U28:BJ28) -> 150000
A29: =A28+1 -> 27 | B29: REFERAL (Berlangganan) | C29: - | D29: Selly Andini | E29: Sultan Laundry. co | F29: 15694 | G29: Lou Laundry | H29: Lou Laundry | J29: Referral | K29: Bisnis 12 Bulan | L29: Lidya | M29: https://drive.google.com/file/d/1XAHJn_aO9g0JZeVdXb1-ySaHH_dSNBXp/view?usp=sharing | N29: 45838 | O29: 45841 | P29: Sudah 1 Tahun | Q29: 45852 | S29: Selesai Dicairkan | BA29: 150000 | BB29: FINISH | BN29: =BR29-BQ29 -> 0 | BO29: 150000 | BP29: 0 | BQ29: =sum(U29:BH29) -> 150000 | BR29: =SUM(U29:BJ29) -> 150000
A30: =A29+1 -> 28 | B30: REFERAL (Berlangganan) | C30: 10409 | D30: Ahmad Kamal Dahlan | E30: Zona Laundry Mamuju | F30: 15520 | G30: Nuzul Rahmat | H30: Wonder Wash | J30: Referral | K30: Bisnis 12 Bulan | L30: Lidya | M30: https://drive.google.com/file/d/1bWhlEd_sniZnaEC4ffaBa2NuUAYLlHTb/view?usp=sharing | N30: 45805 | O30: 45817 | P30: Sudah 1 Tahun | Q30: 45862 | S30: Selesai Dicairkan | AZ30: 150000 | BA30: - | BB30: FINISH | BN30: =BR30-BQ30 -> 0 | BO30: 150000 | BP30: 0 | BQ30: =sum(U30:BH30) -> 150000 | BR30: =SUM(U30:BJ30) -> 150000
A31: =A30+1 -> 29 | B31: REFERAL (Berlangganan) | C31: 4323 | D31: Atik Nurbayati | E31: Delisha Laundry | F31: 15514 | G31: Siti Umayah | H31: Super Laundry | J31: Referral | K31: Basic 12 Bulan | L31: Lidya | M31: https://drive.google.com/file/d/1oeFvFHRb21ZPhzAP3hPIV9RYNHCB11au/view?usp=sharing | N31: 45805 | O31: 45807 | P31: Sudah 1 Tahun | Q31: 45862 | S31: Selesai Dicairkan | AY31: 100000 | AZ31: - | BA31: - | BB31: FINISH | BN31: =BR31-BQ31 -> 0 | BO31: 100000 | BP31: 0 | BQ31: =sum(U31:BH31) -> 100000 | BR31: =SUM(U31:BJ31) -> 100000
A32: =A31+1 -> 30 | B32: REFERAL (Berlangganan) | C32: 8177 | D32: Tengku ariani | E32: Mame laundry | F32: 16306 | G32: Vicky loundry | H32: loundry | J32: Referral | K32: Basic 6 Bulan | L32: Lidya | N32: 45911 | O32: 45911 | P32: Belum 1 Tahun | Q32: 45932 | S32: Selesai Dicairkan | BC32: 49998 | BN32: =BR32-BQ32 -> 0 | BO32: 49998 | BP32: 0 | BQ32: =sum(U32:BH32) -> 49998 | BR32: =SUM(U32:BJ32) -> 49998
A33: =A32+1 -> 31 | B33: AFILIASI (Perlengkapan Ex. Mesin | C33: 6125 | D33: Harapan | E33: Expert laundry | F33: 9174 | G33: Vicky loundry | H33: Teman Laundry | J33: Referral | K33: Bisnis 12 Bulan | L33: Lidya | N33: 45075 | O33: 45108 | P33: Sudah 1 Tahun | S33: Selesai Dicairkan | AA33: 150000 | AB33: FINISH | BN33: =BR33-BQ33 -> 0 | BO33: 0 | BP33: 0 | BQ33: =sum(U33:BH33) -> 150000 | BR33: =SUM(U33:BJ33) -> 150000
A34: =A33+1 -> 32 | B34: AFILIASI (Perlengkapan Ex. Mesin | C34: 6125 | D34: Harapan | E34: Expert laundry | F34: 9477 | G34: Arem Laundry | H34: Arem Laundry | J34: Referral | K34: Bisnis 12 Bulan | L34: Lidya | N34: 45112 | O34: 45127 | P34: Sudah 1 Tahun | S34: Selesai Dicairkan | AC34: 150000 | AD34: FINISH | BN34: =BR34-BQ34 -> 0 | BO34: 0 | BP34: 0 | BQ34: =sum(U34:BH34) -> 150000 | BR34: =SUM(U34:BJ34) -> 150000
A35: =A34+1 -> 33 | B35: AFILIASI (Perlengkapan Ex. Mesin | C35: 6125 | D35: Harapan | E35: Expert laundry | F35: 9621 | G35: Marta Situmorang | H35: Sahabat Laundry | J35: Referral | K35: Basic 1 Bulan | L35: Lidya | N35: 45124 | O35: 45132 | P35: Sudah 1 Tahun | S35: Dicairkan Sebagian | AC35: 8333 | AD35: 8333 | AE35: - | AF35: 8333 | AG35: US | AH35: US | AI35: US | AJ35: US | AK35: US | AL35: US | AM35: US | AN35: US | AO35: FINISH | BN35: =BR35-BQ35 -> 16666 | BO35: 0 | BP35: 0 | BQ35: =sum(AC35) -> 8333 | BR35: =SUM(U35:BJ35) -> 24999
A36: =A35+1 -> 34 | B36: AFILIASI (Perlengkapan Ex. Mesin | C36: 6125 | D36: Harapan | E36: Expert laundry | F36: 10156 | G36: KHANZA LAUNDRY | H36: KHANZA LAUNDRY | J36: Referral | K36: Basic 1 Bulan | L36: Lidya | N36: 45187 | O36: 45205 | P36: Sudah 1 Tahun | S36: Belum Dicairkan | AE36: 8333 | AF36: US | AG36: US | AH36: US | AI36: US | AJ36: US | AK36: US | AL36: US | AM36: US | AN36: US | AO36: US | AP36: US | AQ36: FINISH | BN36: =BR36-BQ36 -> 8333 | BO36: 0 | BP36: 0 | BQ36: 0 | BR36: =SUM(U36:BJ36) -> 8333
A37: =A36+1 -> 35 | B37: AFILIASI (Perlengkapan Ex. Mesin | C37: 6125 | D37: Harapan | E37: Expert laundry | F37: 10254 | G37: INDAH SARI BARUS | H37: SINAR LAUNDRY | J37: Referral | K37: Basic 1 Bulan | L37: Lidya | N37: 45197 | O37: 45197 | P37: Sudah 1 Tahun | Q37: 45880 | S37: Dicairkan Sebagian | T37: Share CMO | AE37: 8333 | AF37: - | AG37: 8333 | AH37: 8333 | AI37: 8333 | AJ37: 8333 | AK37: 8333 | AL37: 8333 | AM37: 8333 | AN37: 8333 | AO37: 8333 | AP37: 8333 | AQ37: 8333 | AR37: FINISH | BN37: =BR37-BQ37 -> 8333 | BO37: 0 | BP37: 0 | BQ37: =sum(AG37:AQ37) -> 91663 | BR37: =SUM(U37:BJ37) -> 99996
A38: =A37+1 -> 36 | B38: AFILIASI (Perlengkapan Ex. Mesin | C38: - | D38: Ardiansyah | E38: Loundrystore Jambi | F38: 14813 | G38: SAGA LAUNDRY | H38: SAGA LAUNDRY JAMBI | J38: Referral | K38: Bisnis 6 Bulan | L38: Lidya | N38: 45906 | O38: 46087 | P38: Sudah 1 Tahun | Q38: 45904 | S38: Dicairkan Sebagian | T38: Share CMO | AV38: =150000/2 -> 75000 | AW38: - | AX38: - | AY38: - | AZ38: - | BA38: - | BB38: - | BC38: 75000 | BD38: FINISH | BN38: =BR38-BQ38 -> 75000 | BO38: =sum(AV38:BB38) -> 75000 | BP38: 0 | BQ38: =sum(AV38:BB38) -> 75000 | BR38: =SUM(U38:BJ38) -> 150000
A39: =A38+1 -> 37 | B39: AFILIASI (Perlengkapan Ex. Mesin | C39: - | D39: KG TEKNIK BATAM | E39: KG TEKNIK BATAM | F39: 15129 | G39: Robin | H39: boss laundry | J39: Referral | K39: Bisnis 12 Bulan | L39: Lidya | N39: 45758 | O39: 45768 | P39: Sudah 1 Tahun | S39: Belum Dicairkan | T39: Share CMO | AX39: 150000 | AY39: FINISH | BN39: =BR39-BQ39 -> 150000 | BO39: =SUM(AR39) -> 0 | BP39: 0 | BQ39: 0 | BR39: =SUM(U39:BJ39) -> 150000
A40: =A39+1 -> 38 | B40: AFILIASI (Perlengkapan Ex. Mesin | C40: - | D40: KG TEKNIK BATAM | E40: KG TEKNIK BATAM | F40: 15401 | G40: Susi Yanti | H40: D' Laundry coin | J40: Referral | K40: Bisnis 6 Bulan | L40: Lidya | N40: 45782 | O40: 45782 | P40: Belum 1 Tahun | S40: Belum Dicairkan | T40: Share CMO | AY40: 75000 | AZ40: - | BA40: - | BB40: - | BC40: - | BD40: - | BE40: US | BF40: US | BG40: US | BN40: =BR40-BQ40 -> 75000 | BO40: =SUM(AR40) -> 0 | BP40: 0 | BQ40: 0 | BR40: =SUM(U40:BJ40) -> 75000
...

Sheet Komisi Mitra Corporate
A1: Komisi Mitra Corporate Aplikasi Piposmart Laundry
A2: Nama Paket | B2: Per Bulan | C2: Komisi / Outlet | D2: Bonus Pencapaian (10 Orang) | E2: Total Pendapatan (30 Orang)
A3: Paket Basic | B3: =C3/12 -> 10010 | C3: 120120 | D3: 500000 | E3: 5103600
A4: Paket Business | B4: =C4/12 -> 15143.333 | C4: 181720 | D4: 1000000 | E4: 8451600
A5: Paket Bundling Business | B5: =C5/12 -> 19987.5 | C5: 239850 | D5: 1500000 | E5: 11695500
A6: UMKM | B6: =C6/12 -> 22492.5 | C6: 269910 | D6: 2000000 | E6: 14097300
A7: Entrepeneur | B7: =C7/12 -> 26242.5 | C7: 314910 | D7: 2500000 | E7: 16947300
A8: Peluang Kerjasama Menjadi Mitra Piposmart :
A9: - Setiap mitra corporate Piposmart berhak memperoleh dua kategori pendapatan, yaitu komisi dan bonus pencapaian.
A10: 1. Komisi: Diberikan untuk setiap akuisisi nasabah berdasarkan kategori plangganan yang dipilih oleh nasabah.
A11: 2. Bonus Pencapaian: Diberikan untuk setiap kelipatan 10 nasabah yang berhasil berlangganan, dengan sistem akumulasi yang berlaku sesuai dengan kategori nasabah.
A12: - Besaran komisi yang diterima oleh mitra corporate akan disesuaikan dengan paket langganan yang telah ditetapkan oleh perusahaan.
A13: - Komisi akan dibayarkan setelah nasabah melakukan pembayaran paket berlangganan yang telah dipilih.
A15: dihitung berdasarkan 30 nasabah
A17: dihitung berdasarkan 10 nasabah

Sheet Salinan dari Daftar Mitra
A1: No | B1: CMO | C1: MITRA | D1: Kategori Mitra | E1: Tanggal Kerjasama | F1: Kode Owner | G1: Nama | H1: Nama Brand / Outlet | I1: No Hp | J1: Email | K1: Kecamatan | L1: Kabupaten/Kota | M1: Provinsi | N1: Alamat | O1: No Rekening | P1: Nama Bank | Q1: Jumlah Referral | R1: PIC | S1: Keterangan | T1: PIC 2
A2: 1 | B2: SHARE CMO | C2: REFERAL (Berlangganan) | D2: REFERRAL | F2: 11117 | G2: Guruh Adi Pratama | H2: Doux Laundry | I2: 082114005032 | J2: pratamaadiguruh@gmail.com | L2: Jakarta Selatan | M2: Dki Jakarta | N2: Kebembem Raya No 35 Jagakarsa, Jakarta Selatan, DKI Jakarta | O2: 7180472813 | P2: BCA | Q2: 1 | R2: Heriwati | T2: Novel
A3: =A2+1 -> 2 | B3: SHARE CMO | C3: REFERAL (Berlangganan) | D3: REFERRAL | F3: 1694 | G3: Julita | H3: Kitee_Laundry | I3: 0822 88381555 | J3: julita.susanti123@gmail.com | K3: Ranai Darat | L3: Kab. Natuna | M3: Kepulauan Riau | N3: JLN. HR SEOBRANTAS RT/RW 002/003 RANAI DARAT | O3: 1090016628075 | P3: MANDIRI | Q3: 2 | R3: Heriwati | T3: Lady
A4: =A3+1 -> 3 | B4: SHARE CMO | C4: REFERAL (Berlangganan) | D4: REFERRAL | F4: 4134 | G4: Chareel Josua Vandana Maningkas | H4: Mercy Laundry | I4: 087712092001 | J4: cika.roline777@gmail.com | K4: Siopat Suhu | L4: Kota Pematang Siantar | M4: Sumatera Utara | N4: Asrama Poltekad Kodiklatad, Kota Pematang Siantar, Sumatera Utara | Q4: 1 | R4: Heriwati | T4: Lady
A5: =A4+1 -> 4 | B5: SHARE CMO | C5: REFERAL (Berlangganan) | D5: REFERRAL | E5: 45920 | F5: 15517 | G5: Erika/ M. Iqbal Romzah | H5: Many Laundy | I5: 081802656191 | J5: iqbalwilianza@gmail.com | K5: Jagakarsa | L5: Jakarta Selatan | M5: Dki Jakarta | N5: Gg. Muara IA Tanjung barat jakarta selatan | O5: 8681130152 | P5: BCA | Q5: 1 | R5: Heriwati | T5: Novel
A6: =A5+1 -> 5 | B6: SHARE CMO | C6: AFILIASI (Perlengkapan Ex. Mesin | D6: PERLENGKAPAN | F6: 1782 | G6: Ismail | H6: Akbar Laundry | I6: 085251394079 | J6: ismail2015648@gmail.com | K6: Sungai Bangkong | L6: Kota Pontianak | M6: Kalimantan Barat | N6: jln dr Sutomo GG karya 1 no 78 Akbar Laundry dan Service Pontianak Kalimantan barat | O6: 304701028491533 | P6: BRI | Q6: 8 | R6: Heriwati | T6: Givoni
A7: =A6+1 -> 6 | B7: SHARE CMO | C7: AFILIASI (Perlengkapan Ex. Mesin | D7: PERLENGKAPAN | E7: 44927 | F7: 6343 | G7: Ade Syahputra | H7: Key Loundry/AAdelia store | I7: 085270356833 | J7: papakey1708@gmail.com | K7: Sei Semayang | L7: Kab. Deli Serdang | M7: Sumatera Utara | N7: jln mesjid dusun 1 aman damai,Sei Semayang,Kab. Deli Serdang,Sumatera Utara | Q7: 12 | R7: Heriwati | T7: Givoni
A8: =A7+1 -> 7 | B8: SHARE CMO | C8: AFILIASI (Perlengkapan Ex. Mesin | D8: PERLENGKAPAN | F8: 989 | G8: Pak NANANG | H8: Junior Laundry | I8: 087786116755 | J8: nanangjunior232@gmail.com | K8: Grogol | L8: Kab. Sukoharjo | M8: Jawa Tengah | N8: jl.parangkesit , Ngruki 02/17 , cemani , Grogol , sukoharjo, Jawa Tengah | Q8: 6 | R8: Heriwati | T8: Givoni
A9: =A8+1 -> 8 | B9: SHARE CMO | C9: AFILIASI (Perlengkapan Ex. Mesin | D9: PERLENGKAPAN | G9: Pak Medi | H9: BMG Laundry | Q9: 2 | R9: Heriwati | T9: Givoni
A10: =A9+1 -> 9 | B10: SHARE CMO | C10: AFILIASI (Perlengkapan Ex. Mesin | D10: PERLENGKAPAN | F10: 6509 | G10: Mulya Sari | H10: mulya jaya abadi | I10: 0813833788860 | J10: mulyasari992@gmail.com | K10: Cempaka Putih | L10: Kota Jakarta Pusat | M10: Dki Jakarta | N10: jl.cempaka putih tengah 1 no 10 a | Q10: 6 | R10: Heriwati | T10: Givoni
A11: =A10+1 -> 10 | B11: SHARE CMO | C11: AFILIASI (Perlengkapan Ex. Mesin | D11: PERLENGKAPAN | F11: 8645 | G11: Yendri Yusman | H11: Dhiva Laundry | I11: 081238802987 | J11: makmur0902@gmail.com | K11: Medan Maimun | L11: Kota Medan | M11: Sumatera Utara | N11: Jl. Brigjen katamso, Kel.Kampung Baru, Kec.Medan Maimun, Kota Medan, Sumatera Utara | O11: 8430520009 | P11: BCA | Q11: 4 | R11: Heriwati | T11: Givoni
A12: =A11+1 -> 11 | B12: SHARE CMO | C12: AFILIASI (Perlengkapan Ex. Mesin | D12: PERLENGKAPAN | F12: 14152 | G12: Mohacmad Hadi | H12: PUTRA TEKNIK SEMARANG | I12: 087718146514 | J12: alifjunior210@gmail.com | L12: Semarang | M12: Jawa Tengah | N12: jl. Bukit Palem Kipas Blok 7, Semarang, Jawa Tengah | O12: 303701020614532 | P12: BRI | Q12: 2 | R12: Heriwati | T12: Givoni
A13: =A12+1 -> 12 | B13: SHARE CMO | C13: AFILIASI (Perlengkapan Ex. Mesin | D13: PERLENGKAPAN | G13: Adip | H13: ADIP LAUNDRY SEMARANG | I13: 081575502277 | Q13: 1 | R13: Heriwati | T13: Givoni
A14: =A13+1 -> 13 | B14: SHARE CMO | C14: FRANCHISE (Jual Brand Usaha) | D14: FRENCHISE | E14: 45047 | G14: Beta Nurry Damayanti | H14: Deter_gent Laundry | I14: 081252347769 | J14: @detergentlaundry_official | K14: Lowokwaru | L14: Kota Malang | M14: Jawa Timur | N14: Jln Simp.Pandan Arum No 2 RT 01 RW 02, Desa/Kel. Jatimulyo, | O14: 223701000459309 | P14: BRI | Q14: 6 | R14: Heriwati | T14: Givoni
A15: =A14+1 -> 14 | B15: SHARE CMO | C15: FRANCHISE (Jual Brand Usaha) | D15: FRENCHISE | F15: 10717 | G15: joko Widodo daulay | H15: Adira laundry expres | I15: 082181303164 | J15: askaraputradaulay@gmail.com | K15: Kisaran Timur | L15: Kab. Asahan | M15: Sumatera Utara | N15: Jalan kakak Tua, kisaran. Kab. Asahan,Sumatera Utara | O15: 269276177 | P15: BNI | Q15: 2 | R15: Heriwati | T15: Givoni
A16: =A15+1 -> 15 | B16: SHARE CMO | C16: REFERAL (Berlangganan) | D16: REFERRAL | F16: 5836 | G16: Adi Prayitno | H16: Inches Laundry Express | I16: 082110007816 | J16: adiprayitno754@gmail.com | K16: Sungai Jawi | L16: Kota Pontianak | M16: Kalimantan Barat | N16: Jl. Tabrani Ahmad, Pontianak, kalimantan Barat | Q16: 1 | R16: Heriwati | T16: Givoni
A17: =A16+1 -> 16 | B17: SHARE CMO | C17: REFERAL (Berlangganan) | D17: REFERRAL | F17: 4896 | G17: Elisabeth | H17: Baladewa Laundry | I17: 089639843456 | J17: dhinidhini893@gmail.com | K17: Puseurjaya | L17: Kab. Karawang | M17: Jawa Barat | N17: Jl. Menati 1 No.27 Puserjaya Kec. Telukjambe Timur Kab. Karawang | Q17: 1 | R17: Heriwati | T17: Givoni
A18: =A17+1 -> 17 | B18: SHARE CMO | C18: REFERAL (Berlangganan) | D18: REFERRAL | F18: 7233 | G18: Riendi Pratama | H18: Adrienu laundry | I18: 081295989384 | J18: riendi.pratama@gmail.com | K18: Padangsambian Klod | L18: Kota Denpasar | M18: Bali | N18: Padangsambian,Kota Denpasar Kota Bali, Bali | Q18: 1 | R18: Heriwati | T18: Givoni
A19: =A18+1 -> 18 | B19: SHARE CMO | C19: REFERAL (Berlangganan) | D19: REFERRAL | F19: 2700 | G19: My Laundry | H19: Rezky Perdana | I19: 08116360330 | J19: superlte4g@gmail.com | K19: Tanjung Gusta | L19: Kab. Deli Serdang | M19: Sumatera Utara | N19: JL LEMBAGA PEMASYARAKATAN NO 225 | Q19: 4 | R19: Heriwati | T19: Givoni
A20: =A19+1 -> 19 | B20: SHARE CMO | C20: REFERAL (Berlangganan) | D20: REFERRAL | G20: Rico Yuli Prasetyo | H20: Raja Laundry | I20: O89501299837 | J20: rico.pras09785@gmail.com | L20: Surabaya | M20: Jawa Timur | N20: Bendul merisi GG 1 selatan no.59 surabaya | O20: 4290938843 | P20: BCA | Q20: 3 | R20: Heriwati | T20: Givoni
A21: =A20+1 -> 20 | B21: SHARE CMO | C21: REFERAL (Berlangganan) | D21: REFERRAL | F21: 9265 | G21: Adi Muhammadiah | H21: CANDU LAUNDRY | I21: 087796877639 | J21: muhammadiah99@gmail.com | K21: Siantan | L21: Kab. Pontianak | M21: Kalimantan Barat | N21: Jalan Raya Jungkat | Q21: 1 | R21: Heriwati | T21: Givoni
A22: =A21+1 -> 21 | B22: SHARE CMO | C22: REFERAL (Berlangganan) | D22: REFERRAL | E22: September 2025 | F22: 14972 | G22: Trimardijati | H22: My Laundry | I22: 081236885494 | J22: maya2272@gmail.com | K22: Nunbaun Sabu | L22: Kota Kupang | M22: Nusa Tenggara Timur | N22: Jalan Pahlawan No 22 | O22: 44538470 | P22: BNI | Q22: 1 | R22: Heriwati | T22: Givoni
A23: =A22+1 -> 22 | B23: SHARE CMO | C23: REFERAL (Berlangganan) | D23: REFERRAL | E23: Oktober 2025 | G23: Razeco Laundry | H23: Razeco Laundry | I23: 085361656385 | J23: emmanputera85@gmail.com | K23: Medan selayang | L23: Kota Medan | M23: Sumatera Utara | N23: Perumahan Wijaya kesuma residence no 20. Jl. bunga Wijaya kesuma, kel PB. selayang II kecamatan Medan selayang Kota Medan | O23: 3491613155 | P23: BCA | Q23: 1 | R23: Heriwati | T23: Givoni
A24: =A23+1 -> 23 | B24: SHARE CMO | C24: FRANCHISE (Jual Brand Usaha) | D24: FRENCHISE | E24: Agustus 2024 | F24: 10682 | G24: Pandapotan | H24: TUNTAS TENGGUMUNG | I24: 082257529696 | J24: tuntaslaundrytenggumung@gmail.com | K24: Wonokusumo | L24: Kota Surabaya | M24: Jawa Timur | N24: Jl.Tenggumung Karya Lor No.53 | O24: 6985282611 | P24: BCA | Q24: 1 | R24: Heriwati | T24: Givoni
A25: =A24+1 -> 24 | B25: SHARE CMO | C25: AFILIASI (Perlengkapan Ex. Mesin | D25: PERLENGKAPAN | F25: - | G25: Agung | H25: KING LAUNDRY | I25: 081260746002 | Q25: 1 | R25: Heriwati | T25: Givoni
A26: =A25+1 -> 25 | B26: SHARE CMO | C26: FRANCHISE (Jual Brand Usaha) | D26: FRENCHISE | F26: 6926 | G26: leny | H26: Get Laundry RMJ | I26: 087777139459 | J26: lenidwiyarti321@gmail.com | K26: Kec. Serpong | L26: Kota Tangerang Selatan | M26: Banten | N26: ln. Ciater Rt 004/Rw 022, Kel. Rawa Buntu Kec. Serpong, Kota Tangerang Selatan, Banten | O26: Top Up Saldo | Q26: 2 | R26: Lidya | T26: Intan
A27: =A26+1 -> 26 | B27: SHARE CMO | C27: FRANCHISE (Jual Brand Usaha) | D27: FRENCHISE | F27: 11165 | G27: Ayu Widyasari primanda | H27: HAWP LAUNDRY | I27: 082197946038 | J27: ayuwidyasariprimanda000@gmail.com | K27: Kec. Sukmajaya | L27: Kota Depok | M27: Jawa Barat | N27: jln kemang swatama, gg H Tarin no 28, Kel/Kec Sukmajaya Depok | Q27: 1 | R27: Lidya | T27: Intan
A28: =A27+1 -> 27 | B28: SHARE CMO | C28: REFERAL (Berlangganan) | D28: REFERRAL | F28: 1522 | G28: Sugiana | H28: Indah Express Laundry | I28: 082147446756 | J28: ndahtari7@gmail.com | K28: Denpasar Selatan | L28: Kota Denpasar | M28: Bali | N28: Danau tempe no.35 sanur kecamatan Denpasar Selatan | Q28: 1 | R28: Lidya | T28: Intan
A29: =A28+1 -> 28 | B29: SHARE CMO | C29: REFERAL (Berlangganan) | D29: REFERRAL | F29: 6058 | G29: Citra Halim | H29: Citra Laundry | I29: 08174885266 | J29: citra.halim1@gmail.com | K29: Tanjung Duren Selatan | L29: Kota Jakarta Barat | M29: Dki Jakarta | N29: Jl. Tanjung Duren Timur Raya Gang Mandalika, Kota Jakarta Barat, Dki Jakarta | Q29: 2 | R29: Lidya | T29: Intan
A30: =A29+1 -> 29 | B30: SHARE CMO | C30: REFERAL (Berlangganan) | D30: REFERRAL | F30: 7479 | G30: farhan alfatan | H30: juragan laundry | I30: 082125008245 | J30: rabbittank02@gmail.com | K30: Kec. Banyusari | L30: Kab. Karawang | M30: Jawa Barat | N30: kp.krajan1 ds.jayamukti kec.banyusari kab.karawang | Q30: 1 | R30: Lidya | T30: Intan
A31: =A30+1 -> 30 | B31: SHARE CMO | C31: REFERAL (Berlangganan) | D31: REFERRAL | F31: 4723 | G31: Budi Santo | H31: sahabat laundry | I31: 082174637062 | J31: sahabatlaundrybaru@gmail.com | K31: Cikampek | L31: Kab. Karawang | M31: Jawa Barat | N31: jln pertokoan stasiun cikampek nmr 2, Kab. Karawang, Jawa Barat | Q31: 6 | R31: Lidya | T31: Intan
A32: =A31+1 -> 31 | B32: SHARE CMO | C32: REFERAL (Berlangganan) | D32: REFERRAL | F32: 4181 | G32: DIGNITY SINAGA | H32: DIGNITY LAUNDRY | I32: 0811620080 | J32: sachio3008@gmail.com | K32: Tangerang | L32: Kota Tangerang | M32: Banten | N32: Tanggerang, Cikokol, Tangerang, Banten | Q32: 6 | R32: Lidya | T32: Intan
A33: =A32+1 -> 32 | B33: SHARE CMO | C33: REFERAL (Berlangganan) | D33: REFERRAL | F33: 7801 | G33: Rahmawaty Madjid | H33: Aroma Palopo / NETTO LAUNDRY | I33: 08114220487 | J33: aromapaloponmie@gmail.com | K33: Kadia | L33: Kota Kendari | M33: Sulawesi Tenggara | N33: Food Court The Park,Kadia,Kota Kendari,Sulawesi Tenggara | Q33: 2 | R33: Lidya | T33: Intan
A34: =A33+1 -> 33 | B34: SHARE CMO | C34: REFERAL (Berlangganan) | D34: REFERRAL | F34: 11515 | G34: APRILIA | H34: SHARENA LAUNDRY | I34: 085210108123 | J34: apinkcalen@gmail.com | K34: Kec. Cakung | L34: Kota Jakarta Timur | M34: Dki Jakarta | N34: JL H.R ISMAIL RT 08 RW 03 JATINEGARA CAKUNG JAKARTA TIMUR | O34: 0940964237 | P34: BCA | Q34: 1 | R34: Lidya | T34: Intan
A35: =A34+1 -> 34 | B35: SHARE CMO | C35: REFERAL (Berlangganan) | D35: REFERRAL | F35: 9441 | G35: Kasih Laundry Siantar | H35: Kasih Laundry | I35: 0859106762310 | J35: kasihlaundrysiantar@gmail.com | K35: Bukit Shofa | L35: Kota Pematang Siantar | M35: Sumatera Utara | N35: Jl.Sisingamangaraja, No.15, Bukit Sofa, Siantar Sitalasari, Pematang Siantar | Q35: 1 | R35: Lidya | T35: Intan
A36: =A35+1 -> 35 | B36: SHARE CMO | C36: REFERAL (Berlangganan) | D36: REFERRAL | F36: 14464 | G36: Kilo Laundry | H36: Kilo Laundry Singosari | I36: 087866932707 | J36: deanathaniaardita96@gmail.com | K36: Kec. Singosari | L36: Kab. Malang | M36: Jawa Timur | N36: Jl raya mondoroko, Mondoroko, Singosari, Kec. Singosari, Kabupaten Malang, Jawa Timur | O36: 0881632747 | P36: BCA | Q36: 1 | R36: Lidya | T36: Intan
A37: =A36+1 -> 36 | B37: SHARE CMO | C37: REFERAL (Berlangganan) | D37: REFERRAL | F37: 13944 | G37: Orlando Manalu | H37: LAUNDRY KITA | I37: 085163695628 | J37: orlandomanalu0@gmail.com | K37: Kec. Siantar | L37: Kab. Simalungun | M37: Sumatera Utara | N37: Jl. Asahan,KM 3,5. Pematang Simalungun, Kec. Siantar, Kabupaten Simalungun, Sumatera Utara 21151(Komplek Graha Asahan Gold) | Q37: 1 | R37: Lidya | T37: Intan
A38: =A37+1 -> 37 | B38: SHARE CMO | C38: REFERAL (Berlangganan) | D38: REFERRAL | F38: 10563 | G38: Abi Hafidz | H38: AZZAHRO LAUNDRY ٣٨ CIKANDE | I38: 085217955565 | J38: noer.underbon9048@gmail.com | K38: Kec. Cikande | L38: Kab. Serang | M38: Banten | N38: kp.Gegong burung Rt 02/02 Desa situterate Kec. Cikande Kabupaten SERANG BANTEN kode pos 42186 | Q38: 1 | R38: Lidya | T38: Intan
A39: =A38+1 -> 38 | B39: SHARE CMO | C39: REFERAL (Berlangganan) | D39: REFERRAL | G39: Selly Andini | H39: Sultan Laundry. co | I39: 082297051345 | J39: Sellyandini15@yahoo.com | L39: Tanggerang | M39: Dki Jakarta | N39: Jln. Duta Raya, Perumahan Taman Cibodas, Blok H1 No.2, Tanggerang | O39: 6250379160 | P39: BCA | Q39: 1 | R39: Lidya | T39: Intan
A40: =A39+1 -> 39 | B40: SHARE CMO | C40: REFERAL (Berlangganan) | D40: REFERRAL | E40: Mei | F40: 10409 | G40: Ahmad Kamal Dahlan | H40: Zona Laundry Mamuju | I40: 085213159125 | J40: kamaldoremi@gmail.com | K40: Kec. Simboro | L40: Kab. Mamuju | M40: Sulawesi Barat | N40: Jl. Martadinata Mamuju, Kab. Mamuju | O40: 305401020779530 | P40: BRI | Q40: 1 | R40: Lidya | T40: Intan
...

Sheet Sheet4
A2: Referral | B2: Corporate Paket Bisnis | C2: Corporate Paket Basic | D2: Corporate Paket UMKM | E2: Corporate Paket Bundling Bisnis
A3: =COUNTIF('Mitra - Referral'!$J$3:$J$239,A2) -> 217 | B3: =COUNTIF('Mitra - Referral'!$J$3:$J$239,B2) -> 4 | C3: =COUNTIF('Mitra - Referral'!$J$3:$J$239,C2) -> 8 | D3: =COUNTIF('Mitra - Referral'!$J$3:$J$239,D2) -> 1 | E3: =COUNTIF('Mitra - Referral'!$J$3:$J$239,E2) -> 1
A5: =A4+1 -> 1 | B5: AFILIASI (Perlengkapan Ex. Mesin, Parfum, Dll) | D5: Taufik | E5: mesincucilaundry.com | F5: 14142 | G5: Diah Ijah Mahmudah | H5: PD Laundry Express | I5: Referral | J5: Bisnis 6 Bulan | K5: Lidya | M5: 45660 | N5: 45660 | O5: Belum 1 Tahun | R5: =COUNTIF($D$5:$D$91,D5) -> 12 | AT5: =12500*6 -> 75000 | AU5: - | AV5: - | AZ5: =BD5-BC5 -> 75012 | BA5: 0 | BB5: 0 | BC5: 0 | BD5: =SUM(R5:AX5) -> 75012
A6: =A5+1 -> 2 | B6: AFILIASI (Perlengkapan Ex. Mesin, Parfum, Dll) | D6: Taufik | E6: mesincucilaundry.com | F6: 14547 | G6: Nur Fadhillah Octavia | H6: Sera Laundry | I6: Referral | J6: Basic 6 Bulan | K6: Lidya | M6: 45688 | N6: 45688 | O6: Belum 1 Tahun | AR6: =8333*6 -> 49998 | AS6: - | AT6: - | AU6: - | AZ6: =BD6-BC6 -> 49998 | BA6: 0 | BB6: 0 | BC6: 0 | BD6: =SUM(R6:AX6) -> 49998
A7: =A6+1 -> 3 | B7: AFILIASI (Perlengkapan Ex. Mesin, Parfum, Dll) | D7: Taufik | E7: mesincucilaundry.com | F7: 14538 | G7: Teguh Pratama | H7: RTP LAUNDRY | I7: Referral | J7: Bisnis 12 Bulan | K7: Lidya | M7: 45689 | N7: 46061 | O7: Sudah 1 Tahun | AS7: 150000 | AT7: FINISH | AZ7: =BD7-BC7 -> 150000 | BA7: 0 | BB7: 0 | BC7: 0 | BD7: =SUM(R7:AX7) -> 150000
A8: =A7+1 -> 4 | B8: AFILIASI (Perlengkapan Ex. Mesin, Parfum, Dll) | D8: Taufik | E8: mesincucilaundry.com | F8: 14588 | G8: yenni lim | H8: Momo Laundry | I8: Referral | J8: Bisnis 6 Bulan | K8: Lidya | M8: 45693 | N8: 45886 | O8: Belum 1 Tahun | AS8: =12500*6 -> 75000 | AT8: - | AU8: - | AV8: - | AW8: - | AX8: - | AZ8: =BD8-BC8 -> 75000 | BA8: 0 | BB8: 0 | BC8: 0 | BD8: =SUM(R8:AX8) -> 75000
A9: =A8+1 -> 5 | B9: AFILIASI (Perlengkapan Ex. Mesin, Parfum, Dll) | D9: Taufik | E9: mesincucilaundry.com | F9: 14514 | G9: Eka Ratna Juwita | H9: Cucumbah Laundry | I9: Referral | J9: Basic 6 Bulan | K9: Lidya | M9: 45849 | N9: 45879 | O9: Belum 1 Tahun | AS9: =8333*6 -> 49998 | AT9: - | AU9: - | AV9: - | AW9: - | AX9: - | AZ9: =BD9-BC9 -> 49998 | BA9: 0 | BB9: 0 | BC9: 0 | BD9: =SUM(R9:AX9) -> 49998
A10: =A9+1 -> 6 | B10: AFILIASI (Perlengkapan Ex. Mesin, Parfum, Dll) | D10: Taufik | E10: mesincucilaundry.com | F10: 14636 | G10: Shalwa Laundry | H10: Shalwa Laundry & Dry Cleaning | I10: Referral | J10: Basic 3 Bulan | K10: Lidya | M10: 45720 | N10: 45810 | O10: Belum 1 Tahun | AT10: =8333*3 -> 24999 | AU10: - | AV10: - | AZ10: =BD10-BC10 -> 24999 | BA10: 0 | BB10: 0 | BC10: 0 | BD10: =SUM(R10:AX10) -> 24999
A11: =A10+1 -> 7 | B11: AFILIASI (Perlengkapan Ex. Mesin, Parfum, Dll) | D11: Taufik | E11: mesincucilaundry.com | F11: 15266 | G11: Henny Rahmawati | H11: Barbie Laundry | I11: Referral | J11: Bisnis 12 Bulan | K11: Lidya | M11: 45769 | N11: 45782 | O11: Sudah 1 Tahun | AJ11: 150000 | AZ11: =BD11-BC11 -> 150000 | BA11: 0 | BB11: 0 | BC11: 0 | BD11: =SUM(R11:AX11) -> 150000
A12: =A11+1 -> 8 | B12: AFILIASI (Perlengkapan Ex. Mesin, Parfum, Dll) | D12: Taufik | E12: mesincucilaundry.com | F12: 15375 | G12: maria sihombing | H12: Andaria laundry | I12: Referral | J12: Bisnis 12 Bulan | K12: Lidya | M12: 45791 | N12: 45793 | O12: Sudah 1 Tahun | AJ12: 150000 | AZ12: =BD12-BC12 -> 150000 | BA12: 0 | BB12: 0 | BC12: 0 | BD12: =SUM(R12:AX12) -> 150000
A13: =A12+1 -> 9 | B13: AFILIASI (Perlengkapan Ex. Mesin, Parfum, Dll) | D13: Taufik | E13: mesincucilaundry.com | F13: 15438 | G13: Suka Clean Service | H13: Suka Clean Service | I13: Referral | J13: Bisnis 12 Bulan | K13: Lidya | M13: 45796 | N13: 45808 | O13: Sudah 1 Tahun | AJ13: 150000 | AZ13: =BD13-BC13 -> 150000 | BA13: 0 | BB13: 0 | BC13: 0 | BD13: =SUM(R13:AX13) -> 150000
A14: =A13+1 -> 10 | B14: AFILIASI (Perlengkapan Ex. Mesin, Parfum, Dll) | D14: Taufik | E14: mesincucilaundry.com | F14: 14785 | G14: Yudo Yudho | H14: laudrybest | I14: Referral | J14: Bisnis 6 Bulan | K14: Lidya | M14: 45783 | AZ14: =BD14-BC14 -> 0 | BA14: 0 | BB14: 0 | BC14: 0 | BD14: =SUM(R14:AX14) -> 0
A15: =A14+1 -> 11 | B15: AFILIASI (Perlengkapan Ex. Mesin, Parfum, Dll) | D15: Taufik | E15: mesincucilaundry.com | F15: 15510 | G15: Lukmanul Hakim | H15: cuciqu laundry | I15: Referral | J15: Bisnis 6 Bulan | K15: Lidya | M15: 45797 | N15: 45809 | O15: Belum 1 Tahun | AK15: =12500*6 -> 75000 | AZ15: =BD15-BC15 -> 75000 | BA15: 0 | BB15: 0 | BC15: 0 | BD15: =SUM(R15:AX15) -> 75000
A16: =A15+1 -> 12 | B16: AFILIASI (Perlengkapan Ex. Mesin, Parfum, Dll) | D16: Taufik | E16: mesincucilaundry.com | F16: 15382 | G16: Kintan Deska Sasono Putri | H16: Rumah Laundry | I16: Referral | J16: Basic 12 Bulan | K16: Lidya | M16: 45792 | N16: 45794 | O16: Sudah 1 Tahun | AJ16: 100000 | AZ16: =BD16-BC16 -> 0 | BA16: 0 | BB16: 0 | BC16: =sum(AJ16) -> 100000 | BD16: =SUM(R16:AX16) -> 100000
A17: =A16+1 -> 13 | B17: AFILIASI (Perlengkapan Ex. Mesin, Parfum, Dll) | C17: 1782 | D17: Ismail | E17: Akbar Laundry | F17: 11304 | G17: Akhmad Daud, SE | H17: Danty Loundry | I17: Referral | J17: Basic 12 Bulan | K17: Heriwati | M17: 45353 | N17: 45353 | O17: Sudah 1 Tahun | P17: 45615 | R17: =COUNTIF($D$5:$D$91,D17) -> 8 | AH17: 100000 | AI17: FINISH | AZ17: =BD17-BC17 -> 8 | BA17: =SUM(AH17) -> 100000 | BB17: 0 | BC17: 100000 | BD17: =SUM(R17:AX17) -> 100008
A18: =A17+1 -> 14 | B18: AFILIASI (Perlengkapan Ex. Mesin, Parfum, Dll) | C18: 1782 | D18: Ismail | E18: Akbar Laundry | F18: 11332 | G18: BAHARI ENJOY | H18: mercy laundry | I18: Referral | J18: Basic 12 Bulan | K18: Heriwati | M18: 45324 | N18: 45324 | O18: Sudah 1 Tahun | P18: 45615 | AG18: 100000 | AH18: FINISH | AZ18: =BD18-BC18 -> 0 | BA18: =SUM(AG18) -> 100000 | BB18: 0 | BC18: 100000 | BD18: =SUM(R18:AX18) -> 100000
A19: =A18+1 -> 15 | B19: AFILIASI (Perlengkapan Ex. Mesin, Parfum, Dll) | C19: 1782 | D19: Ismail | E19: Akbar Laundry | F19: 11335 | G19: Sony Triyadi | H19: Amel Laundry | I19: Referral | J19: Basic 12 Bulan | K19: Heriwati | M19: 45345 | N19: 45345 | O19: Sudah 1 Tahun | P19: 45615 | AG19: 100000 | AH19: FINISH | AZ19: =BD19-BC19 -> 0 | BA19: =SUM(AG19) -> 100000 | BB19: 0 | BC19: 100000 | BD19: =SUM(R19:AX19) -> 100000
A20: =A19+1 -> 16 | B20: AFILIASI (Perlengkapan Ex. Mesin, Parfum, Dll) | C20: 1782 | D20: Ismail | E20: Akbar Laundry | F20: 12599 | G20: Yellow laundry | H20: Yellow laundry | I20: Referral | J20: Basic 12 Bulan | K20: Heriwati | M20: 45481 | N20: 45481 | O20: Sudah 1 Tahun | P20: 45615 | AL20: 100000 | AM20: FINISH | AZ20: =BD20-BC20 -> 0 | BA20: =SUM(AL20) -> 100000 | BB20: 0 | BC20: 100000 | BD20: =SUM(R20:AX20) -> 100000
A21: =A20+1 -> 17 | B21: AFILIASI (Perlengkapan Ex. Mesin, Parfum, Dll) | C21: 1782 | D21: Ismail | E21: Akbar Laundry | F21: 12557 | G21: Erika Mustifasari | H21: Clean & Co | I21: Referral | J21: Basic 12 Bulan | K21: Heriwati | M21: 45481 | N21: 45481 | O21: Sudah 1 Tahun | P21: 45615 | AL21: 100000 | AM21: FINISH | AZ21: =BD21-BC21 -> 0 | BA21: =SUM(AL21) -> 100000 | BB21: 0 | BC21: 100000 | BD21: =SUM(R21:AX21) -> 100000
A22: =A21+1 -> 18 | B22: AFILIASI (Perlengkapan Ex. Mesin, Parfum, Dll) | C22: 1782 | D22: Ismail | E22: Akbar Laundry | F22: 12748 | G22: Icha Nolita | H22: De'Cucci Laundry | I22: Referral | J22: Basic 12 Bulan | K22: Heriwati | M22: 45484 | N22: 45484 | O22: Sudah 1 Tahun | P22: 45615 | AL22: 100000 | AM22: FINISH | AZ22: =BD22-BC22 -> 0 | BA22: =SUM(AL22) -> 100000 | BB22: 0 | BC22: 100000 | BD22: =SUM(R22:AX22) -> 100000
A23: =A22+1 -> 19 | B23: AFILIASI (Perlengkapan Ex. Mesin, Parfum, Dll) | C23: 1782 | D23: Ismail | E23: Akbar Laundry | F23: 13597 | G23: Anikun Laundry | H23: Anikun Laundry | I23: Referral | J23: Basic 12 Bulan | K23: Heriwati | M23: 45589 | N23: 45589 | O23: Sudah 1 Tahun | P23: 45615 | AO23: 100000 | AP23: FINISH | AZ23: =BD23-BC23 -> 0 | BA23: =SUM(AO23) -> 100000 | BB23: 0 | BC23: 100000 | BD23: =SUM(R23:AX23) -> 100000
A24: =A23+1 -> 20 | B24: AFILIASI (Perlengkapan Ex. Mesin, Parfum, Dll) | C24: 1782 | D24: Ismail | E24: Akbar Laundry | F24: 14006 | G24: Titan Management | H24: Titan Laundry | I24: Referral | J24: Basic 12 Bulan | K24: Heriwati | M24: 45629 | N24: 45636 | O24: Sudah 1 Tahun | AQ24: 100000 | AR24: FINISH | AZ24: =BD24-BC24 -> 100000 | BA24: 0 | BB24: 0 | BC24: 0 | BD24: =SUM(R24:AX24) -> 100000
A25: =A24+1 -> 21 | B25: AFILIASI (Perlengkapan Ex. Mesin, Parfum, Dll) | C25: 6343 | D25: Ade Syahputra | E25: Key Loundry/AAdelia store | F25: 11295 | G25: King Laundry Grup | H25: King Laundry Marelan | I25: Referral | J25: Basic 1 Bulan | K25: Heriwati | M25: 45343 | N25: 45343 | O25: Sudah 1 Tahun | R25: =COUNTIF($D$5:$D$91,D25) -> 10 | AG25: 8333 | AH25: 8333 | AI25: 8333 | AJ25: 8333 | AK25: 8333 | AL25: US | AM25: US | AN25: US | AO25: US | AP25: US | AQ25: US | AR25: US | AS25: FINISHH | AZ25: =BD25-BC25 -> 33342 | BA25: 0 | BB25: 0 | BC25: =AG25 -> 8333 | BD25: =SUM(R25:AX25) -> 41675
A26: =A25+1 -> 22 | B26: AFILIASI (Perlengkapan Ex. Mesin, Parfum, Dll) | C26: 6343 | D26: Ade Syahputra | E26: Key Loundry/AAdelia store | F26: 11295 | G26: King Laundry Grup | H26: King Laundry Marendal | I26: Referral | J26: Basic 1 Bulan | K26: Heriwati | M26: 45343 | N26: 45343 | O26: Sudah 1 Tahun | AG26: 8333 | AH26: 8333 | AI26: 8333 | AJ26: 8333 | AK26: 8333 | AL26: 8333 | AM26: 8333 | AN26: 8333 | AO26: 8333 | AP26: 8333 | AQ26: 8333 | AR26: 8333 | AS26: FINISHH | AZ26: =BD26-BC26 -> 91663 | BA26: 0 | BB26: 0 | BC26: =AG26 -> 8333 | BD26: =SUM(R26:AX26) -> 99996
A27: =A26+1 -> 23 | B27: AFILIASI (Perlengkapan Ex. Mesin, Parfum, Dll) | C27: 6343 | D27: Ade Syahputra | E27: Key Loundry/AAdelia store | F27: 11703 | G27: sofia laundry | H27: sofia laundry | I27: Referral | J27: Bisnis 1 Bulan | K27: Heriwati | M27: 45379 | N27: 45380 | O27: Sudah 1 Tahun | AH27: 12500 | AI27: - | AJ27: 12500 | AK27: 12500 | AL27: 12500 | AM27: 12500 | AN27: 12500 | AO27: 12500 | AP27: 12500 | AQ27: 12500 | AR27: 12500 | AS27: 12500 | AT27: FINISHH | AZ27: =BD27-BC27 -> 137500 | BA27: 0 | BB27: 0 | BC27: 0 | BD27: =SUM(R27:AX27) -> 137500
