Workbook

Sheet JOB
A1: "DIVISI" | B1: "JOB DESCRIPTION"
A2: BUSINESS CONSULTANT | B2: 1. Memastikan Data Kelolaan di Hubungi dengan maksimal
B3: 2. Daily Call Minimal 20 New Customer di Hubungi
B4: 3. Demo Aplikasi Prioritas Closing
B5: 4. Nasabah Potensial Harus lebih banyak dibanding Target Pencapaian
B6: 5. Mencapai Target setiap bulan mengukur KPI
B7: 6. Invite new member di group Pengguna Aplikasi Piposmart di WhatsApp
B8: 7. Melampirkan fhoto usaha laundry yang telah bekerja sama
B9: 8. Ajak nasabah, Aflisiasi, Referral untuk menjadi mitra piposmart

Sheet SOP Data Kelolaan 2026
A1: SOP kategori nasabah menjadi Nasabah Potensi dan Nasabah Tidak Potensi (di tarik) | J1: ✨ TO DO LIST SALES & CS
A2: Kategori Nasabah Potensi
A3: Nasabah dapat dikategorikan sebagai Nasabah Potensi apabila memenuhi salah satu atau beberapa indikator berikut:
A4: Nasabah responsif dan interaktif selama masa trial. | J4: 🔥 TEAM SALES
A5: Terdapat rencana demo atau training lanjutan.
A6: Nasabah aktif membahas harga atau skema langganan aplikasi. | J6: 1. Follow up data kelolaan 50 data
A7: Terjadi peningkatan transaksi selama masa penggunaan. | J7: 2. Follow up data nasabah new download - Project list & outlet
A8: Memberikan rekomendasi rekan atau mitra. | J8: 3. Follow up data nasabah potensi
A9: Memiliki progres komunikasi yang mengarah pada closing. | J9: 4. Follow up data nasabah jatuh tempo
J10: 5. Follow up mitra kelolaan
A11: Untuk nasabah potensi, tim bisnis wajib: | J11: 6. Posting konten harian (Story WhatsApp)
A12: Melakukan follow up secara berkala dan terjadwal | J12: 7. Posting konten di Instagram, Tiktok dan FB.
A13: Mencatat perkembangan pada kolom call & chat | J13: 8. Follow up nasabah yang belum memberikan rating & logo laundry
A14: Mengarahkan ke proses closing atau upgrade paket | J14: 9. Daily report follow up data kelolaan (WA Group)
J15: 10. Daily report follow up data jatuh tempo (WA Group)
A16: Kategori Nasabah Tidak Potensi (Ditarik) | J16: 11. Pengisian data kelolaan : Data kelolaan, report follow up, data kelolaan mitra, data kpi, report penjualan.
A17: Nasabah dapat dikategorikan sebagai Tidak Potensi dan dapat ditarik dari daftar aktif apabila memenuhi kriteria berikut: | J17: 💬 TEAM CS
A18: Akun nasabah teridentifikasi sebagai akun testing atau akun karyawan. | J18: 1. Follow up data nasabah existing (Jatuh tempo & Berlangganan)
A19: Telah dilakukan follow up maksimal 5 (lima) kali baik call maupun chat tanpa respons | J19: 2. Follow up data nasabah non-regustrasi akun (user temp)
A20: Status chat “centang 1” tanpa respons selama 2–3 hari berturut-turut | J20: 3. Follow up data nasabah unsubscribe
A21: Nasabah secara langsung meminta untuk tidak dihubungi kembali
A22: Nomor tidak aktif atau tidak dapat dihubungi selama 2–3 hari berturut-turut
A23: Menolak karena harga tidak sesuai setelah penawaran resmi diberikan
A24: Transaksi outlet tidak bertambah baik selama masa trial maupun setelah masa trial
A27: Modul Call Cs | J27: Modul Chat Cs
A29: 1. Call Contacted : | J29: 1. Chat Send :
A30: - Telepon memanggil atau tidak tersambung dengan nomor atau nasabah yang di tuju | J30: - Chat ceklis 1 atau tidak terkirim
A31: 2. Call Connected | J31: - Nomor tidak aktif, nomor di blokir
J32: 2. Chat Delivered
A33: - Telepon masuk dan berdering tapi nasabah tidak merespon | J33: - Chat ceklis 2 atau terkirim tapi nasabah tidak merespon
A34: - Nomor nasabah aktif | J34: - Nomor nasabah aktif
A35: 3. Call Engage : | J35: 3. Chat Engage :
A36: - Nasabah mengangkat telepon tapi tidak ada percakapan lanjut, di putuskan sepihak oleh nasabah | J36: - Nasabah membalas pean tapi tidak ada percakapan lanjut, di putuskan sepihak oleh nasabah
A37: - Nasabah masih sibuk saat di hubungi atau sedang di jalan | J37: - Nasabah masih sibuk saat di chat atau sedang di jalan
A38: 4. Call Interest : | J38: 4. Chat Interest :
A39: - Nasabah tertarik dan masuk pembahasan lanjut mengenai penggunaaan aplikasi, fitur-fitur yang ada dan mengenai harga berlangganan | J39: - Nasabah tertarik dan masuk pembahasan lanjut mengenai penggunaaan aplikasi, fitur-fitur yang ada dan mengenai harga berlangganan
A40: - Nasabah sudah ada gambaran akan berlangganan paket apa | J40: - Nasabah sudah ada gambaran akan berlangganan paket apa
A41: 5. Call Prospek : | J41: 5. Chat Prospek :
A42: - Nasabah potensi dan nasabah sudah sampai tahap training demo aplikasi melalui online meeting atau pun visit ke laundry (Batam) | J42: - Nasabah potensi dan nasabah sudah sampai tahap training demo aplikasi melalui online meeting atau pun visit ke laundry (Batam)
A43: 6. Call Uninterest : | J43: 6. Chat Uninterest :
...

Sheet TARGET 
A2: Pencapaian TEAM HUNTER
A3: Tahun 2026
A4: Bulan | B4: Target User | C4: Target Omset | D4: Realisasi Membership | E4: Realisasi Omset | F4: Kekurangan User | G4: Kekurangan Omset | H4: Persentase Tercapai User (%) | I4: Persentase Target Booking (%) | J4: Penilaian Membership | K4: Penilaian Target | L4: User | M4: Pencapaian Week 1 | N4: User | O4: Pencapaian Week 2 | P4: User | Q4: Pencapaian Week 3 | R4: User | S4: Pencapaian Week 4
A5: Januari | B5: 20 | C5: 15000000 | D5: =L5+N5+P5+R5 -> 10 | E5: ='PotensiDemo '!M135 -> 12532297 | F5: =D5-B5 -> -10 | G5: =E5-C5 -> -2467703 | H5: =D5/B5 -> 0.5 | I5: =E5/C5 -> 0.83548647 | J5: =IF(H5>=100%,"Hijau",IF(H5>=70%,"Kuning",IF(H5>=50%,"Merah","Hitam"))) -> Merah | K5: =IF(I5>=100%,"Hijau",IF(I5>=70%,"Kuning",IF(I5>=50%,"Merah","Hitam"))) -> Kuning | L5: 3 | M5: ='PotensiDemo '!N126+'PotensiDemo '!N128+'PotensiDemo '!N129 -> 2854134 | N5: 5 | O5: ='PotensiDemo '!N123+'PotensiDemo '!N124+'PotensiDemo '!N122+'PotensiDemo '!N130+'PotensiDemo '!N131 -> 6692163 | P5: 1 | Q5: ='PotensiDemo '!N127 -> 1298000 | R5: 1 | S5: ='PotensiDemo '!N125 -> 1688000
A6: Februari | B6: 20 | C6: 15000000 | D6: =L6+N6+P6+R6 -> 4 | E6: ='PotensiDemo '!M116 -> 12591143 | F6: =D6-B6 -> -16 | G6: =E6-C6 -> -2408857 | H6: =D6/B6 -> 0.2 | I6: =E6/C6 -> 0.83940953 | J6: =IF(H6>=100%,"Hijau",IF(H6>=70%,"Kuning",IF(H6>=50%,"Merah","Hitam"))) -> Hitam | K6: =IF(I6>=100%,"Hijau",IF(I6>=70%,"Kuning",IF(I6>=50%,"Merah","Hitam"))) -> Kuning | L6: 1 | M6: ='PotensiDemo '!N101 -> 2078000 | N6: 1 | O6: ='PotensiDemo '!N103 -> 1298000 | P6: 2 | Q6: ='PotensiDemo '!N104+'PotensiDemo '!N105+'PotensiDemo '!N106+'PotensiDemo '!N107 -> 2150000 | R6: 0 | S6: 0
A7: Maret | B7: 35 | C7: 46100000 | D7: =L7+N7+P7+R7 -> 6 | E7: ='PotensiDemo '!M95 -> 8390000 | F7: =D7-B7 -> -29 | G7: =E7-C7 -> -37710000 | H7: =D7/B7 -> 0.17142857 | I7: =E7/C7 -> 0.18199566 | J7: =IF(H7>=100%,"Hijau",IF(H7>=70%,"Kuning",IF(H7>=50%,"Merah","Hitam"))) -> Hitam | K7: =IF(I7>=100%,"Hijau",IF(I7>=70%,"Kuning",IF(I7>=50%,"Merah","Hitam"))) -> Hitam | L7: 3 | M7: ='PotensiDemo '!N82+'PotensiDemo '!N83+'PotensiDemo '!N84 -> 4156000 | N7: 1 | O7: ='PotensiDemo '!N85 -> 858000 | P7: 1 | Q7: ='PotensiDemo '!N91 -> 1688000 | R7: 1 | S7: ='PotensiDemo '!N86 -> 1688000
A8: April | B8: 33 | C8: 42684888 | D8: =L8+N8+P8+R8 -> 5 | E8: ='PotensiDemo '!M76 -> 4707167 | F8: =D8-B8 -> -28 | G8: =E8-C8 -> -37977721 | H8: =D8/B8 -> 0.15151515 | I8: =E8/C8 -> 0.11027713 | J8: =IF(H8>=100%,"Hijau",IF(H8>=70%,"Kuning",IF(H8>=50%,"Merah","Hitam"))) -> Hitam | K8: =IF(I8>=100%,"Hijau",IF(I8>=70%,"Kuning",IF(I8>=50%,"Merah","Hitam"))) -> Hitam | L8: 3 | M8: ='PotensiDemo '!N57+'PotensiDemo '!N59+'PotensiDemo '!N60+'PotensiDemo '!N69 -> 3381086 | N8: 0 | O8: 0 | P8: 1 | Q8: 858000 | R8: 1 | S8: 468000
A9: Mei | B9: 18 | C9: 23894000 | D9: =L9+N9+P9+R9 -> 12 | E9: ='PotensiDemo '!M51 -> 15889022 | F9: =D9-B9 -> -6 | G9: =E9-C9 -> -8004978 | H9: =D9/B9 -> 0.66666667 | I9: =E9/C9 -> 0.66497958 | J9: =IF(H9>=100%,"Hijau",IF(H9>=70%,"Kuning",IF(H9>=50%,"Merah","Hitam"))) -> Merah | K9: =IF(I9>=100%,"Hijau",IF(I9>=70%,"Kuning",IF(I9>=50%,"Merah","Hitam"))) -> Merah | L9: 3 | M9: ='PotensiDemo '!N27+'PotensiDemo '!N28+'PotensiDemo '!N37 -> 3574020 | N9: 2 | O9: ='PotensiDemo '!N29+'PotensiDemo '!N38+'PotensiDemo '!N39+'PotensiDemo '!N40 -> 2309000 | P9: 3 | Q9: ='PotensiDemo '!N30+'PotensiDemo '!N36+'PotensiDemo '!N31 -> 4084000 | R9: 4 | S9: ='PotensiDemo '!N32+'PotensiDemo '!N33+'PotensiDemo '!N35+'PotensiDemo '!N34 -> 5922002
A10: Juni | B10: 18 | C10: 28150000 | D10: =L10+N10+P10+R10 -> 8 | E10: ='PotensiDemo '!M21 -> 7278118 | F10: =D10-B10 -> -10 | G10: =E10-C10 -> -20871882 | H10: =D10/B10 -> 0.44444444 | I10: =E10/C10 -> 0.25854771 | J10: =IF(H10>=100%,"Hijau",IF(H10>=70%,"Kuning",IF(H10>=50%,"Merah","Hitam"))) -> Hitam | K10: =IF(I10>=100%,"Hijau",IF(I10>=70%,"Kuning",IF(I10>=50%,"Merah","Hitam"))) -> Hitam | L10: 4 | M10: ='PotensiDemo '!N5+'PotensiDemo '!N6+'PotensiDemo '!N7+'PotensiDemo '!N8 -> 5326048 | N10: 2 | O10: ='PotensiDemo '!N9+'PotensiDemo '!N10 -> 976000 | P10: 2 | Q10: ='PotensiDemo '!N11+'PotensiDemo '!N12 -> 976070
A11: Juli | F11: =D11-B11 -> 0 | G11: =E11-C11 -> 0 | H11: =D11/B11 -> #DIV/0! | I11: =E11/C11 -> #DIV/0! | J11: =IF(H11>=100%,"Hijau",IF(H11>=70%,"Kuning",IF(H11>=50%,"Merah","Hitam"))) -> #DIV/0! | K11: =IF(I11>=100%,"Hijau",IF(I11>=70%,"Kuning",IF(I11>=50%,"Merah","Hitam"))) -> #DIV/0!
A12: Agustus | F12: =D12-B12 -> 0 | G12: =E12-C12 -> 0 | H12: =D12/B12 -> #DIV/0! | I12: =E12/C12 -> #DIV/0! | J12: =IF(H12>=100%,"Hijau",IF(H12>=70%,"Kuning",IF(H12>=50%,"Merah","Hitam"))) -> #DIV/0! | K12: =IF(I12>=100%,"Hijau",IF(I12>=70%,"Kuning",IF(I12>=50%,"Merah","Hitam"))) -> #DIV/0!
A13: September | F13: =D13-B13 -> 0 | G13: =E13-C13 -> 0 | H13: =D13/B13 -> #DIV/0! | I13: =E13/C13 -> #DIV/0! | J13: =IF(H13>=100%,"Hijau",IF(H13>=70%,"Kuning",IF(H13>=50%,"Merah","Hitam"))) -> #DIV/0! | K13: =IF(I13>=100%,"Hijau",IF(I13>=70%,"Kuning",IF(I13>=50%,"Merah","Hitam"))) -> #DIV/0!
A14: Oktober | F14: =D14-B14 -> 0 | G14: =E14-C14 -> 0 | H14: =D14/B14 -> #DIV/0! | I14: =E14/C14 -> #DIV/0! | J14: =IF(H14>=100%,"Hijau",IF(H14>=70%,"Kuning",IF(H14>=50%,"Merah","Hitam"))) -> #DIV/0! | K14: =IF(I14>=100%,"Hijau",IF(I14>=70%,"Kuning",IF(I14>=50%,"Merah","Hitam"))) -> #DIV/0!
A15: November | F15: =D15-B15 -> 0 | G15: =E15-C15 -> 0 | H15: =D15/B15 -> #DIV/0! | I15: =E15/C15 -> #DIV/0! | J15: =IF(H15>=100%,"Hijau",IF(H15>=70%,"Kuning",IF(H15>=50%,"Merah","Hitam"))) -> #DIV/0! | K15: =IF(I15>=100%,"Hijau",IF(I15>=70%,"Kuning",IF(I15>=50%,"Merah","Hitam"))) -> #DIV/0!
A16: Desember | F16: =D16-B16 -> 0 | G16: =E16-C16 -> 0 | H16: =D16/B16 -> #DIV/0! | I16: =E16/C16 -> #DIV/0! | J16: =IF(H16>=100%,"Hijau",IF(H16>=70%,"Kuning",IF(H16>=50%,"Merah","Hitam"))) -> #DIV/0! | K16: =IF(I16>=100%,"Hijau",IF(I16>=70%,"Kuning",IF(I16>=50%,"Merah","Hitam"))) -> #DIV/0!
A17: Total Target | B17: =SUM(B5:B16) -> 144 | C17: =SUM(C5:C16) -> 170828888 | D17: =SUM(D5:D16) -> 45 | E17: =SUM(E5:E16) -> 61387747 | F17: =D17-B17 -> -99 | G17: =C17-E17 -> 109441141 | H17: =D17/B17 -> 0.3125 | I17: =E17/C17 -> 0.35935226 | J17: =IF(H17>=100%,"Hijau",IF(H17>=70%,"Kuning",IF(H17>=50%,"Merah","Hitam"))) -> Hitam | K17: =IF(I17>=100%,"Hijau",IF(I17>=70%,"Kuning",IF(I17>=50%,"Merah","Hitam"))) -> Hitam
A18: Rata- rata Omset | D18: =D17/5 -> 9 | E18: =E17/5 -> 12277549
A19: Catatan Penting:
A20: Warna Hijau Tercapai 100%
A21: Warna Kuning Posisi Aman dgn min. capai 70%
A22: Warna Merah Posisi tidak aman dgn minimal capai 50% dr Target
A23: Warna Hitam Posisi Finalti dengan capai dibawah 30% dari Target
A25: TEAM HUNTER
A26: Target Juni 2026
A27: Pic Team Hunter | B27: Target User | C27: Target Nominal | D27: Realisasi | F27: Kekurangan
D28: User | E28: Omset | F28: User | G28: Omset
A29: Lidya | B29: =D42 -> 11 | C29: =F42 -> 14362000 | D29: 2 | E29: 2124086 | F29: =B29-D29 -> 9 | G29: =C29-E29 -> 12237914
A30: Total Pencapaian | B30: =sum(B29) -> 11 | C30: =sum(C29) -> 14362000 | D30: =sum(D29) -> 2 | E30: =sum(E29) -> 2124086 | F30: =sum(F29) -> 9 | G30: =sum(G29) -> 12237914
A31: Total Kekurangan [%] | B31: =B30/B30 -> 1 | C31: =C30/C30 -> 1 | D31: =D30/B30 -> 0.18181818 | E31: =E30/C30 -> 0.14789625 | F31: =F30/B30 -> 0.81818182 | G31: =G30/C30 -> 0.85210375
A33: Pic Team Hunter | B33: New Member | C33: Paket Langganan | D33: User | F33: Penjualan
D34: Target | E34: Realisasi | F34: Target | G34: Realisasi
B35: Basic 9 | C35: 702000 | D35: 1 | E35: 1 | F35: =C35*D35 -> 702000 | G35: =E35*C35 -> 702000
B36: Basic 12 | C36: 858000 | D36: 2 | E36: 3 | F36: =C36*D36 -> 1716000 | G36: =E36*C36 -> 2574000
B37: Business 9 | C37: 998000 | D37: 1 | E37: 0 | F37: =C37*D37 -> 998000 | G37: =E37*C37 -> 0
B38: Business 12 | C38: 1298000 | D38: 3 | E38: 0 | F38: =C38*D38 -> 3894000 | G38: =E38*C38 -> 0
B39: Pro 12 | C39: 1688000 | D39: 2 | E39: 1 | F39: =C39*D39 -> 3376000 | G39: =E39*C39 -> 1688000
B40: Jagoan Business | C40: 1598000 | D40: 1 | E40: 0 | F40: =C40*D40 -> 1598000 | G40: =E40*C40 -> 0
B41: Jagoan Pro | C41: 2078000 | D41: 1 | E41: 1 | F41: =C41*D41 -> 2078000 | G41: =E41*C41 -> 2078000
A42: Total Penjualan | D42: =sum(D35:D41) -> 11 | E42: =sum(E35:E41) -> 6 | F42: =sum(F35:F41) -> 14362000 | G42: =sum(G35:G41) -> 7042000
A43: Kekurangan | D43: =D42-E42 -> 5 | F43: =F42-G42 -> 7320000
...

Sheet JOBDESK 
A1: Ceklist daily jobdesk team sales
A2: PBGC 2 Lidya Marpaung
A3: Divisi : Business Growth Consultant
A4: No | B4: JobDesk | C4: Target | D4: Validasi (Businesse Control)
E5: 46176 | F5: 46177 | G5: 46178 | H5: 46181 | I5: 46182 | J5: 46183 | K5: 46184 | L5: 46185 | M5: 46188 | N5: 46190 | O5: 46191 | P5: 46192 | Q5: 46195 | R5: 46196 | S5: 46197 | T5: 46198 | U5: 46199 | V5: 46202 | W5: 46203
A6: 1 | B6: Follow up data kelolaan | C6: 50 | D6: FALSE | E6: TRUE | F6: TRUE | G6: FALSE | H6: TRUE | I6: TRUE | J6: TRUE | K6: TRUE | L6: TRUE | M6: TRUE | N6: TRUE | O6: FALSE | P6: FALSE | Q6: FALSE | R6: FALSE | S6: FALSE | T6: FALSE | U6: FALSE | V6: FALSE | W6: FALSE
A7: 2 | B7: Follow up data nasabah new download - Project list & new outlet | C7: 10 | D7: FALSE | E7: TRUE | F7: TRUE | G7: FALSE | H7: TRUE | I7: TRUE | J7: TRUE | K7: TRUE | L7: TRUE | M7: TRUE | N7: TRUE | O7: FALSE | P7: FALSE | Q7: FALSE | R7: FALSE | S7: FALSE | T7: FALSE | U7: FALSE | V7: FALSE | W7: FALSE
A8: 3 | B8: Follow up data nasabah potensi | C8: 5 | D8: FALSE | E8: TRUE | F8: TRUE | G8: FALSE | H8: TRUE | I8: TRUE | J8: TRUE | K8: TRUE | L8: TRUE | M8: TRUE | N8: TRUE | O8: FALSE | P8: FALSE | Q8: FALSE | R8: FALSE | S8: FALSE | T8: FALSE | U8: FALSE | V8: FALSE | W8: FALSE
A9: 4 | B9: Follow up data nasabah jatuh tempo | C9: 20 | D9: FALSE | E9: TRUE | F9: TRUE | G9: FALSE | H9: TRUE | I9: TRUE | J9: TRUE | K9: TRUE | L9: TRUE | M9: TRUE | N9: TRUE | O9: FALSE | P9: FALSE | Q9: FALSE | R9: FALSE | S9: FALSE | T9: FALSE | U9: FALSE | V9: FALSE | W9: FALSE
A10: 5 | B10: Follow up mitra kelolaan & akuisisi new mitra | C10: 5 | D10: FALSE | E10: TRUE | F10: FALSE | G10: FALSE | H10: TRUE | I10: FALSE | J10: FALSE | K10: TRUE | L10: FALSE | M10: FALSE | N10: FALSE | O10: FALSE | P10: FALSE | Q10: FALSE | R10: FALSE | S10: FALSE | T10: FALSE | U10: FALSE | V10: FALSE | W10: FALSE
A11: 6 | B11: Posting konten di whatsapp | C11: - | D11: FALSE | E11: TRUE | F11: TRUE | G11: FALSE | H11: TRUE | I11: TRUE | J11: TRUE | K11: TRUE | L11: TRUE | M11: TRUE | N11: TRUE | O11: TRUE | P11: FALSE | Q11: FALSE | R11: FALSE | S11: FALSE | T11: FALSE | U11: FALSE | V11: FALSE | W11: FALSE
A12: 7 | B12: Posting konten di Instagram, Tiktok dan Facebook | C12: - | D12: FALSE | E12: TRUE | F12: TRUE | G12: FALSE | H12: FALSE | I12: TRUE | J12: TRUE | K12: FALSE | L12: TRUE | M12: TRUE | N12: TRUE | O12: TRUE | P12: FALSE | Q12: FALSE | R12: FALSE | S12: FALSE | T12: FALSE | U12: FALSE | V12: FALSE | W12: FALSE
A13: 8 | B13: Follow up nasabah yang belum memberikan rating & logo laundry | C13: 5 | D13: FALSE | E13: TRUE | F13: TRUE | G13: FALSE | H13: TRUE | I13: FALSE | J13: FALSE | K13: TRUE | L13: FALSE | M13: FALSE | N13: TRUE | O13: FALSE | P13: FALSE | Q13: FALSE | R13: FALSE | S13: FALSE | T13: FALSE | U13: FALSE | V13: FALSE | W13: FALSE
A14: 9 | B14: Daily report follow up data kelolaan (WA Group) | C14: - | D14: FALSE | E14: FALSE | F14: FALSE | G14: FALSE | H14: FALSE | I14: FALSE | J14: FALSE | K14: FALSE | L14: FALSE | M14: FALSE | N14: FALSE | O14: FALSE | P14: FALSE | Q14: FALSE | R14: FALSE | S14: FALSE | T14: FALSE | U14: FALSE | V14: FALSE | W14: FALSE
A15: 10 | B15: Daily report follow up data jatuh tempo(WA Group) | C15: - | D15: FALSE | E15: TRUE | F15: TRUE | G15: FALSE | H15: TRUE | I15: TRUE | J15: FALSE | K15: TRUE | L15: TRUE | M15: TRUE | N15: TRUE | O15: FALSE | P15: FALSE | Q15: FALSE | R15: FALSE | S15: FALSE | T15: FALSE | U15: FALSE | V15: FALSE | W15: FALSE
A16: 11 | B16: Pengisian data kelolaan | C16: - | D16: FALSE | E16: TRUE | F16: TRUE | G16: FALSE | H16: TRUE | I16: TRUE | J16: TRUE | K16: TRUE | L16: TRUE | M16: TRUE | N16: TRUE | O16: FALSE | P16: FALSE | Q16: FALSE | R16: FALSE | S16: FALSE | T16: FALSE | U16: FALSE | V16: FALSE | W16: FALSE

Sheet K.-Lidya
A1: PT PIPOSMART DIGITAL INDONESIA
A2: Data Kelolaan Nasabah
A3: Pengertian Scorsing = 0. (Tidak Tertarik) 1. (New Download) 2. (Potensial) 3. (Berlangganan)
A4: Total Fu | B4: Tanggal Fu | C4: Tahun | D4: Bulan | E4: No | F4: Tanggal Dibagikan (Data) | G4: Status Akun | H4: Kode Baris | I4: Kode Owner | J4: Nama Owner | K4: Project/Brand | L4: Outlet | M4: No. HP Owner | N4: No. HP Outlet | O4: Create Date Project | P4: Expired Date | Q4: Total Transaksi | R4: Scor | S4: Call | T4: Chat | U4: Validitas | V4: Remaks | W4: Sumber Nasabah | X4: Finalisasi (Closing) | Y4: Nominal | Z4: Noted | AA4: Audit
A5: =COUNTIF('Call & Chat-Lidya'!$I$4:$I$2433,I5) -> 5 | B5: 46188 | C5: 2026 | D5: Juni | E5: 6 | F5: 46175 | G5: AKun Baru | H5: 11313 | I5: 18907 | J5: Bubble's~2 | K5: Bubble 2 | L5: Bubble 2 | M5: 085240267611 | O5: 46175 | P5: 46189 | Q5: 4 | R5: 3 | S5: NO CALL | T5: PROSPECT | U5: VALID | V5: (3) Berlangganan | X5: Basic | Y5: 858000 | Z5: reminder untuk perpanjangan berlanganan dan penjelasan promo berlangganan dan nasabah sudah melakukan pembayaran dan sudah aktivasi membership
A6: =COUNTIF('Call & Chat-Lidya'!$I$4:$I$2433,I6) -> 2 | B6: 46185 | C6: 2026 | D6: Juni | E6: 7 | F6: 46175 | G6: AKun Baru | H6: 10828 | I6: 18070 | J6: Ramlah 15 | K6: IRA LAUNDRY | L6: IRA LAUNDRY | M6: 085252472966 | N6: 082252472966 | O6: 46090 | P6: 46104 | Q6: 0 | R6: 0 | S6: CONTACTED | T6: NO CHAT | U6: INVALID | V6: (0) Tidak Merespon | Z6: Nomor tidak terhubung dengan wa
A7: =COUNTIF('Call & Chat-Lidya'!$I$4:$I$2433,I7) -> 2 | B7: 46185 | C7: 2026 | D7: Juni | E7: 8 | F7: 46175 | G7: AKun Baru | H7: 10850 | I7: 18104 | J7: Sofiah ichwani | K7: Azzahra laundry | L7: Azzahra laundry | M7: 081269923421 | N7: 081269923421 | O7: 46095 | P7: 46109 | Q7: 4 | R7: 1 | S7: CONTACTED | T7: DELIVERED | U7: VALID | V7: (0) Tidak Merespon
A8: =COUNTIF('Call & Chat-Lidya'!$I$4:$I$2433,I8) -> 1 | B8: 46175 | C8: 2026 | D8: Juni | E8: 9 | F8: 46175 | G8: AKun Baru | H8: 10854 | I8: 18108 | J8: Amanda Artha | K8: Laundry | L8: Laundry | M8: 089518979800 | N8: 08522236974 | O8: 46097 | R8: 0 | Z8: Akun tim karna sudah aktivasi membership tanpa ada bukti pembayaran dari transfer
A9: =COUNTIF('Call & Chat-Lidya'!$I$4:$I$2433,I9) -> 2 | B9: 46185 | C9: 2026 | D9: Juni | E9: 10 | F9: 46175 | G9: AKun Baru | H9: 10860 | I9: 18117 | J9: Aswar Anas | K9: Laundry.KU | L9: Laundry.KU | M9: 082291364112 | N9: 082291364112 | O9: 46098 | P9: 46112 | Q9: 0 | R9: 1 | S9: CONTACTED | T9: DELIVERED | U9: VALID | V9: (0) Tidak Merespon
A10: =COUNTIF('Call & Chat-Lidya'!$I$4:$I$2433,I10) -> 2 | B10: 46185 | C10: 2026 | D10: Juni | E10: 11 | F10: 46175 | G10: AKun Baru | H10: 10865 | I10: 18124 | J10: Slastia | K10: LAUNDRY 99 KARAWANG | L10: LAUNDRY 99 KARAWANG | M10: 089630415505 | N10: 089630415505 | O10: 46099 | P10: 46113 | Q10: 0 | R10: 1 | S10: CONTACTED | T10: DELIVERED | U10: VALID | V10: (0) Tidak Merespon
A11: =COUNTIF('Call & Chat-Lidya'!$I$4:$I$2433,I11) -> 2 | B11: 46185 | C11: 2026 | D11: Juni | E11: 12 | F11: 46175 | G11: AKun Baru | H11: 10867 | I11: 18126 | J11: Ica Vera | K11: terima uang | L11: terima uang | M11: 082128887889 | N11: 082128887889 | O11: 46100 | P11: 46114 | Q11: 0 | R11: 0 | S11: CONTACTED | T11: SENT | U11: INVALID | V11: (0) Tidak Merespon
A12: =COUNTIF('Call & Chat-Lidya'!$I$4:$I$2433,I12) -> 2 | B12: 46185 | C12: 2026 | D12: Juni | E12: 13 | F12: 46175 | G12: AKun Baru | H12: 10871 | I12: 18132 | J12: ori zapp | K12: Geubrina londry | L12: Geubrina londry | M12: 085136305406 | N12: 085136305406 | O12: 46102 | P12: 46116 | Q12: 2 | R12: 1 | S12: CONTACTED | T12: DELIVERED | U12: VALID | V12: (0) Tidak Merespon
A13: =COUNTIF('Call & Chat-Lidya'!$I$4:$I$2433,I13) -> 2 | B13: 46185 | C13: 2026 | D13: Juni | E13: 14 | F13: 46175 | G13: AKun Baru | H13: 10876 | I13: 18140 | J13: Batapas Laundry Express | K13: Batapas Laundry Express | L13: Batapas Laundry Express | M13: 085960224716 | N13: 085960224716 | O13: 46104 | P13: 46118 | Q13: 1 | R13: 1 | S13: CONTACTED | T13: DELIVERED | U13: VALID | V13: (0) Tidak Merespon
A14: =COUNTIF('Call & Chat-Lidya'!$I$4:$I$2433,I14) -> 2 | B14: 46185 | C14: 2026 | D14: Juni | E14: 15 | F14: 46175 | G14: AKun Baru | H14: 10880 | I14: 18147 | J14: Moja Wash BSD | K14: mo | L14: mo | M14: 087887700094 | N14: 087887700094 | O14: 46106 | P14: 46120 | Q14: 0 | R14: 1 | S14: CONNECTED | T14: DELIVERED | U14: VALID | V14: (0) Tidak Merespon
A15: =COUNTIF('Call & Chat-Lidya'!$I$4:$I$2433,I15) -> 4 | B15: 46185 | C15: 2026 | D15: Juni | E15: 16 | F15: 46175 | G15: AKun Baru | H15: 10882 | I15: 18150 | J15: Abimanyu | K15: Laundry Yook | L15: Laundry Yook | M15: 0882007927333 | N15: 0882007927333 | O15: 46106 | P15: 46120 | Q15: 55 | R15: 1 | S15: CONTACTED | T15: DELIVERED | U15: VALID | V15: (0) Tidak Merespon
A16: =COUNTIF('Call & Chat-Lidya'!$I$4:$I$2433,I16) -> 5 | B16: 46190 | C16: 2026 | D16: Juni | E16: 17 | F16: 46175 | G16: AKun Baru | H16: 11315 | I16: 18911 | J16: sigit purnomo | K16: Laundry | L16: Mamas Laundry | M16: 081289304588 | O16: 46175 | P16: 46189 | Q16: 0 | R16: 1 | S16: CONNECTED | T16: DELIVERED | U16: VALID | V16: (0) Tidak Merespon
A17: =COUNTIF('Call & Chat-Lidya'!$I$4:$I$2433,I17) -> 3 | B17: 46190 | C17: 2026 | D17: Juni | E17: 18 | F17: 46175 | G17: AKun Baru | H17: 11316 | I17: 18912 | J17: Syariah Laundry | K17: Syariah Laundry | L17: Syariah Laundry | M17: 082181951816 | N17: 082181951816 | O17: 46175 | P17: 46189 | Q17: 0 | R17: 1 | S17: CONNECTED | T17: DELIVERED | U17: VALID | V17: (0) Data Employee dan Trial
A18: =COUNTIF('Call & Chat-Lidya'!$I$4:$I$2433,I18) -> 4 | B18: 46190 | C18: 2026 | D18: Juni | E18: 19 | F18: 46175 | G18: AKun Baru | H18: 11317 | I18: 18913 | J18: Elfira Yanti | K18: buk Yanti laundry | L18: buk Yanti laundry | M18: 082280298103 | N18: 082280298103 | O18: 46175 | P18: 46189 | Q18: 1 | R18: 1 | S18: CONNECTED | T18: UNINTEREST | U18: VALID | V18: (0) Data Employee dan Trial | Z18: Aplikasi piposmartnya tidak digunakan
A19: =COUNTIF('Call & Chat-Lidya'!$I$4:$I$2433,I19) -> 4 | B19: 46190 | C19: 2026 | D19: Juni | E19: 20 | F19: 46175 | G19: AKun Baru | H19: 11318 | I19: 18916 | J19: Yanti Fitria Sari | K19: JA londry | L19: JA londry | M19: 085283284078 | N19: 85283284078 | O19: 46175 | P19: 46189 | Q19: 0 | R19: 0 | S19: CONTACTED | T19: SENT | U19: INVALID | V19: (0) Nomor Diblokir
A20: =COUNTIF('Call & Chat-Lidya'!$I$4:$I$2433,I20) -> 4 | B20: 46185 | C20: 2026 | D20: Juni | E20: 21 | F20: 46176 | G20: AKun Baru | H20: 10882 | I20: 18150 | J20: Abimanyu | K20: WOW LAUNDRY | L20: Laundry Yook | M20: 0882007927333 | N20: 0882007927333 | O20: 46106 | P20: 46120 | Q20: 111 | R20: 1 | S20: CONTACTED | T20: DELIVERED | U20: VALID | V20: (0) Tidak Merespon
A21: =COUNTIF('Call & Chat-Lidya'!$I$4:$I$2433,I21) -> 2 | B21: 46185 | C21: 2026 | D21: Juni | E21: 22 | F21: 46176 | G21: AKun Baru | H21: 10886 | I21: 18155 | J21: Owner | K21: 24Laundry | L21: 24Laundry | M21: 081334428518 | N21: 085156239895 | O21: 46106 | P21: 46120 | Q21: 24 | R21: 1 | S21: CONTACTED | T21: DELIVERED | U21: VALID | V21: (0) Tidak Merespon
A22: =COUNTIF('Call & Chat-Lidya'!$I$4:$I$2433,I22) -> 2 | B22: 46185 | C22: 2026 | D22: Juni | E22: 23 | F22: 46176 | G22: AKun Baru | H22: 10890 | I22: 18163 | J22: Gusti Ayu Aris Widyantari | K22: Paradis Laundry | L22: Paradis Laundry | M22: 081239382543 | N22: 082266853437 | O22: 46107 | P22: 46121 | Q22: 0 | R22: 1 | S22: CONNECTED | T22: DELIVERED | U22: VALID | V22: (0) Tidak Merespon
A23: =COUNTIF('Call & Chat-Lidya'!$I$4:$I$2433,I23) -> 2 | B23: 46185 | C23: 2026 | D23: Juni | E23: 24 | F23: 46176 | G23: AKun Baru | H23: 10892 | I23: 18165 | J23: Nanda Aulia | K23: Ara Laundry | L23: Ara Laundry | M23: 085215899395 | N23: 085215899395 | O23: 46107 | P23: 46121 | Q23: 10 | R23: 1 | S23: CONTACTED | T23: DELIVERED | U23: VALID | V23: (0) Tidak Merespon
A24: =COUNTIF('Call & Chat-Lidya'!$I$4:$I$2433,I24) -> 1 | B24: 46176 | C24: 2026 | D24: Juni | E24: 25 | F24: 46176 | G24: AKun Baru | H24: 10900 | I24: 18176 | J24: Nurliah | K24: Agnifa Laundry | L24: Agnifa Laundry | M24: 081321973546 | N24: 08998975443 | O24: 46109 | P24: 46123 | Q24: 2 | R24: 1 | S24: ENGAGE | T24: DELIVERED | U24: VALID | V24: (0) Data Employee dan Trial | Z24: Konfirmasi penggunaan aplikasi dan call langsung dimatikan
A25: =COUNTIF('Call & Chat-Lidya'!$I$4:$I$2433,I25) -> 2 | B25: 46185 | C25: 2026 | D25: Juni | E25: 26 | F25: 46176 | G25: AKun Baru | H25: 10916 | I25: 18201 | J25: anindia | K25: Star Laundry 2 | L25: Star Laundry 2 | M25: 085820557960 | N25: 085820557960 | O25: 46112 | P25: 46126 | Q25: 0 | R25: 1 | S25: ENGAGE | T25: DELIVERED | U25: VALID | V25: (0) Data Employee dan Trial | Z25: Konfirmasi penggunaan aplikasi piposmart dan call langsung dimatikan
A26: =COUNTIF('Call & Chat-Lidya'!$I$4:$I$2433,I26) -> 2 | B26: 46185 | C26: 2026 | D26: Juni | E26: 27 | F26: 46176 | G26: AKun Baru | H26: 10920 | I26: 18214 | J26: Arkan laundry | K26: Arkan Laundry | L26: Arkan Laundry | M26: 083150654324 | N26: 083150654324 | O26: 46114 | P26: 46128 | Q26: 8 | R26: 1 | S26: ENGAGE | T26: DELIVERED | U26: VALID | V26: (0) Data Employee dan Trial | Z26: Konfirmasi penggunaan aplikasi piposmart dan call langsung dimatikan
A27: =COUNTIF('Call & Chat-Lidya'!$I$4:$I$2433,I27) -> 2 | B27: 46185 | C27: 2026 | D27: Juni | E27: 28 | F27: 46176 | G27: AKun Baru | H27: 10924 | I27: 18220 | J27: Kanza Aulia | K27: Jastrika | L27: Jastrika | M27: 0895342756135 | N27: 0895342756135 | O27: 46114 | P27: 46128 | Q27: 1 | R27: 1 | S27: CONNECTED | T27: DELIVERED | U27: VALID | V27: (0) Tidak Merespon
A28: =COUNTIF('Call & Chat-Lidya'!$I$4:$I$2433,I28) -> 2 | B28: 46185 | C28: 2026 | D28: Juni | E28: 29 | F28: 46176 | G28: AKun Baru | H28: 10932 | I28: 18235 | J28: Arwina | K28: Win Laundry | L28: Win Laundry | M28: 088245670913 | N28: 088245670913 | O28: 46116 | P28: 46130 | Q28: 0 | R28: 1 | S28: CONTACTED | T28: DELIVERED | U28: VALID | V28: (0) Tidak Merespon
A29: =COUNTIF('Call & Chat-Lidya'!$I$4:$I$2433,I29) -> 2 | B29: 46185 | C29: 2026 | D29: Juni | E29: 30 | F29: 46176 | G29: AKun Baru | H29: 10935 | I29: 18239 | J29: feny setiani | K29: Cleanwash Laundry | L29: Cleanwash Laundry | M29: 0895372027589 | O29: 46117 | P29: 46131 | Q29: 0 | R29: 1 | S29: CONNECTED | T29: DELIVERED | U29: VALID | V29: (0) Tidak Merespon
A30: =COUNTIF('Call & Chat-Lidya'!$I$4:$I$2433,I30) -> 2 | B30: 46185 | C30: 2026 | D30: Juni | E30: 31 | F30: 46176 | G30: AKun Baru | H30: 10959 | I30: 18286 | J30: Ariana | K30: Anah laundry | L30: Anah laundry | M30: 081220754792 | N30: 081220754792 | O30: 46120 | P30: 46134 | Q30: 1 | R30: 1 | S30: CONTACTED | T30: DELIVERED | U30: VALID | V30: (0) Tidak Merespon
A31: =COUNTIF('Call & Chat-Lidya'!$I$4:$I$2433,I31) -> 2 | B31: 46185 | C31: 2026 | D31: Juni | E31: 32 | F31: 46176 | G31: AKun Baru | H31: 10977 | I31: 18313 | J31: mamaJO | K31: mamaJO LAUNDRY | L31: mamaJO LAUNDRY | M31: 082374564878 | O31: 46123 | P31: 46137 | Q31: 5 | R31: 1 | S31: CONTACTED | T31: DELIVERED | U31: VALID | V31: (0) Tidak Merespon
A32: =COUNTIF('Call & Chat-Lidya'!$I$4:$I$2433,I32) -> 2 | B32: 46185 | C32: 2026 | D32: Juni | E32: 33 | F32: 46176 | G32: AKun Baru | H32: 10992 | I32: 18346 | J32: Mariana | K32: Sint Loundry | L32: Sint Loundry | M32: 082180157705 | N32: 082180157705 | O32: 46125 | P32: 46139 | Q32: 0 | R32: 1 | S32: CONTACTED | T32: DELIVERED | U32: VALID | V32: (0) Tidak Merespon
A33: =COUNTIF('Call & Chat-Lidya'!$I$4:$I$2433,I33) -> 2 | B33: 46185 | C33: 2026 | D33: Juni | E33: 34 | F33: 46176 | G33: AKun Baru | H33: 10996 | I33: 18351 | J33: zuria lidiana | K33: Myesha laundry | L33: Myesha laundry | M33: 081361415817 | N33: 085369967799 | O33: 46126 | P33: 46140 | Q33: 3 | R33: 1 | S33: ENGAGE | T33: DELIVERED | U33: VALID | V33: (0) Data Employee dan Trial | Z33: Konfirmasi penggunaan aplikasi piposmart dan call langsung dimatikan
A34: =COUNTIF('Call & Chat-Lidya'!$I$4:$I$2433,I34) -> 4 | B34: 46188 | C34: 2026 | D34: Juni | E34: 35 | F34: 46176 | G34: AKun Baru | H34: 11320 | I34: 18919 | J34: Risnul Syafrizal | K34: Skuyy Laundry | L34: Skuyy Laundry | M34: 082170927742 | N34: 5169170881 | O34: 46176 | P34: 46190 | Q34: 110 | R34: 3 | S34: PROSPECT | T34: DELIVERED | U34: VALID | V34: (3) Berlangganan | W34: Playstore | X34: Business | Y34: 118070 | Z34: Sejauh ini aplikasi piposmartnya belum ada kendala dan rencana berlangganan hari dengan paket 1 bulan bisnis dan akan dihubungi kembali
A35: =COUNTIF('Call & Chat-Lidya'!$I$4:$I$2433,I35) -> 2 | B35: 46185 | C35: 2026 | D35: Juni | E35: 36 | F35: 46178 | G35: AKun Baru | H35: 11001 | I35: 18359 | J35: Clink Mojokerto | K35: klemiz | L35: klemiz | M35: 085633335268 | N35: 085666326984 | O35: 46127 | P35: 46141 | Q35: 0 | R35: 1 | S35: CONTACTED | T35: NO CHAT | U35: INVALID | V35: (0) Tidak Merespon | Z35: Nomor tidak terhubung dengan wa
A36: =COUNTIF('Call & Chat-Lidya'!$I$4:$I$2433,I36) -> 2 | B36: 46185 | C36: 2026 | D36: Juni | E36: 37 | F36: 46178 | G36: AKun Baru | H36: 11007 | I36: 18373 | J36: dehazby dehazby | K36: CK Lona Laundry | L36: CK Lona Laundry | M36: 088216036140 | N36: 088216036140 | O36: 46128 | P36: 46142 | Q36: 2 | R36: 1 | S36: CONNECTED | T36: DELIVERED | U36: VALID | V36: (0) Tidak Merespon
A37: =COUNTIF('Call & Chat-Lidya'!$I$4:$I$2433,I37) -> 2 | B37: 46185 | C37: 2026 | D37: Juni | E37: 38 | F37: 46178 | G37: AKun Baru | H37: 11017 | I37: 18390 | J37: Wahyuni Ida ningsih | K37: Mawar | L37: Mawar | M37: 08991857388 | O37: 46129 | P37: 46143 | Q37: 6 | R37: 1 | S37: CONNECTED | T37: DELIVERED | U37: VALID | V37: (0) Tidak Merespon
A38: =COUNTIF('Call & Chat-Lidya'!$I$4:$I$2433,I38) -> 1 | B38: 46181 | C38: 2026 | D38: Juni | E38: 39 | F38: 46178 | G38: AKun Baru | H38: 11033 | I38: 18437 | J38: Dwi Wullan | K38: Omah Laundry | L38: Omah Laundry | M38: 087743123571 | N38: 087743123571 | O38: 46133 | P38: 46147 | Q38: 0 | R38: 1 | S38: ENGAGE | T38: DELIVERED | U38: VALID | V38: (0) Data Employee dan Trial | Z38: Konfirmasi penggunaan aplikasi piposmart dan call langsung dimatikan
A39: =COUNTIF('Call & Chat-Lidya'!$I$4:$I$2433,I39) -> 2 | B39: 46185 | C39: 2026 | D39: Juni | E39: 40 | F39: 46178 | G39: AKun Baru | H39: 11035 | I39: 18440 | J39: Ade Nandy Wirya | K39: Hoky Laundry Jambi | L39: Hoky Laundry Jambi | M39: 081272706900 | N39: 081272706900 | O39: 46133 | P39: 46147 | Q39: 0 | R39: 1 | S39: CONTACTED | T39: DELIVERED | U39: VALID | V39: (0) Tidak Merespon
A40: =COUNTIF('Call & Chat-Lidya'!$I$4:$I$2433,I40) -> 2 | B40: 46185 | C40: 2026 | D40: Juni | E40: 41 | F40: 46178 | G40: AKun Baru | H40: 11037 | I40: 18443 | J40: Dewi 5198 | K40: Rumah loundry | L40: Rumah loundry | N40: 085373405848 | O40: 46134 | P40: 46148 | Q40: 0 | R40: 1 | S40: CONTACTED | T40: DELIVERED | U40: VALID | V40: (0) Tidak Merespon
...

Sheet Call & Chat-Lidya
A1: PT PIPOSMART DIGITAL INDONESIA
A2: Data Kelolaan Nasabah
A3: Pengertian Scorsing = 0. (Tidak Tertarik) 1. (New Download) 2. (Potensial) 3. (Berlangganan)
A4: Total FU | B4: Tanggal FU | C4: Tahun | D4: Bulan | E4: No | F4: Tanggal Dibagikan (Data) | G4: Status Akun | H4: Kode Baris | I4: Kode Owner | J4: Nama Owner | K4: Project/Brand | L4: Outlet | M4: No. HP Owner | N4: No. HP Outlet | O4: Create Date Project | P4: Expired Date | Q4: Total Transaksi | R4: Scor | S4: Call | T4: Chat | U4: Validitas | V4: Remaks | W4: Sumber Nasabah | X4: Finalisasi (Closing) | Y4: Nominal | Z4: Noted | AA4: Audit
B5: 46098 | C5: 2026 | D5: Maret | E5: 1 | F5: 46097 | H5: 10853 | I5: 18107 | J5: rayakaundry | K5: laundry | L5: laundry | M5: 083895556893 | N5: 083895556893 | O5: 46097 | P5: 46111 | Q5: 0 | R5: 1 | S5: NO CALL | T5: DELIVERED | U5: VALID | V5: (0) Tidak Merespon
A6: =COUNTIF('Call & Chat-Lidya'!$I$4:$I$2391,I6) -> 5 | B6: 46190 | C6: 2026 | D6: Juni | E6: 17 | F6: 46175 | G6: AKun Baru | H6: 11315 | I6: 18911 | J6: sigit purnomo | K6: Laundry | L6: Mamas Laundry | M6: 081289304588 | O6: 46175 | P6: 46189 | Q6: 0 | R6: 1 | S6: CONNECTED | T6: DELIVERED | U6: VALID | V6: (0) Tidak Merespon
A7: =COUNTIF('Call & Chat-Lidya'!$I$4:$I$2391,I7) -> 3 | B7: 46190 | C7: 2026 | D7: Juni | E7: 18 | F7: 46175 | G7: AKun Baru | H7: 11316 | I7: 18912 | J7: Syariah Laundry | K7: Syariah Laundry | L7: Syariah Laundry | M7: 082181951816 | N7: 082181951816 | O7: 46175 | P7: 46189 | Q7: 0 | R7: 1 | S7: CONNECTED | T7: DELIVERED | U7: VALID | V7: (0) Data Employee dan Trial
A8: =COUNTIF('Call & Chat-Lidya'!$I$4:$I$2391,I8) -> 4 | B8: 46190 | C8: 2026 | D8: Juni | E8: 19 | F8: 46175 | G8: AKun Baru | H8: 11317 | I8: 18913 | J8: Elfira Yanti | K8: buk Yanti laundry | L8: buk Yanti laundry | M8: 082280298103 | N8: 082280298103 | O8: 46175 | P8: 46189 | Q8: 1 | R8: 1 | S8: CONNECTED | T8: UNINTEREST | U8: VALID | V8: (0) Data Employee dan Trial | Z8: Aplikasi piposmartnya tidak digunakan
A9: =COUNTIF('Call & Chat-Lidya'!$I$4:$I$2391,I9) -> 4 | B9: 46190 | C9: 2026 | D9: Juni | E9: 20 | F9: 46175 | G9: AKun Baru | H9: 11318 | I9: 18916 | J9: Yanti Fitria Sari | K9: JA londry | L9: JA londry | M9: 085283284078 | N9: 85283284078 | O9: 46175 | P9: 46189 | Q9: 0 | R9: 0 | S9: CONTACTED | T9: SENT | U9: INVALID | V9: (0) Nomor Diblokir
A10: =COUNTIF('Call & Chat-Lidya'!$I$4:$I$2391,I10) -> 8 | B10: 46190 | C10: 2026 | D10: Juni | E10: 52 | F10: 46178 | G10: AKun Baru | H10: 11324 | I10: 18926 | J10: Tawakkal | K10: New Malomo Laundry | L10: New Malomo Laundry 01 | M10: 082333222543 | N10: 082333222543 | O10: 46177 | P10: 46191 | Q10: 6 | R10: 2 | S10: CONNECTED | T10: DELIVERED | U10: VALID | V10: (2) Trial, Demo, Interaktif | W10: Playstore
A11: =COUNTIF('Call & Chat-Lidya'!$I$4:$I$2391,I11) -> 2 | B11: 46190 | C11: 2026 | D11: Juni | E11: 53 | F11: 46178 | G11: AKun Baru | H11: 11326 | I11: 18930 | J11: rayyan | K11: rayyan laundry | L11: rayyan laundry | M11: 0895329286867 | N11: 082375740626 | O11: 46177 | P11: 46191 | Q11: 0 | R11: 1 | S11: ENGAGE | T11: DELIVERED | U11: VALID | V11: (0) Data Employee dan Trial | Z11: Konfirmasi penggunaan aplikasi piposmart dan call langsung dimatikan
A12: hv | B12: 46190 | C12: 2026 | D12: Juni | E12: 54 | F12: 46178 | G12: AKun Baru | H12: 11327 | I12: 18931 | J12: Dian Maulidini | K12: Yusuf Laundry | L12: Yusuf Laundry | M12: 081398606092 | N12: 081398606092 | O12: 46177 | P12: 46191 | Q12: 7 | R12: 2 | S12: INTEREST | T12: DELIVERED | U12: VALID | V12: (0) Data Karyawan dan Trial | W12: Facebook | Z12: Usaha laundry jalan 4 tahun dan masih menggunakan nota manual dan penjelasan sistem berlangganan dan paket promo berlangganan. Untuk berlangganan akan di diskusikan dulu dengan suaminya. Aplikasi tidak ada kendala dan mudah digunakan dan rencana penggunaan dia wal bulan juli dan reminder berlangganan tanggal 29 Juni
A13: =COUNTIF('Call & Chat-Lidya'!$I$4:$I$2391,I13) -> 8 | B13: 46190 | C13: 2026 | D13: Juni | E13: 52 | F13: 46178 | G13: AKun Baru | H13: 11324 | I13: 18926 | J13: Tawakkal | K13: New Malomo Laundry | L13: New Malomo Laundry | M13: 082333222543 | N13: 082333222543 | O13: 46177 | P13: 46191 | Q13: 6 | R13: 2 | S13: CONNECTED | T13: DELIVERED | U13: VALID | V13: (2) Trial, Demo, Interaktif | W13: Playstore
A14: =COUNTIF('Call & Chat-Lidya'!$I$4:$I$2391,I14) -> 4 | B14: 46190 | C14: 2026 | D14: Juni | E14: 56 | F14: 46178 | G14: AKun Baru | H14: 11331 | I14: 18938 | J14: Assalam Laundry | K14: Assalam Laundry | L14: Assalam Laundry | M14: 085602291180 | N14: 085602291180 | O14: 46178 | P14: 46192 | Q14: 0 | R14: 1 | S14: ENGAGE | T14: DELIVERED | U14: VALID | V14: (0) Data Employee dan Trial | Z14: Konfirmasi penggunaan aplikasi piposmart dan call langsung dimatikan
A15: =COUNTIF('Call & Chat-Lidya'!$I$4:$I$2391,I15) -> 4 | B15: 46190 | C15: 2026 | D15: Juni | E15: 58 | F15: 46179 | G15: AKun Baru | H15: 11334 | I15: 18946 | J15: moxie wash | K15: moxiewash | L15: moxiewash | M15: 0811868493 | N15: 08139999235 | O15: 46179 | P15: 46193 | Q15: 0 | R15: 0 | S15: NO CALL | T15: UNINTEREST | U15: VALID | V15: (0) Data Employee dan Trial | Z15: Aplikasi tidak digunakan dan tidak ada kendala karna kemarin hanya coba". Jika perlu nasabahnya yang akan menghubungi kembali
A16: =COUNTIF('Call & Chat-Lidya'!$I$4:$I$2391,I16) -> 4 | B16: 46190 | C16: 2026 | D16: Juni | E16: 60 | F16: 46181 | G16: Outlet Baru | H16: 15536 | I16: 15510 | J16: Amanda | K16: cuciqu laundry | L16: CICERI DROP POINT | M16: 087798951222 | N16: 087798951222 | O16: 46181 | P16: 45822 | Q16: 0 | R16: 2 | S16: NO CALL | T16: DELIVERED | U16: VALID | V16: (2) Trial, Demo, Interaktif | W16: Playstore
A17: =COUNTIF('Call & Chat-Lidya'!$I$4:$I$2391,I17) -> 6 | B17: 46190 | C17: 2026 | D17: Juni | E17: 61 | F17: 46181 | G17: AKun Baru | H17: 11338 | I17: 18954 | J17: Dewi Anggraini | K17: We Laundry | L17: We Laundry | M17: 08161896392 | N17: 08161896392 | O17: 46181 | P17: 46195 | Q17: 3 | R17: 2 | S17: CONNECTED | T17: INTEREST | U17: VALID | V17: (2) Trial, Demo, Interaktif | W17: Playstore
A18: =COUNTIF('Call & Chat-Lidya'!$I$4:$I$2391,I18) -> 4 | B18: 46190 | C18: 2026 | D18: Juni | E18: 62 | F18: 46181 | G18: AKun Baru | H18: 11342 | I18: 18963 | J18: Cyclops Laundry | K18: Cyclops Laundry | L18: Cyclops Laundry | M18: 08218812277 | N18: 08218812277 | O18: 46181 | P18: 46195 | Q18: 2 | R18: 1 | S18: ENGAGE | T18: DELIVERED | U18: VALID | V18: (0) Data Employee dan Trial | Z18: Konfirmasi penggunaan aplikasi piposmart dan call langsung dimatikan
A19: =COUNTIF('Call & Chat-Lidya'!$I$4:$I$2391,I19) -> 4 | B19: 46190 | C19: 2026 | D19: Juni | E19: 63 | F19: 46181 | G19: Referral Mitra | H19: 11343 | I19: 18964 | J19: BRI Link Vania Loundry | K19: Vannessa Laundry | L19: Vannessa Laundry | M19: 085715609873 | N19: 085715609873 | O19: 46181 | P19: 46195 | Q19: 0 | R19: 2 | S19: CONNECTED | T19: DELIVERED | U19: VALID | V19: (2) Trial, Demo, Interaktif | W19: Mitra
A20: =COUNTIF('Call & Chat-Lidya'!$I$4:$I$2391,I20) -> 5 | B20: 46190 | C20: 2026 | D20: Juni | E20: 64 | F20: 46181 | G20: AKun Baru | H20: 11344 | I20: 18965 | J20: Hertati Simanjuntak | K20: miss resik laundry | L20: miss resik laundry | M20: 081280167784 | N20: 085813991103 | O20: 46181 | P20: 46195 | Q20: 1 | R20: 2 | S20: NO CALL | T20: DELIVERED | U20: VALID | V20: (2) Trial, Demo, Interaktif | W20: Mitra
A21: =COUNTIF('Call & Chat-Lidya'!$I$4:$I$2391,I21) -> 2 | B21: 46190 | C21: 2026 | D21: Juni | E21: 71 | F21: 46182 | G21: AKun Baru | H21: 11100 | I21: 18540 | J21: Hanin Laundry | K21: Hanin laundry | L21: Hanin laundry | M21: 081370907324 | N21: 085212096130 | O21: 46142 | P21: 46156 | Q21: 0 | R21: 2 | S21: PROSPECT | T21: DELIVERED | U21: VALID | V21: (2) Trial, Demo, Interaktif | Z21: Penjelasan biaya berlangganan dan rencana berlangganan 12 plus 6 bulan Pro, Reminder berlangganan besok tanggal 18 Juni 2026
A22: =COUNTIF('Call & Chat-Lidya'!$I$4:$I$2391,I22) -> 3 | B22: 46190 | C22: 2026 | D22: Juni | E22: 73 | F22: 46182 | G22: AKun Baru | H22: 11350 | I22: 18975 | J22: Wawan Hermawan | K22: emaluna laundry | L22: emaluna laundry | M22: 082147293334 | N22: 082147293334 | O22: 46182 | P22: 46196 | Q22: 0 | R22: 1 | S22: NO CALL | T22: DELIVERED | U22: VALID | V22: (0) Data Employee dan Trial | Z22: Nasabah sudah instal kembali dan daftar akun yang baru
A23: =COUNTIF('Call & Chat-Lidya'!$I$4:$I$2391,I23) -> 2 | B23: 46190 | C23: 2026 | D23: Juni | E23: 74 | F23: 46183 | G23: AKun Baru | H23: 11354 | I23: 18981 | J23: Rosmawatihadiarjo77 | K23: Alfian Laundry | L23: Alfian Laundry | M23: 088294365107 | N23: 088294365107 | O23: 46183 | P23: 46197 | Q23: 0 | R23: 1 | S23: CONTACTED | T23: DELIVERED | U23: VALID | V23: (0) Tidak Merespon
A24: =COUNTIF('Call & Chat-Lidya'!$I$4:$I$2391,I24) -> 3 | B24: 46190 | C24: 2026 | D24: Juni | E24: 75 | F24: 46184 | G24: Outlet Baru | H24: 8303 | I24: 12986 | J24: KEVIN SEVEN's | K24: SEVEN's LAUNDRY | L24: SEVEN's LAUNDRY 2 | M24: 085724591167 | N24: 085724591167 | O24: 46184 | P24: 45525 | Q24: 0 | R24: 1 | S24: CONNECTED | T24: DELIVERED | U24: VALID | V24: (0) Tidak Merespon | W24: Playstore
A25: =COUNTIF('Call & Chat-Lidya'!$I$4:$I$2391,I25) -> 3 | B25: 46190 | C25: 2026 | D25: Juni | E25: 88 | F25: 46184 | G25: AKun Baru | H25: 11359 | I25: 18993 | J25: Liviaaja Dede | K25: Ayu Laundry 1 | L25: Ayu Laundry 1 | M25: 081977525901 | N25: 081547468365 | O25: 46184 | P25: 46198 | Q25: 2 | R25: 1 | S25: CONNECTED | T25: DELIVERED | U25: VALID | V25: (0) Tidak Merespon
A26: =COUNTIF('Call & Chat-Lidya'!$I$4:$I$2391,I26) -> 10 | B26: 46190 | C26: 2026 | D26: Juni | E26: 89 | F26: 46184 | G26: Outlet Baru | H26: 10315 | I26: 17147 | J26: Aulia Laundry_PP | K26: Aulia Laundry | L26: Laundry Aulia II | M26: 085336166676 | N26: 085336166676 | O26: 46184 | P26: 46020 | Q26: 0 | R26: 1 | S26: CONNECTED | T26: DELIVERED | U26: VALID | V26: (0) Tidak Merespon | X26: Business | Y26: 118000
A27: =COUNTIF('Call & Chat-Lidya'!$I$4:$I$2391,I27) -> 2 | B27: 46190 | C27: 2026 | D27: Juni | E27: 90 | F27: 46184 | G27: AKun Baru | H27: 11360 | I27: 18998 | J27: Melly susanti | K27: Melly Laundry | L27: Melly Laundry | M27: 085760462638 | N27: 085760462638 | O27: 46184 | P27: 46198 | Q27: 0 | R27: 1 | S27: CONTACTED | T27: DELIVERED | U27: VALID | V27: (0) Tidak Merespon
A28: =COUNTIF('Call & Chat-Lidya'!$I$4:$I$2391,I28) -> 2 | B28: 46190 | C28: 2026 | D28: Juni | E28: 91 | F28: 46185 | G28: AKun Baru | H28: 11361 | I28: 19001 | J28: Putra Firdamansyah | K28: CEMARA LAUNDRY | L28: CEMARA LAUNDRY | M28: 082213883618 | N28: 082213883618 | O28: 46185 | P28: 46199 | Q28: 0 | R28: 0 | S28: CONNECTED | T28: ENGAGE | U28: VALID | V28: (0) Nomor Diblokir | Z28: Kenapa nelpon" terus gak sopan dan aplikasi tidak jadi digunakan
A29: =COUNTIF('Call & Chat-Lidya'!$I$4:$I$2391,I29) -> 2 | B29: 46190 | C29: 2026 | D29: Juni | E29: 92 | F29: 46186 | G29: AKun Baru | H29: 11364 | I29: 19009 | J29: septy | K29: Family Laundry | L29: Family Laundry | M29: 081584258949 | N29: 081584258949 | O29: 46186 | P29: 46200 | Q29: 0 | R29: 1 | S29: UNINTEREST | T29: DELIVERED | U29: VALID | V29: (0) Pakai Aplikasi Lain | Z29: Aplikasi piposmart tidak digunakan dan saat ini sudah menggunakan aplikasi lain dan call langsung dimatikan
A30: =COUNTIF('Call & Chat-Lidya'!$I$4:$I$2391,I30) -> 2 | B30: 46190 | C30: 2026 | D30: Juni | E30: 93 | F30: 46188 | G30: AKun Baru | H30: 11366 | I30: 19016 | J30: siti aisyah | K30: INONG LAUNDRY | L30: INONG LAUNDRY | M30: 081290050427 | N30: 081290050427 | O30: 46187 | P30: 46201 | Q30: 0 | R30: 1 | S30: ENGAGE | T30: DELIVERED | U30: VALID | V30: (0) Data Employee dan Trial | Z30: Konfirmasi penggunaan aplikasi piposmart dan call langsung dimatikan
A31: =COUNTIF('Call & Chat-Lidya'!$I$4:$I$2391,I31) -> 1 | B31: 46190 | C31: 2026 | D31: Juni | E31: 94 | F31: 46188 | G31: AKun Baru | H31: 11368 | I31: 19022 | J31: Yora | K31: Yora Loundry | L31: Yora Loundry | M31: 089504716938 | N31: 089504716938 | O31: 46188 | P31: 46202 | Q31: 0 | R31: 1 | S31: INTEREST | T31: DELIVERED | U31: VALID | V31: (0) Data Employee dan Trial | W31: Tiktok | Z31: Aplikasi piposmartnya suaminya yang instal dan registrasi akun dan memang ada rencana mau beralih ke sistem aplikasi namun masih mau menghabiskan nota manual nya dulu karna ada sisa. Usaha laundry jalan 1 bulan stengah dan penjelasan aplikasi dan sistem berlangganan. Jika ada waktu untuk training dan ada kendala akan dihubungi kembali
A32: =COUNTIF('Call & Chat-Lidya'!$I$4:$I$2391,I32) -> 1 | B32: 46190 | C32: 2026 | D32: Juni | E32: 95 | F32: 46189 | G32: AKun Baru | H32: 11371 | I32: 19029 | J32: mama dean sinta | K32: madesi laundry | L32: madesi laundry | M32: 082117314993 | N32: 082117314993 | O32: 46189 | P32: 46203 | Q32: 0 | R32: 1 | S32: INTEREST | T32: DELIVERED | U32: VALID | V32: (0) Data Employee dan Trial | Z32: Aplikasi belum digunakan karna masih menunggu anaknya yang masih kuliah. Usaha laundry jalan 2 bulan dan masih menggunakan nota manual, penjelasan aplikasi piposmart dan aplikasinya akan dicoba diskusikan dulu dengan anaknya dan jika ada kendala akan dihubungi kembai
A33: =COUNTIF('Call & Chat-Lidya'!$I$4:$I$2391,I33) -> 1 | B33: 46190 | C33: 2026 | D33: Juni | E33: 96 | F33: 46189 | G33: AKun Baru | H33: 11372 | I33: 19030 | J33: Bunda Kanefia | K33: Bunbun Laundry | L33: Bunbun Laundry | M33: 088901446926 | N33: 088901446926 | O33: 46189 | P33: 46203 | Q33: 0 | R33: 1 | S33: CONNECTED | T33: ENGAGE | U33: VALID | V33: (0) Data Employee dan Trial | Z33: Jika ada kendala dalam penggunaan piposmartnya akan dihubungi kembali
A34: =COUNTIF('Call & Chat-Lidya'!$I$4:$I$2391,I34) -> 1 | B34: 46190 | C34: 2026 | D34: Juni | E34: 97 | F34: 46190 | G34: AKun Baru | H34: 11373 | I34: 19031 | J34: karenamu jaya laundry | K34: karenamu jaya laundry | L34: karenamu jaya laundry | M34: 082144229754 | N34: 082144229754 | O34: 46189 | P34: 46203 | Q34: 0 | R34: 1 | S34: CONTACTED | T34: DELIVERED | U34: VALID | V34: (0) Tidak Merespon
A35: =COUNTIF('Call & Chat-Lidya'!$I$4:$I$2391,I35) -> 1 | B35: 46190 | C35: 2026 | D35: Juni | E35: 98 | F35: 46190 | G35: AKun Baru | H35: 11376 | I35: 19035 | J35: Novia Hutahaean | K35: Celine Laundry | L35: Celine Laundry | M35: 085276064292 | O35: 46190 | P35: 46204 | Q35: 1 | R35: 1 | S35: CONNECTED | T35: ENGAGE | U35: VALID | V35: (0) Data Employee dan Trial | Z35: Bantu penjelasan untuk penginputan jumlah item yang di cuci dalam cuci kiloan
A36: =COUNTIF('Call & Chat-Lidya'!$I$4:$I$2391,I36) -> 1 | B36: 46190 | C36: 2026 | D36: Juni | E36: 99 | F36: 46190 | G36: AKun Baru | H36: 9491 | I36: 15512 | J36: Beryan Zee | K36: Gen Z Laundry | L36: GEN Z 2 Laundry | M36: 085367135058 | N36: 082322452222 | O36: 46190 | P36: 45822 | Q36: 0 | R36: 2 | S36: INTEREST | T36: DELIVERED | U36: VALID | V36: (0) Data Employee dan Trial | W36: Playstore | Z36: Ada rencana buka outlet baru dengan sistem laundry self service, namun untuk menjalankan mesin menggunakan QRIS dan masih ditanyakan dengan perlengkapan laundry nya untuk sistem operasional mesin nya. dan jika ada kendala dan mau dibantu kembali dari sisi piposmartnya akan dihubungi kembali. Rencana pembukaan laundry 24 Juni 2026 dan saat ini masi dalam proses instalasi mesin
A37: =COUNTIF('Call & Chat-Lidya'!$I$4:$I$2391,I37) -> 1 | B37: 46190 | C37: 2026 | D37: Juni | E37: 100 | F37: 46190 | G37: Outlet Baru | H37: 9794 | I37: 16248 | J37: SHAVARA LAUNDRY | K37: SHAVARA LAUNDRY | L37: Shavara Laundry (MV) | M37: 087832009030 | N37: 087832009030 | O37: 46190 | P37: 45911 | Q37: 0 | R37: 1 | S37: CONNECTED | T37: DELIVERED | U37: VALID | V37: (0) Tidak Merespon | W37: Playstore
A38: =COUNTIF('Call & Chat-Lidya'!$I$4:$I$2391,I38) -> 13 | B38: 46190 | C38: 2026 | D38: Mei | E38: 339 | F38: 46134 | G38: AKun Baru | H38: 11027 | I38: 18420 | J38: Villy | K38: Resik Laundry | L38: Resik Laundry | M38: 085163036060 | N38: 085163036060 | O38: 46132 | P38: 46146 | Q38: 3 | R38: 2 | S38: CONNECTED | T38: DELIVERED | U38: VALID | V38: (2) Trial, Demo, Interaktif
A39: =COUNTIF('Call & Chat-Lidya'!$I$4:$I$2391,I39) -> 4 | B39: 46190 | C39: 2026 | D39: Juni | E39: 2 | F39: 46174 | G39: AKun Baru | H39: 11307 | I39: 18899 | J39: Renita Setianingsih | K39: Golden Laundry | L39: Golden Laundry | M39: 087829560267 | N39: 085725651447 | O39: 46174 | P39: 46188 | Q39: 0 | R39: 1 | S39: CONNECTED | T39: DELIVERED | U39: VALID | V39: (0) Tidak Merespon
A40: =COUNTIF('Call & Chat-Lidya'!$I$4:$I$2391,I40) -> 4 | B40: 46190 | C40: 2026 | D40: Juni | E40: 3 | F40: 46175 | G40: AKun Baru | H40: 11310 | I40: 18904 | J40: Nadiva Laundry | K40: Nadiva Laundry | L40: Nadiva Laundry | M40: 085608982002 | N40: 085608982002 | O40: 46174 | P40: 46188 | Q40: 0 | R40: 1 | S40: CONNECTED | T40: DELIVERED | U40: VALID | V40: (0) Tidak Merespon
...

Sheet Report - Lidya
A1: Kategori Nasabah | C1: Jan | D1: Feb | E1: Maret | F1: April | G1: Mei | H1: Juni | I1: Juli | J1: Agust | K1: Total
A2: Nasabah Baru | C2: =SUM(F97:F115) -> 169 | D2: =SUM(F74:F96) -> 268 | E2: =SUM(F66:F84) -> 208 | F2: =SUM(F46:F65) -> 115 | G2: =SUM(F30:F45) -> 100 | H2: =SUM(F19:F29) -> 66
A3: Nasabah Potensial | C3: =SUM(L97:L115) -> 35 | D3: =SUM(L74:L96) -> 41 | E3: =SUM(L66:L84) -> 26 | F3: =SUM(L46:L65) -> 34 | G3: =SUM(L30:L45) -> 72 | H3: =SUM(L19:L29) -> 44
A4: Nasabah Mitra | C4: =SUM(R97:R115) -> 2 | D4: =SUM(R74:R96) -> 7 | E4: =SUM(R66:R84) -> 4 | F4: =SUM(R46:R65) -> 2 | G4: =SUM(R30:R45) -> 2 | H4: =SUM(R19:R29) -> 1
A5: Total Nasabah No Respon | C5: =SUM(Z97:Z115) -> 346 | D5: =SUM(Z74:Z96) -> 583 | E5: =SUM(Z66:Z84) -> 566 | F5: =SUM(Z46:Z65) -> 434 | G5: =SUM(Z30:Z45) -> 588 | H5: =SUM(Z19:Z29) -> 303
A6: Total Nasabah Respon | C6: =SUM(C2:C4) -> 206 | D6: =SUM(D2:D4) -> 316 | E6: =SUM(Y66:Y84) -> 238 | F6: =SUM(F2:F4) -> 151 | G6: =SUM(G2:G4) -> 174 | H6: =SUM(Y19:Y29) -> 128 | I6: =SUM(I2:I4) -> 0 | J6: =SUM(J2:J4) -> 0 | K6: =SUM(K2:K4) -> 0
A8: Daily Report Activity | Y8: Total Respon (Nasabah Baru + Potensi + Mitra) | Z8: Total No Respon (Nasabah Baru + Potensi + Mitra) | AA8: Total
A9: Bulan | B9: Tanggal | C9: Nasabah Registrasi Akun | G9: Nasabah Potensi | M9: Mitra | S9: Nasabah Jatuh Tempo
C10: Respon | E10: No Respon | F10: Respon | G10: Respon | K10: No Respon | L10: Respon | M10: Respon | Q10: No Respon | R10: Respon | S10: Respon | W10: No Respon | X10: Respon
C11: Call | D11: Chat | G11: Call | H11: Chat | I11: Online Meeting | J11: Visit Laundry | M11: Call | N11: Chat | O11: Online Meeting | P11: Visit Laundry | S11: Call | T11: Chat | U11: Online Meeting | V11: Visit Laundry
A13: Juni
A14: Juni
A15: Juni
A16: Juni
A17: Juni
A18: Juni | B18: Kamis. 18
A19: Juni | B19: Rabu, 17 | C19: 7 | D19: 5 | E19: 14 | F19: =SUM(C19:D19) -> 12 | G19: 4 | H19: 0 | I19: 1 | J19: 0 | K19: 7 | L19: =SUM(G19:J19) -> 5 | M19: 0 | N19: 0 | O19: 0 | P19: 0 | Q19: 0 | R19: 0 | S19: 0 | T19: 1 | U19: 0 | V19: 0 | W19: 9 | X19: =SUM(S19:V19) -> 1 | Y19: =SUM(F19,L19,R19,X19) -> 18 | Z19: =SUM(E19,K19,Q19,W19) -> 30 | AA19: =SUM(Y19+Z19) -> 48
A20: Juni | B20: Senin, 15 | C20: 5 | D20: 2 | E20: 14 | F20: =SUM(C20:D20) -> 7 | G20: 3 | H20: 3 | I20: 1 | J20: 0 | K20: 6 | L20: =SUM(G20:J20) -> 7 | M20: 0 | N20: 0 | O20: 0 | P20: 0 | Q20: 0 | R20: 0 | S20: 0 | T20: 2 | U20: 0 | V20: 0 | W20: 24 | X20: =SUM(S20:V20) -> 2 | Y20: =SUM(F20,L20,R20,X20) -> 16 | Z20: =SUM(E20,K20,Q20,W20) -> 44 | AA20: =SUM(Y20+Z20) -> 60
A21: Juni | B21: Jumat. 12 | C21: 3 | D21: 0 | E21: 27 | F21: =SUM(C21:D21) -> 3 | G21: 0 | H21: 0 | I21: 1 | J21: 0 | K21: 0 | L21: =SUM(G21:J21) -> 1 | M21: 0 | N21: 0 | O21: 0 | P21: 0 | Q21: 0 | R21: 0 | S21: 1 | T21: 0 | U21: 0 | V21: 0 | W21: 8 | X21: =SUM(S21:V21) -> 1 | Y21: =SUM(F21,L21,R21,X21) -> 5 | Z21: =SUM(E21,K21,Q21,W21) -> 35 | AA21: =SUM(Y21+Z21) -> 40
A22: Juni | B22: Kamis, 11 | C22: 9 | D22: 2 | E22: 24 | F22: =SUM(C22:D22) -> 11 | G22: 1 | H22: 2 | I22: 1 | J22: 0 | K22: 5 | L22: =SUM(G22:K22) -> 9 | M22: 0 | N22: 0 | O22: 0 | P22: 0 | Q22: 0 | R22: 0 | S22: 0 | T22: 1 | U22: 0 | V22: 0 | W22: 9 | X22: =SUM(S22:V22) -> 1 | Y22: =SUM(F22,L22,R22,X22) -> 21 | Z22: =SUM(E22,K22,Q22,W22) -> 38 | AA22: =SUM(Y22+Z22) -> 59
A23: Juni | B23: Rabu, 10 | C23: 5 | D23: 2 | E23: 12 | F23: =SUM(C23:D23) -> 7 | G23: 5 | H23: 2 | I23: 1 | J23: 0 | K23: 5 | L23: =SUM(G23:J23) -> 8 | M23: 0 | N23: 0 | O23: 0 | P23: 0 | Q23: 0 | R23: 0 | S23: 1 | T23: 0 | U23: 0 | V23: 0 | W23: 0 | X23: =SUM(S23:V23) -> 1 | Y23: =SUM(F23,L23,R23,X23) -> 16 | Z23: =SUM(E23,K23,Q23,W23) -> 17 | AA23: =SUM(Y23+Z23) -> 33
A24: Juni | B24: Selasa. 09 | C24: 6 | D24: 2 | E24: 16 | F24: =SUM(C24:D24) -> 8 | G24: 1 | H24: 2 | I24: 2 | J24: 0 | K24: 2 | L24: =SUM(G24:J24) -> 5 | M24: 0 | N24: 0 | O24: 0 | P24: 0 | Q24: 0 | R24: 0 | S24: 0 | T24: 1 | U24: 0 | V24: 0 | W24: 15 | X24: =SUM(S24:V24) -> 1 | Y24: =SUM(F24,L24,R24,X24) -> 14 | Z24: =SUM(E24,K24,Q24,W24) -> 33 | AA24: =SUM(Y24+Z24) -> 47
A25: Juni | B25: Senin, 08 | C25: 1 | D25: 1 | E25: 17 | F25: =SUM(C25:D25) -> 2 | G25: 4 | H25: 1 | I25: 3 | J25: 0 | K25: 4 | L25: =SUM(G25:J25) -> 8 | M25: 0 | N25: 1 | O25: 0 | P25: 0 | Q25: 0 | R25: =SUM(M25:P25) -> 1 | S25: 2 | T25: 3 | U25: 0 | V25: 0 | W25: 4 | X25: =SUM(S25:V25) -> 5 | Y25: =SUM(F25,L25,R25,X25) -> 16 | Z25: =SUM(E25,K25,Q25,W25) -> 25 | AA25: =SUM(Y25+Z25) -> 41
A26: Juni | B26: Jumat, 05 | C26: Test Bug Ayocuci dan bantu special case dan kendala beberapa nasabah
A27: Juni | B27: Kamis, 04 | C27: 8 | D27: 6 | E27: 24 | F27: =SUM(C27:D27) -> 14 | G27: 0 | H27: 1 | I27: 0 | J27: 0 | K27: 3 | L27: =SUM(G27:J27) -> 1 | M27: 0 | N27: 0 | O27: 0 | P27: 0 | Q27: 0 | R27: 0 | S27: 0 | T27: 0 | U27: 0 | V27: 0 | W27: 0 | X27: 0 | Y27: =SUM(F27,L27,R27,X27) -> 15 | Z27: =SUM(E27,K27,Q27,W27) -> 27 | AA27: =SUM(Y27+Z27) -> 42
A28: Juni | B28: Rabu,03 | C28: 1 | D28: 1 | E28: 21 | F28: =SUM(C28:D28) -> 2 | G28: 0 | H28: 0 | I28: 0 | J28: 0 | K28: 6 | L28: 0 | M28: 0 | N28: 0 | O28: 0 | P28: 0 | Q28: 2 | R28: 0 | S28: 0 | T28: 5 | U28: 0 | V28: 0 | W28: 25 | X28: =SUM(S28:V28) -> 5 | Y28: =SUM(F28,L28,R28,X28) -> 7 | Z28: =SUM(E28,K28,Q28,W28) -> 54 | AA28: =SUM(Y28+Z28) -> 61
A29: Juni | B29: Selasa. 02 | C29: Melengkapi data kelolaan Mei
A30: Mei | B30: Jumat, 29 | C30: 6 | D30: 1 | E30: 21 | F30: =SUM(C30:D30) -> 7 | G30: 5 | H30: 1 | I30: 0 | J30: 0 | K30: 6 | L30: =SUM(G30:J30) -> 6 | M30: 0 | N30: 0 | O30: 0 | P30: 0 | Q30: 0 | R30: 0 | S30: 2 | T30: 2 | U30: 0 | V30: 0 | W30: 14 | X30: =SUM(S30:V30) -> 4 | Y30: =SUM(F30,L30,R30,X30) -> 17 | Z30: =SUM(E30,K30,Q30,W30) -> 41 | AA30: =SUM(Y30+Z30) -> 58
A31: Mei | B31: Kamis,28 | C31: 1 | D31: 0 | E31: 4 | F31: =SUM(C31:D31) -> 1 | G31: 6 | H31: 1 | I31: 1 | J31: 0 | K31: 24 | L31: =SUM(G31:J31) -> 8 | M31: 0 | N31: 0 | O31: 0 | P31: 0 | Q31: 0 | R31: 0 | S31: 0 | T31: 2 | U31: 0 | V31: 0 | W31: 28 | X31: =SUM(S31:V31) -> 2 | Y31: =SUM(F31,L31,R31,X31) -> 11 | Z31: =SUM(E31,K31,Q31,W31) -> 56 | AA31: =SUM(Y31+Z31) -> 67
A32: Mei | B32: Selasa, 26 | C32: 6 | D32: 4 | E32: 42 | F32: =SUM(C32:D32) -> 10 | G32: 0 | H32: 0 | I32: 2 | J32: 0 | K32: 2 | L32: =SUM(G32:J32) -> 2 | M32: 0 | N32: 0 | O32: 0 | P32: 0 | Q32: 0 | R32: 0 | S32: 1 | T32: 0 | U32: 0 | V32: 0 | W32: 8 | X32: =SUM(S32:V32) -> 1 | Y32: =SUM(F32,L32,R32,X32) -> 13 | Z32: =SUM(E32,K32,Q32,W32) -> 52 | AA32: =SUM(Y32+Z32) -> 65
A33: Mei | B33: Senin, 25 | C33: 4 | D33: 3 | E33: 14 | F33: =SUM(C33:D33) -> 7 | G33: 2 | H33: 0 | I33: 1 | J33: 0 | K33: 6 | L33: =SUM(G33:J33) -> 3 | M33: 0 | N33: 0 | O33: 0 | P33: 0 | Q33: 0 | R33: 0 | S33: 0 | T33: 0 | U33: 0 | V33: 0 | W33: 0 | X33: =SUM(S33:V33) -> 0 | Y33: =SUM(F33,L33,R33,X33) -> 10 | Z33: =SUM(E33,K33,Q33,W33) -> 20 | AA33: =SUM(Y33+Z33) -> 30
A34: Mei | B34: Jumat, 22 | C34: 2 | D34: 5 | E34: 16 | F34: =SUM(C34:D34) -> 7 | G34: 0 | H34: 2 | I34: 1 | J34: 0 | K34: 7 | L34: =SUM(G34:J34) -> 3 | M34: 0 | N34: 0 | O34: 0 | P34: 0 | Q34: 0 | R34: 0 | S34: 1 | T34: 0 | U34: 0 | V34: 0 | W34: 20 | X34: =SUM(S34:V34) -> 1 | Y34: =SUM(F34,L34,R34,X34) -> 11 | Z34: =SUM(E34,K34,Q34,W34) -> 43 | AA34: =SUM(Y34+Z34) -> 54
A35: Mei | B35: Kamis, 21 | C35: 5 | D35: 3 | E35: 13 | F35: =SUM(C35:D35) -> 8 | G35: 5 | H35: 0 | I35: 0 | J35: 0 | K35: 13 | L35: =SUM(G35:J35) -> 5 | M35: 0 | N35: 0 | O35: 0 | P35: 0 | Q35: 0 | R35: 0 | S35: 2 | T35: 0 | U35: 0 | V35: 0 | W35: 0 | X35: =SUM(S35:V35) -> 2 | Y35: =SUM(F35,L35,R35,X35) -> 15 | Z35: =SUM(E35,K35,Q35,W35) -> 26 | AA35: =SUM(Y35+Z35) -> 41
A36: Mei | B36: Rabu, 20 | C36: 2 | D36: 0 | E36: 5 | F36: =SUM(C36:D36) -> 2 | G36: 3 | H36: 4 | I36: 1 | J36: 0 | K36: 12 | L36: =SUM(G36:J36) -> 8 | M36: 0 | N36: 0 | O36: 0 | P36: 0 | Q36: 0 | R36: 0 | S36: 1 | T36: 0 | U36: 0 | V36: 0 | W36: 0 | X36: =SUM(S36:V36) -> 1 | Y36: =SUM(F36,L36,R36,X36) -> 11 | Z36: =SUM(E36,K36,Q36,W36) -> 17 | AA36: =SUM(Y36+Z36) -> 28
A37: Mei | B37: Selasa, 19 | C37: 5 | D37: 1 | E37: 23 | F37: =SUM(C37:D37) -> 6 | G37: 1 | H37: 3 | I37: 0 | J37: 0 | K37: 2 | L37: =SUM(G37:J37) -> 4 | M37: 0 | N37: 0 | O37: 0 | P37: 0 | Q37: 0 | R37: 0 | S37: 0 | T37: 3 | U37: 0 | V37: 0 | W37: 16 | X37: =SUM(S37:V37) -> 3 | Y37: =SUM(F37,L37,R37,X37) -> 13 | Z37: =SUM(E37,K37,Q37,W37) -> 41 | AA37: =SUM(Y37+Z37) -> 54
A38: Mei | B38: Senin, 18 | C38: 7 | D38: 7 | E38: 26 | F38: =SUM(C38:D38) -> 14 | G38: 1 | H38: 2 | I38: 3 | J38: 0 | K38: 6 | L38: =SUM(G38:J38) -> 6 | M38: 0 | N38: 0 | O38: 0 | P38: 0 | Q38: 0 | R38: 0 | S38: 0 | T38: 2 | U38: 0 | V38: 0 | W38: 13 | X38: =SUM(S38:V38) -> 2 | Y38: =SUM(F38,L38,R38,X38) -> 22 | Z38: =SUM(E38,K38,Q38,W38) -> 45 | AA38: =SUM(Y38+Z38) -> 67
A39: Mei | B39: Jumat, 15 | C39: 4 | D39: 1 | E39: 18 | F39: =SUM(C39:D39) -> 5 | G39: 3 | H39: 4 | I39: 0 | J39: 0 | K39: 6 | L39: =SUM(G39:J39) -> 7 | M39: 0 | N39: 0 | O39: 0 | P39: 0 | Q39: 0 | R39: 0 | S39: 0 | T39: 2 | U39: 0 | V39: 0 | W39: 12 | X39: =SUM(S39:V39) -> 2 | Y39: =SUM(F39,L39,R39,X39) -> 14 | Z39: =SUM(E39,K39,Q39,W39) -> 36 | AA39: =SUM(Y39+Z39) -> 50
A40: Mei | B40: Rabu, 13 | C40: 4 | D40: 2 | E40: 20 | F40: =SUM(C40:D40) -> 6 | G40: 0 | H40: 2 | I40: 0 | J40: 0 | K40: 2 | L40: =SUM(G40:J40) -> 2 | M40: 0 | N40: 0 | O40: 0 | P40: 0 | Q40: 0 | R40: 0 | S40: 0 | T40: 4 | U40: 0 | V40: 0 | W40: 18 | X40: =SUM(S40:V40) -> 4 | Y40: =SUM(F40,L40,R40,X40) -> 12 | Z40: =SUM(E40,K40,Q40,W40) -> 40 | AA40: =SUM(Y40+Z40) -> 52
A41: Mei | B41: Jumat, 08 | C41: 4 | D41: 2 | E41: 32 | F41: =SUM(C41:D41) -> 6 | G41: 2 | H41: 1 | I41: 0 | J41: 0 | K41: 12 | L41: =SUM(G41:J41) -> 3 | M41: 0 | N41: 0 | O41: 0 | P41: 0 | Q41: 0 | R41: 0 | S41: 0 | T41: 3 | U41: 0 | V41: 0 | W41: 14 | X41: =SUM(S41:V41) -> 3 | Y41: =SUM(F41,L41,R41,X41) -> 12 | Z41: =SUM(E41,K41,Q41,W41) -> 58 | AA41: =SUM(Y41+Z41) -> 70
A42: Mei | B42: Kamis, 07 | C42: 8 | D42: 2 | E42: 30 | F42: =SUM(C42:D42) -> 10 | G42: 1 | H42: 1 | I42: 0 | J42: 0 | K42: 1 | L42: =SUM(G42:J42) -> 2 | M42: 0 | N42: 0 | O42: 0 | P42: 0 | Q42: 0 | R42: 0 | S42: 0 | T42: 2 | U42: 0 | V42: 0 | W42: 6 | X42: =SUM(S42:W42) -> 8 | Y42: =SUM(F42,L42,R42,X42) -> 20 | Z42: =SUM(E42,K42,Q42,W42) -> 37 | AA42: =SUM(Y42+Z42) -> 57
...

Sheet List Mitra
A1: PT. PIPOSMART DIGITAL INDONESIA
A2: DATA LIST MITRA PIPOSMART INDONESIA
A3: Kategori Mitra | B3: PIC Nasabah | C3: Bulan Terdaftar | D3: Tahun | E3: Kode Owner | F3: Owner Mitra | G3: Nama Brand / Nama Badan Usaha | H3: No. Telp | I3: Email Mitra | J3: No Rekening | K3: Bank | L3: Kategori Mitra | M3: Kota/Provinsi | N3: Alamat | O3: Total Akuisisi Referal | P3: Total Referral | Q3: Jan | R3: Feb | S3: Mar | T3: Apr | U3: Mei | V3: Jun | W3: Jul | X3: Aug | Y3: Sep | Z3: Okt | AA3: Nov | AB3: Des
A4: AFILIASI (Perlengkapan Ex. Mesin, Rak, Dll) | B4: PBGC 1 - Lidya | C4: Januari | D4: 2025 | F4: KG TEKNIK BATAM | G4: KG TEKNIK BATAM | H4: 081364050429 | I4: amiraizati01@gmail.com | J4: 1090019010180 | K4: Mandiri | L4: Mitra Corporated | M4: Kota Batam/Kepulauan Riau | N4: Ruko Puri Legenda Blok C2 No 02-03 Batam Centre | O4: ='Kelolaan Mitra'!H180 -> 3 | P4: =SUM(Q4:AB4) -> 7 | Q4: 3 | R4: 3 | S4: 0 | T4: 0 | U4: 1
